[2025-08-01 10:00:39,269] [UserIP.py:93] [UserIP:process_response] [INFO]- 2025-08-01 10:00:39: None/AnonymousUser/None> None/None/None > 127.0.0.1/127.0.0.1 > <AsgiRequest: POST '/PersonalInfo/api_Per/login/'>
[2025-08-01 10:00:39,273] [runserver.py:141] [runserver:log_action] [INFO]- HTTP POST /PersonalInfo/api_Per/login/ 200 [0.07, 127.0.0.1:62164]
[2025-08-01 10:00:39,755] [UserIP.py:93] [UserIP:process_response] [INFO]- 2025-08-01 10:00:39: None/API_CQM/None> None/None/None > 127.0.0.1/127.0.0.1 > <AsgiRequest: GET '/PersonalInfo/Perapi/?Customer=&SAPNum=&GroupNum=&Status=&DepartmentCode='>
[2025-08-01 10:00:39,756] [runserver.py:141] [runserver:log_action] [INFO]- HTTP GET /PersonalInfo/Perapi/?Customer=&SAPNum=&GroupNum=&Status=&DepartmentCode= 200 [0.48, 127.0.0.1:62166]
[2025-08-01 10:00:44,209] [UserIP.py:93] [UserIP:process_response] [INFO]- 2025-08-01 10:00:44: None/AnonymousUser/None> None/None/None > 127.0.0.1/127.0.0.1 > <AsgiRequest: POST '/PersonalInfo/api_Per/login/'>
[2025-08-01 10:00:44,211] [runserver.py:141] [runserver:log_action] [INFO]- HTTP POST /PersonalInfo/api_Per/login/ 200 [0.02, 127.0.0.1:62175]
[2025-08-01 10:00:45,392] [UserIP.py:93] [UserIP:process_response] [INFO]- 2025-08-01 10:00:45: None/API_CQM/None> None/None/None > 127.0.0.1/127.0.0.1 > <AsgiRequest: GET '/PersonalInfo/Perapi/?Customer=&SAPNum=&GroupNum=&Status=&DepartmentCode='>
[2025-08-01 10:00:45,396] [runserver.py:141] [runserver:log_action] [INFO]- HTTP GET /PersonalInfo/Perapi/?Customer=&SAPNum=&GroupNum=&Status=&DepartmentCode= 200 [1.18, 127.0.0.1:62177]
[2025-08-01 12:35:18,700] [UserIP.py:93] [UserIP:process_response] [INFO]- 2025-08-01 12:35:18: None/AnonymousUser/None> None/None/None > 127.0.0.1/127.0.0.1 > <AsgiRequest: GET '/TestPlanSW/TestPlanSW-summary/'>
[2025-08-01 12:35:18,708] [runserver.py:147] [runserver:log_action] [INFO]- HTTP GET /TestPlanSW/TestPlanSW-summary/ 302 [0.32, 127.0.0.1:58561]
[2025-08-01 12:35:18,747] [UserIP.py:93] [UserIP:process_response] [INFO]- 2025-08-01 12:35:18: None/AnonymousUser/None> None/None/None > 127.0.0.1/127.0.0.1 > <AsgiRequest: GET '/login/'>
[2025-08-01 12:35:18,750] [runserver.py:141] [runserver:log_action] [INFO]- HTTP GET /login/ 200 [0.04, 127.0.0.1:58561]
[2025-08-01 12:35:18,894] [UserIP.py:93] [UserIP:process_response] [INFO]- 2025-08-01 12:35:18: None/AnonymousUser/None> None/None/None > 127.0.0.1/127.0.0.1 > <AsgiRequest: GET '/favicon.ico'>
[2025-08-01 12:35:18,896] [runserver.py:147] [runserver:log_action] [INFO]- HTTP GET /favicon.ico 302 [0.04, 127.0.0.1:58561]
[2025-08-01 12:35:18,905] [UserIP.py:93] [UserIP:process_response] [INFO]- 2025-08-01 12:35:18: None/AnonymousUser/None> None/None/None > 127.0.0.1/127.0.0.1 > <AsgiRequest: GET '/login/'>
[2025-08-01 12:35:18,905] [runserver.py:141] [runserver:log_action] [INFO]- HTTP GET /login/ 200 [0.01, 127.0.0.1:58561]
[2025-08-01 12:35:21,575] [UserIP.py:93] [UserIP:process_response] [INFO]- 2025-08-01 12:35:21: C1010S3/AnonymousUser/Edwin> None/None/None > 127.0.0.1/127.0.0.1 > <AsgiRequest: POST '/login/?next='>
[2025-08-01 12:35:21,598] [runserver.py:147] [runserver:log_action] [INFO]- HTTP POST /login/?next= 302 [0.06, 127.0.0.1:58561]
[2025-08-01 12:35:21,617] [UserIP.py:93] [UserIP:process_response] [INFO]- 2025-08-01 12:35:21: C1010S3/AnonymousUser/Edwin> None/None/None > 127.0.0.1/127.0.0.1 > <AsgiRequest: GET '/login/'>
[2025-08-01 12:35:21,626] [runserver.py:147] [runserver:log_action] [INFO]- HTTP GET /login/ 302 [0.02, 127.0.0.1:58561]
[2025-08-01 12:35:21,740] [UserIP.py:93] [UserIP:process_response] [INFO]- 2025-08-01 12:35:21: C1010S3/AnonymousUser/Edwin> None/None/None > 127.0.0.1/127.0.0.1 > <AsgiRequest: GET '/Navigations/'>
[2025-08-01 12:35:21,758] [runserver.py:141] [runserver:log_action] [INFO]- HTTP GET /Navigations/ 200 [0.13, 127.0.0.1:58561]
[2025-08-01 12:35:21,933] [runserver.py:162] [runserver:log_action] [INFO]- WebSocket HANDSHAKING /ws/msg/Reliability_Row_data/ [127.0.0.1:58577]
[2025-08-01 12:35:22,176] [runserver.py:158] [runserver:log_action] [INFO]- WebSocket CONNECT /ws/msg/Reliability_Row_data/ [127.0.0.1:58577]
[2025-08-01 12:35:22,209] [UserIP.py:93] [UserIP:process_response] [INFO]- 2025-08-01 12:35:22: C1010S3/AnonymousUser/Edwin> None/None/None > 127.0.0.1/127.0.0.1 > <AsgiRequest: GET '/favicon.ico'>
[2025-08-01 12:35:22,241] [runserver.py:141] [runserver:log_action] [INFO]- HTTP GET /favicon.ico 200 [0.05, 127.0.0.1:58561]
[2025-08-01 16:36:28,040] [runserver.py:160] [runserver:log_action] [INFO]- WebSocket DISCONNECT /ws/msg/Reliability_Row_data/ [127.0.0.1:58577]
[2025-08-05 12:49:01,498] [UserIP.py:93] [UserIP:process_response] [INFO]- 2025-08-05 12:49:01: None/AnonymousUser/None> None/None/None > 127.0.0.1/127.0.0.1 > <AsgiRequest: GET '/Navigations/'>
[2025-08-05 12:49:01,509] [runserver.py:147] [runserver:log_action] [INFO]- HTTP GET /Navigations/ 302 [0.10, 127.0.0.1:62565]
[2025-08-05 12:49:01,533] [UserIP.py:93] [UserIP:process_response] [INFO]- 2025-08-05 12:49:01: None/AnonymousUser/None> None/None/None > 127.0.0.1/127.0.0.1 > <AsgiRequest: GET '/login/'>
[2025-08-05 12:49:01,537] [runserver.py:141] [runserver:log_action] [INFO]- HTTP GET /login/ 200 [0.02, 127.0.0.1:62565]
[2025-08-05 12:49:01,749] [UserIP.py:93] [UserIP:process_response] [INFO]- 2025-08-05 12:49:01: None/AnonymousUser/None> None/None/None > 127.0.0.1/127.0.0.1 > <AsgiRequest: GET '/favicon.ico'>
[2025-08-05 12:49:01,751] [runserver.py:147] [runserver:log_action] [INFO]- HTTP GET /favicon.ico 302 [0.03, 127.0.0.1:62565]
[2025-08-05 12:49:01,759] [UserIP.py:93] [UserIP:process_response] [INFO]- 2025-08-05 12:49:01: None/AnonymousUser/None> None/None/None > 127.0.0.1/127.0.0.1 > <AsgiRequest: GET '/login/'>
[2025-08-05 12:49:01,760] [runserver.py:141] [runserver:log_action] [INFO]- HTTP GET /login/ 200 [0.00, 127.0.0.1:62565]
[2025-08-05 16:10:59,360] [log.py:228] [log:log_response] [ERROR]- Internal Server Error: /PersonalInfo/api_Per/login/
Traceback (most recent call last):
  File "C:\Python3129\mecheck\lib\site-packages\django\core\handlers\exception.py", line 34, in inner
    response = get_response(request)
  File "C:\Python3129\mecheck\lib\site-packages\django\core\handlers\base.py", line 126, in _get_response
    response = self.process_exception_by_middleware(e, request)
  File "C:\Python3129\mecheck\lib\site-packages\django\core\handlers\base.py", line 124, in _get_response
    response = wrapped_callback(request, *callback_args, **callback_kwargs)
  File "C:\Python3129\mecheck\lib\site-packages\django\views\decorators\csrf.py", line 54, in wrapped_view
    return view_func(*args, **kwargs)
  File "C:\Python3129\mecheck\lib\site-packages\django\views\generic\base.py", line 68, in view
    return self.dispatch(request, *args, **kwargs)
  File "C:\Python3129\mecheck\lib\site-packages\rest_framework\views.py", line 505, in dispatch
    response = self.handle_exception(exc)
  File "C:\Python3129\mecheck\lib\site-packages\rest_framework\views.py", line 465, in handle_exception
    self.raise_uncaught_exception(exc)
  File "C:\Python3129\mecheck\lib\site-packages\rest_framework\views.py", line 476, in raise_uncaught_exception
    raise exc
  File "C:\Python3129\mecheck\lib\site-packages\rest_framework\views.py", line 502, in dispatch
    response = handler(request, *args, **kwargs)
  File "C:\Python3129\mecheck\lib\site-packages\rest_framework_simplejwt\views.py", line 43, in post
    serializer.is_valid(raise_exception=True)
  File "C:\Python3129\mecheck\lib\site-packages\rest_framework\serializers.py", line 234, in is_valid
    self._validated_data = self.run_validation(self.initial_data)
  File "C:\Python3129\mecheck\lib\site-packages\rest_framework\serializers.py", line 436, in run_validation
    value = self.validate(value)
  File "C:\djangoproject\Reliability_Row_data\PersonalInfo\authentication.py", line 21, in validate
    print(authenticate_kwargs,"authenticate_kwargs")
OSError: [Errno 22] Invalid argument
[2025-08-05 16:10:59,377] [UserIP.py:93] [UserIP:process_response] [INFO]- 2025-08-05 16:10:59: None/AnonymousUser/None> None/None/None > 127.0.0.1/127.0.0.1 > <AsgiRequest: POST '/PersonalInfo/api_Per/login/'>
[2025-08-05 16:10:59,381] [runserver.py:154] [runserver:log_action] [ERROR]- HTTP POST /PersonalInfo/api_Per/login/ 500 [0.68, 127.0.0.1:64784]
[2025-08-05 16:12:54,008] [log.py:228] [log:log_response] [ERROR]- Internal Server Error: /PersonalInfo/api_Per/login/
Traceback (most recent call last):
  File "C:\Python3129\mecheck\lib\site-packages\django\core\handlers\exception.py", line 34, in inner
    response = get_response(request)
  File "C:\Python3129\mecheck\lib\site-packages\django\core\handlers\base.py", line 126, in _get_response
    response = self.process_exception_by_middleware(e, request)
  File "C:\Python3129\mecheck\lib\site-packages\django\core\handlers\base.py", line 124, in _get_response
    response = wrapped_callback(request, *callback_args, **callback_kwargs)
  File "C:\Python3129\mecheck\lib\site-packages\django\views\decorators\csrf.py", line 54, in wrapped_view
    return view_func(*args, **kwargs)
  File "C:\Python3129\mecheck\lib\site-packages\django\views\generic\base.py", line 68, in view
    return self.dispatch(request, *args, **kwargs)
  File "C:\Python3129\mecheck\lib\site-packages\rest_framework\views.py", line 505, in dispatch
    response = self.handle_exception(exc)
  File "C:\Python3129\mecheck\lib\site-packages\rest_framework\views.py", line 465, in handle_exception
    self.raise_uncaught_exception(exc)
  File "C:\Python3129\mecheck\lib\site-packages\rest_framework\views.py", line 476, in raise_uncaught_exception
    raise exc
  File "C:\Python3129\mecheck\lib\site-packages\rest_framework\views.py", line 502, in dispatch
    response = handler(request, *args, **kwargs)
  File "C:\Python3129\mecheck\lib\site-packages\rest_framework_simplejwt\views.py", line 43, in post
    serializer.is_valid(raise_exception=True)
  File "C:\Python3129\mecheck\lib\site-packages\rest_framework\serializers.py", line 234, in is_valid
    self._validated_data = self.run_validation(self.initial_data)
  File "C:\Python3129\mecheck\lib\site-packages\rest_framework\serializers.py", line 436, in run_validation
    value = self.validate(value)
  File "C:\djangoproject\Reliability_Row_data\PersonalInfo\authentication.py", line 21, in validate
    print(authenticate_kwargs,"authenticate_kwargs")
OSError: [Errno 22] Invalid argument
[2025-08-05 16:12:54,011] [UserIP.py:93] [UserIP:process_response] [INFO]- 2025-08-05 16:12:54: None/AnonymousUser/None> None/None/None > 127.0.0.1/127.0.0.1 > <AsgiRequest: POST '/PersonalInfo/api_Per/login/'>
[2025-08-05 16:12:54,014] [runserver.py:154] [runserver:log_action] [ERROR]- HTTP POST /PersonalInfo/api_Per/login/ 500 [0.05, 127.0.0.1:65031]
[2025-08-05 16:12:56,273] [log.py:228] [log:log_response] [ERROR]- Internal Server Error: /PersonalInfo/api_Per/login/
Traceback (most recent call last):
  File "C:\Python3129\mecheck\lib\site-packages\django\core\handlers\exception.py", line 34, in inner
    response = get_response(request)
  File "C:\Python3129\mecheck\lib\site-packages\django\core\handlers\base.py", line 126, in _get_response
    response = self.process_exception_by_middleware(e, request)
  File "C:\Python3129\mecheck\lib\site-packages\django\core\handlers\base.py", line 124, in _get_response
    response = wrapped_callback(request, *callback_args, **callback_kwargs)
  File "C:\Python3129\mecheck\lib\site-packages\django\views\decorators\csrf.py", line 54, in wrapped_view
    return view_func(*args, **kwargs)
  File "C:\Python3129\mecheck\lib\site-packages\django\views\generic\base.py", line 68, in view
    return self.dispatch(request, *args, **kwargs)
  File "C:\Python3129\mecheck\lib\site-packages\rest_framework\views.py", line 505, in dispatch
    response = self.handle_exception(exc)
  File "C:\Python3129\mecheck\lib\site-packages\rest_framework\views.py", line 465, in handle_exception
    self.raise_uncaught_exception(exc)
  File "C:\Python3129\mecheck\lib\site-packages\rest_framework\views.py", line 476, in raise_uncaught_exception
    raise exc
  File "C:\Python3129\mecheck\lib\site-packages\rest_framework\views.py", line 502, in dispatch
    response = handler(request, *args, **kwargs)
  File "C:\Python3129\mecheck\lib\site-packages\rest_framework_simplejwt\views.py", line 43, in post
    serializer.is_valid(raise_exception=True)
  File "C:\Python3129\mecheck\lib\site-packages\rest_framework\serializers.py", line 234, in is_valid
    self._validated_data = self.run_validation(self.initial_data)
  File "C:\Python3129\mecheck\lib\site-packages\rest_framework\serializers.py", line 436, in run_validation
    value = self.validate(value)
  File "C:\djangoproject\Reliability_Row_data\PersonalInfo\authentication.py", line 21, in validate
    print(authenticate_kwargs,"authenticate_kwargs")
OSError: [Errno 22] Invalid argument
[2025-08-05 16:12:56,277] [UserIP.py:93] [UserIP:process_response] [INFO]- 2025-08-05 16:12:56: None/AnonymousUser/None> None/None/None > 127.0.0.1/127.0.0.1 > <AsgiRequest: POST '/PersonalInfo/api_Per/login/'>
[2025-08-05 16:12:56,282] [runserver.py:154] [runserver:log_action] [ERROR]- HTTP POST /PersonalInfo/api_Per/login/ 500 [0.04, 127.0.0.1:65045]
[2025-08-05 16:13:26,816] [log.py:228] [log:log_response] [ERROR]- Internal Server Error: /PersonalInfo/api_Per/login/
Traceback (most recent call last):
  File "C:\Python3129\mecheck\lib\site-packages\django\core\handlers\exception.py", line 34, in inner
    response = get_response(request)
  File "C:\Python3129\mecheck\lib\site-packages\django\core\handlers\base.py", line 126, in _get_response
    response = self.process_exception_by_middleware(e, request)
  File "C:\Python3129\mecheck\lib\site-packages\django\core\handlers\base.py", line 124, in _get_response
    response = wrapped_callback(request, *callback_args, **callback_kwargs)
  File "C:\Python3129\mecheck\lib\site-packages\django\views\decorators\csrf.py", line 54, in wrapped_view
    return view_func(*args, **kwargs)
  File "C:\Python3129\mecheck\lib\site-packages\django\views\generic\base.py", line 68, in view
    return self.dispatch(request, *args, **kwargs)
  File "C:\Python3129\mecheck\lib\site-packages\rest_framework\views.py", line 505, in dispatch
    response = self.handle_exception(exc)
  File "C:\Python3129\mecheck\lib\site-packages\rest_framework\views.py", line 465, in handle_exception
    self.raise_uncaught_exception(exc)
  File "C:\Python3129\mecheck\lib\site-packages\rest_framework\views.py", line 476, in raise_uncaught_exception
    raise exc
  File "C:\Python3129\mecheck\lib\site-packages\rest_framework\views.py", line 502, in dispatch
    response = handler(request, *args, **kwargs)
  File "C:\Python3129\mecheck\lib\site-packages\rest_framework_simplejwt\views.py", line 43, in post
    serializer.is_valid(raise_exception=True)
  File "C:\Python3129\mecheck\lib\site-packages\rest_framework\serializers.py", line 234, in is_valid
    self._validated_data = self.run_validation(self.initial_data)
  File "C:\Python3129\mecheck\lib\site-packages\rest_framework\serializers.py", line 436, in run_validation
    value = self.validate(value)
  File "C:\djangoproject\Reliability_Row_data\PersonalInfo\authentication.py", line 21, in validate
    print(authenticate_kwargs,"authenticate_kwargs")
OSError: [Errno 22] Invalid argument
[2025-08-05 16:13:26,819] [UserIP.py:93] [UserIP:process_response] [INFO]- 2025-08-05 16:13:26: None/AnonymousUser/None> None/None/None > 127.0.0.1/127.0.0.1 > <AsgiRequest: POST '/PersonalInfo/api_Per/login/'>
[2025-08-05 16:13:26,823] [runserver.py:154] [runserver:log_action] [ERROR]- HTTP POST /PersonalInfo/api_Per/login/ 500 [0.04, 127.0.0.1:65130]
[2025-08-05 16:13:41,742] [log.py:228] [log:log_response] [ERROR]- Internal Server Error: /PersonalInfo/api_Per/login/
Traceback (most recent call last):
  File "C:\Python3129\mecheck\lib\site-packages\django\core\handlers\exception.py", line 34, in inner
    response = get_response(request)
  File "C:\Python3129\mecheck\lib\site-packages\django\core\handlers\base.py", line 126, in _get_response
    response = self.process_exception_by_middleware(e, request)
  File "C:\Python3129\mecheck\lib\site-packages\django\core\handlers\base.py", line 124, in _get_response
    response = wrapped_callback(request, *callback_args, **callback_kwargs)
  File "C:\Python3129\mecheck\lib\site-packages\django\views\decorators\csrf.py", line 54, in wrapped_view
    return view_func(*args, **kwargs)
  File "C:\Python3129\mecheck\lib\site-packages\django\views\generic\base.py", line 68, in view
    return self.dispatch(request, *args, **kwargs)
  File "C:\Python3129\mecheck\lib\site-packages\rest_framework\views.py", line 505, in dispatch
    response = self.handle_exception(exc)
  File "C:\Python3129\mecheck\lib\site-packages\rest_framework\views.py", line 465, in handle_exception
    self.raise_uncaught_exception(exc)
  File "C:\Python3129\mecheck\lib\site-packages\rest_framework\views.py", line 476, in raise_uncaught_exception
    raise exc
  File "C:\Python3129\mecheck\lib\site-packages\rest_framework\views.py", line 502, in dispatch
    response = handler(request, *args, **kwargs)
  File "C:\Python3129\mecheck\lib\site-packages\rest_framework_simplejwt\views.py", line 43, in post
    serializer.is_valid(raise_exception=True)
  File "C:\Python3129\mecheck\lib\site-packages\rest_framework\serializers.py", line 234, in is_valid
    self._validated_data = self.run_validation(self.initial_data)
  File "C:\Python3129\mecheck\lib\site-packages\rest_framework\serializers.py", line 436, in run_validation
    value = self.validate(value)
  File "C:\djangoproject\Reliability_Row_data\PersonalInfo\authentication.py", line 21, in validate
    print(authenticate_kwargs,"authenticate_kwargs")
OSError: [Errno 22] Invalid argument
[2025-08-05 16:13:41,744] [UserIP.py:93] [UserIP:process_response] [INFO]- 2025-08-05 16:13:41: None/AnonymousUser/None> None/None/None > 127.0.0.1/127.0.0.1 > <AsgiRequest: POST '/PersonalInfo/api_Per/login/'>
[2025-08-05 16:13:41,747] [runserver.py:154] [runserver:log_action] [ERROR]- HTTP POST /PersonalInfo/api_Per/login/ 500 [0.02, 127.0.0.1:65176]
[2025-08-05 16:14:20,811] [UserIP.py:93] [UserIP:process_response] [INFO]- 2025-08-05 16:14:20: None/AnonymousUser/None> None/None/None > 127.0.0.1/127.0.0.1 > <AsgiRequest: GET '/'>
[2025-08-05 16:14:20,815] [runserver.py:147] [runserver:log_action] [INFO]- HTTP GET / 302 [0.05, 127.0.0.1:65260]
[2025-08-05 16:14:20,822] [UserIP.py:93] [UserIP:process_response] [INFO]- 2025-08-05 16:14:20: None/AnonymousUser/None> None/None/None > 127.0.0.1/127.0.0.1 > <AsgiRequest: GET '/login/'>
[2025-08-05 16:14:20,824] [runserver.py:141] [runserver:log_action] [INFO]- HTTP GET /login/ 200 [0.00, 127.0.0.1:65260]
[2025-08-05 16:14:21,053] [UserIP.py:93] [UserIP:process_response] [INFO]- 2025-08-05 16:14:21: None/AnonymousUser/None> None/None/None > 127.0.0.1/127.0.0.1 > <AsgiRequest: GET '/favicon.ico'>
[2025-08-05 16:14:21,056] [runserver.py:147] [runserver:log_action] [INFO]- HTTP GET /favicon.ico 302 [0.02, 127.0.0.1:65260]
[2025-08-05 16:14:21,065] [UserIP.py:93] [UserIP:process_response] [INFO]- 2025-08-05 16:14:21: None/AnonymousUser/None> None/None/None > 127.0.0.1/127.0.0.1 > <AsgiRequest: GET '/login/'>
[2025-08-05 16:14:21,067] [runserver.py:141] [runserver:log_action] [INFO]- HTTP GET /login/ 200 [0.01, 127.0.0.1:65260]
[2025-08-05 16:14:36,552] [log.py:228] [log:log_response] [ERROR]- Internal Server Error: /PersonalInfo/api_Per/login/
Traceback (most recent call last):
  File "C:\Python3129\mecheck\lib\site-packages\django\core\handlers\exception.py", line 34, in inner
    response = get_response(request)
  File "C:\Python3129\mecheck\lib\site-packages\django\core\handlers\base.py", line 126, in _get_response
    response = self.process_exception_by_middleware(e, request)
  File "C:\Python3129\mecheck\lib\site-packages\django\core\handlers\base.py", line 124, in _get_response
    response = wrapped_callback(request, *callback_args, **callback_kwargs)
  File "C:\Python3129\mecheck\lib\site-packages\django\views\decorators\csrf.py", line 54, in wrapped_view
    return view_func(*args, **kwargs)
  File "C:\Python3129\mecheck\lib\site-packages\django\views\generic\base.py", line 68, in view
    return self.dispatch(request, *args, **kwargs)
  File "C:\Python3129\mecheck\lib\site-packages\rest_framework\views.py", line 505, in dispatch
    response = self.handle_exception(exc)
  File "C:\Python3129\mecheck\lib\site-packages\rest_framework\views.py", line 465, in handle_exception
    self.raise_uncaught_exception(exc)
  File "C:\Python3129\mecheck\lib\site-packages\rest_framework\views.py", line 476, in raise_uncaught_exception
    raise exc
  File "C:\Python3129\mecheck\lib\site-packages\rest_framework\views.py", line 502, in dispatch
    response = handler(request, *args, **kwargs)
  File "C:\Python3129\mecheck\lib\site-packages\rest_framework_simplejwt\views.py", line 43, in post
    serializer.is_valid(raise_exception=True)
  File "C:\Python3129\mecheck\lib\site-packages\rest_framework\serializers.py", line 234, in is_valid
    self._validated_data = self.run_validation(self.initial_data)
  File "C:\Python3129\mecheck\lib\site-packages\rest_framework\serializers.py", line 436, in run_validation
    value = self.validate(value)
  File "C:\djangoproject\Reliability_Row_data\PersonalInfo\authentication.py", line 21, in validate
    print(authenticate_kwargs,"authenticate_kwargs")
OSError: [Errno 22] Invalid argument
[2025-08-05 16:14:36,555] [UserIP.py:93] [UserIP:process_response] [INFO]- 2025-08-05 16:14:36: None/AnonymousUser/None> None/None/None > 127.0.0.1/127.0.0.1 > <AsgiRequest: POST '/PersonalInfo/api_Per/login/'>
[2025-08-05 16:14:36,557] [runserver.py:154] [runserver:log_action] [ERROR]- HTTP POST /PersonalInfo/api_Per/login/ 500 [0.03, 127.0.0.1:65306]
[2025-08-05 16:16:04,090] [log.py:228] [log:log_response] [ERROR]- Internal Server Error: /PersonalInfo/api_Per/login/
Traceback (most recent call last):
  File "C:\Python3129\mecheck\lib\site-packages\django\core\handlers\exception.py", line 34, in inner
    response = get_response(request)
  File "C:\Python3129\mecheck\lib\site-packages\django\core\handlers\base.py", line 126, in _get_response
    response = self.process_exception_by_middleware(e, request)
  File "C:\Python3129\mecheck\lib\site-packages\django\core\handlers\base.py", line 124, in _get_response
    response = wrapped_callback(request, *callback_args, **callback_kwargs)
  File "C:\Python3129\mecheck\lib\site-packages\django\views\decorators\csrf.py", line 54, in wrapped_view
    return view_func(*args, **kwargs)
  File "C:\Python3129\mecheck\lib\site-packages\django\views\generic\base.py", line 68, in view
    return self.dispatch(request, *args, **kwargs)
  File "C:\Python3129\mecheck\lib\site-packages\rest_framework\views.py", line 505, in dispatch
    response = self.handle_exception(exc)
  File "C:\Python3129\mecheck\lib\site-packages\rest_framework\views.py", line 465, in handle_exception
    self.raise_uncaught_exception(exc)
  File "C:\Python3129\mecheck\lib\site-packages\rest_framework\views.py", line 476, in raise_uncaught_exception
    raise exc
  File "C:\Python3129\mecheck\lib\site-packages\rest_framework\views.py", line 502, in dispatch
    response = handler(request, *args, **kwargs)
  File "C:\Python3129\mecheck\lib\site-packages\rest_framework_simplejwt\views.py", line 43, in post
    serializer.is_valid(raise_exception=True)
  File "C:\Python3129\mecheck\lib\site-packages\rest_framework\serializers.py", line 234, in is_valid
    self._validated_data = self.run_validation(self.initial_data)
  File "C:\Python3129\mecheck\lib\site-packages\rest_framework\serializers.py", line 436, in run_validation
    value = self.validate(value)
  File "C:\djangoproject\Reliability_Row_data\PersonalInfo\authentication.py", line 21, in validate
    print(authenticate_kwargs,"authenticate_kwargs")
OSError: [Errno 22] Invalid argument
[2025-08-05 16:16:04,096] [UserIP.py:93] [UserIP:process_response] [INFO]- 2025-08-05 16:16:04: None/AnonymousUser/None> None/None/None > 127.0.0.1/127.0.0.1 > <AsgiRequest: POST '/PersonalInfo/api_Per/login/'>
[2025-08-05 16:16:04,099] [runserver.py:154] [runserver:log_action] [ERROR]- HTTP POST /PersonalInfo/api_Per/login/ 500 [1.10, 127.0.0.1:65181]
[2025-08-05 16:20:32,656] [UserIP.py:93] [UserIP:process_response] [INFO]- 2025-08-05 16:20:32: API_CQM/AnonymousUser/API_CQM> None/None/None > 127.0.0.1/127.0.0.1 > <AsgiRequest: POST '/CQM/api/login/'>
[2025-08-05 16:20:32,680] [runserver.py:141] [runserver:log_action] [INFO]- HTTP POST /CQM/api/login/ 200 [0.08, 127.0.0.1:49269]
[2025-08-05 16:21:18,871] [log.py:228] [log:log_response] [ERROR]- Internal Server Error: /PersonalInfo/api_Per/login/
Traceback (most recent call last):
  File "C:\Python3129\mecheck\lib\site-packages\django\core\handlers\exception.py", line 34, in inner
    response = get_response(request)
  File "C:\Python3129\mecheck\lib\site-packages\django\core\handlers\base.py", line 126, in _get_response
    response = self.process_exception_by_middleware(e, request)
  File "C:\Python3129\mecheck\lib\site-packages\django\core\handlers\base.py", line 124, in _get_response
    response = wrapped_callback(request, *callback_args, **callback_kwargs)
  File "C:\Python3129\mecheck\lib\site-packages\django\views\decorators\csrf.py", line 54, in wrapped_view
    return view_func(*args, **kwargs)
  File "C:\Python3129\mecheck\lib\site-packages\django\views\generic\base.py", line 68, in view
    return self.dispatch(request, *args, **kwargs)
  File "C:\Python3129\mecheck\lib\site-packages\rest_framework\views.py", line 505, in dispatch
    response = self.handle_exception(exc)
  File "C:\Python3129\mecheck\lib\site-packages\rest_framework\views.py", line 465, in handle_exception
    self.raise_uncaught_exception(exc)
  File "C:\Python3129\mecheck\lib\site-packages\rest_framework\views.py", line 476, in raise_uncaught_exception
    raise exc
  File "C:\Python3129\mecheck\lib\site-packages\rest_framework\views.py", line 502, in dispatch
    response = handler(request, *args, **kwargs)
  File "C:\Python3129\mecheck\lib\site-packages\rest_framework_simplejwt\views.py", line 43, in post
    serializer.is_valid(raise_exception=True)
  File "C:\Python3129\mecheck\lib\site-packages\rest_framework\serializers.py", line 234, in is_valid
    self._validated_data = self.run_validation(self.initial_data)
  File "C:\Python3129\mecheck\lib\site-packages\rest_framework\serializers.py", line 436, in run_validation
    value = self.validate(value)
  File "C:\djangoproject\Reliability_Row_data\PersonalInfo\authentication.py", line 21, in validate
    print(authenticate_kwargs,"authenticate_kwargs")
OSError: [Errno 22] Invalid argument
[2025-08-05 16:21:18,902] [UserIP.py:93] [UserIP:process_response] [INFO]- 2025-08-05 16:21:18: API_CQM/AnonymousUser/API_CQM> None/None/None > 127.0.0.1/127.0.0.1 > <AsgiRequest: POST '/PersonalInfo/api_Per/login/'>
[2025-08-05 16:21:18,904] [runserver.py:154] [runserver:log_action] [ERROR]- HTTP POST /PersonalInfo/api_Per/login/ 500 [0.06, 127.0.0.1:49269]
[2025-08-05 16:25:40,174] [log.py:228] [log:log_response] [ERROR]- Internal Server Error: /PersonalInfo/api_Per/login/
Traceback (most recent call last):
  File "C:\Python3129\mecheck\lib\site-packages\django\core\handlers\exception.py", line 34, in inner
    response = get_response(request)
  File "C:\Python3129\mecheck\lib\site-packages\django\core\handlers\base.py", line 126, in _get_response
    response = self.process_exception_by_middleware(e, request)
  File "C:\Python3129\mecheck\lib\site-packages\django\core\handlers\base.py", line 124, in _get_response
    response = wrapped_callback(request, *callback_args, **callback_kwargs)
  File "C:\Python3129\mecheck\lib\site-packages\django\views\decorators\csrf.py", line 54, in wrapped_view
    return view_func(*args, **kwargs)
  File "C:\Python3129\mecheck\lib\site-packages\django\views\generic\base.py", line 68, in view
    return self.dispatch(request, *args, **kwargs)
  File "C:\Python3129\mecheck\lib\site-packages\rest_framework\views.py", line 505, in dispatch
    response = self.handle_exception(exc)
  File "C:\Python3129\mecheck\lib\site-packages\rest_framework\views.py", line 465, in handle_exception
    self.raise_uncaught_exception(exc)
  File "C:\Python3129\mecheck\lib\site-packages\rest_framework\views.py", line 476, in raise_uncaught_exception
    raise exc
  File "C:\Python3129\mecheck\lib\site-packages\rest_framework\views.py", line 502, in dispatch
    response = handler(request, *args, **kwargs)
  File "C:\Python3129\mecheck\lib\site-packages\rest_framework_simplejwt\views.py", line 43, in post
    serializer.is_valid(raise_exception=True)
  File "C:\Python3129\mecheck\lib\site-packages\rest_framework\serializers.py", line 234, in is_valid
    self._validated_data = self.run_validation(self.initial_data)
  File "C:\Python3129\mecheck\lib\site-packages\rest_framework\serializers.py", line 436, in run_validation
    value = self.validate(value)
  File "C:\djangoproject\Reliability_Row_data\PersonalInfo\authentication.py", line 21, in validate
    print(authenticate_kwargs,"authenticate_kwargs")
OSError: [Errno 22] Invalid argument
[2025-08-05 16:25:40,212] [UserIP.py:93] [UserIP:process_response] [INFO]- 2025-08-05 16:25:40: API_CQM/AnonymousUser/API_CQM> None/None/None > 127.0.0.1/127.0.0.1 > <AsgiRequest: POST '/PersonalInfo/api_Per/login/'>
[2025-08-05 16:25:40,214] [runserver.py:154] [runserver:log_action] [ERROR]- HTTP POST /PersonalInfo/api_Per/login/ 500 [0.07, 127.0.0.1:49963]
[2025-08-05 16:26:59,380] [log.py:228] [log:log_response] [ERROR]- Internal Server Error: /PersonalInfo/api_Per/login/
Traceback (most recent call last):
  File "C:\Python3129\mecheck\lib\site-packages\django\core\handlers\exception.py", line 34, in inner
    response = get_response(request)
  File "C:\Python3129\mecheck\lib\site-packages\django\core\handlers\base.py", line 126, in _get_response
    response = self.process_exception_by_middleware(e, request)
  File "C:\Python3129\mecheck\lib\site-packages\django\core\handlers\base.py", line 124, in _get_response
    response = wrapped_callback(request, *callback_args, **callback_kwargs)
  File "C:\Python3129\mecheck\lib\site-packages\django\views\decorators\csrf.py", line 54, in wrapped_view
    return view_func(*args, **kwargs)
  File "C:\Python3129\mecheck\lib\site-packages\django\views\generic\base.py", line 68, in view
    return self.dispatch(request, *args, **kwargs)
  File "C:\Python3129\mecheck\lib\site-packages\rest_framework\views.py", line 505, in dispatch
    response = self.handle_exception(exc)
  File "C:\Python3129\mecheck\lib\site-packages\rest_framework\views.py", line 465, in handle_exception
    self.raise_uncaught_exception(exc)
  File "C:\Python3129\mecheck\lib\site-packages\rest_framework\views.py", line 476, in raise_uncaught_exception
    raise exc
  File "C:\Python3129\mecheck\lib\site-packages\rest_framework\views.py", line 502, in dispatch
    response = handler(request, *args, **kwargs)
  File "C:\Python3129\mecheck\lib\site-packages\rest_framework_simplejwt\views.py", line 43, in post
    serializer.is_valid(raise_exception=True)
  File "C:\Python3129\mecheck\lib\site-packages\rest_framework\serializers.py", line 234, in is_valid
    self._validated_data = self.run_validation(self.initial_data)
  File "C:\Python3129\mecheck\lib\site-packages\rest_framework\serializers.py", line 436, in run_validation
    value = self.validate(value)
  File "C:\djangoproject\Reliability_Row_data\PersonalInfo\authentication.py", line 21, in validate
    print(authenticate_kwargs,"authenticate_kwargs")
OSError: [Errno 22] Invalid argument
[2025-08-05 16:26:59,418] [UserIP.py:93] [UserIP:process_response] [INFO]- 2025-08-05 16:26:59: API_CQM/AnonymousUser/API_CQM> None/None/None > 127.0.0.1/127.0.0.1 > <AsgiRequest: POST '/PersonalInfo/api_Per/login/'>
[2025-08-05 16:26:59,419] [runserver.py:154] [runserver:log_action] [ERROR]- HTTP POST /PersonalInfo/api_Per/login/ 500 [0.08, 127.0.0.1:50113]
