[2025-02-24 07:58:34,322] [log.py:228] [log:log_response] [ERROR]- Internal Server Error: /Navigations/
Traceback (most recent call last):
  File "C:\Python372\mecheck\lib\site-packages\django\contrib\sessions\backends\base.py", line 190, in _get_session
    return self._session_cache
AttributeError: 'SessionStore' object has no attribute '_session_cache'

During handling of the above exception, another exception occurred:

Traceback (most recent call last):
  File "C:\Python372\mecheck\lib\site-packages\pymysql\connections.py", line 583, in connect
    **kwargs)
  File "C:\Python372\lib\socket.py", line 727, in create_connection
    raise err
  File "C:\Python372\lib\socket.py", line 716, in create_connection
    sock.connect(sa)
OSError: [WinError 10048] 通常每个套接字地址(协议/网络地址/端口)只允许使用一次。

During handling of the above exception, another exception occurred:

Traceback (most recent call last):
  File "C:\Python372\mecheck\lib\site-packages\django\db\backends\base\base.py", line 216, in ensure_connection
    self.connect()
  File "C:\Python372\mecheck\lib\site-packages\django\db\backends\base\base.py", line 194, in connect
    self.connection = self.get_new_connection(conn_params)
  File "C:\Python372\mecheck\lib\site-packages\django\db\backends\mysql\base.py", line 227, in get_new_connection
    return Database.connect(**conn_params)
  File "C:\Python372\mecheck\lib\site-packages\pymysql\__init__.py", line 94, in Connect
    return Connection(*args, **kwargs)
  File "C:\Python372\mecheck\lib\site-packages\pymysql\connections.py", line 325, in __init__
    self.connect()
  File "C:\Python372\mecheck\lib\site-packages\pymysql\connections.py", line 630, in connect
    raise exc
pymysql.err.OperationalError: (2003, "Can't connect to MySQL server on '127.0.0.1' ([WinError 10048] 通常每个套接字地址(协议/网络地址/端口)只允许使用一次。)")

The above exception was the direct cause of the following exception:

Traceback (most recent call last):
  File "C:\Python372\mecheck\lib\site-packages\django\core\handlers\exception.py", line 34, in inner
    response = get_response(request)
  File "C:\Python372\mecheck\lib\site-packages\django\core\handlers\base.py", line 126, in _get_response
    response = self.process_exception_by_middleware(e, request)
  File "C:\Python372\mecheck\lib\site-packages\django\core\handlers\base.py", line 124, in _get_response
    response = wrapped_callback(request, *callback_args, **callback_kwargs)
  File "C:\Python372\mecheck\lib\site-packages\django\views\decorators\csrf.py", line 54, in wrapped_view
    return view_func(*args, **kwargs)
  File "C:\djangoproject\Reliability_Row_data\app01\views.py", line 660, in Navigations
    if not request.session.get('is_login', None):
  File "C:\Python372\mecheck\lib\site-packages\django\contrib\sessions\backends\base.py", line 66, in get
    return self._session.get(key, default)
  File "C:\Python372\mecheck\lib\site-packages\django\contrib\sessions\backends\base.py", line 195, in _get_session
    self._session_cache = self.load()
  File "C:\Python372\mecheck\lib\site-packages\django\contrib\sessions\backends\db.py", line 43, in load
    s = self._get_session_from_db()
  File "C:\Python372\mecheck\lib\site-packages\django\contrib\sessions\backends\db.py", line 34, in _get_session_from_db
    expire_date__gt=timezone.now()
  File "C:\Python372\mecheck\lib\site-packages\django\db\models\manager.py", line 82, in manager_method
    return getattr(self.get_queryset(), name)(*args, **kwargs)
  File "C:\Python372\mecheck\lib\site-packages\django\db\models\query.py", line 393, in get
    num = len(clone)
  File "C:\Python372\mecheck\lib\site-packages\django\db\models\query.py", line 250, in __len__
    self._fetch_all()
  File "C:\Python372\mecheck\lib\site-packages\django\db\models\query.py", line 1186, in _fetch_all
    self._result_cache = list(self._iterable_class(self))
  File "C:\Python372\mecheck\lib\site-packages\django\db\models\query.py", line 54, in __iter__
    results = compiler.execute_sql(chunked_fetch=self.chunked_fetch, chunk_size=self.chunk_size)
  File "C:\Python372\mecheck\lib\site-packages\django\db\models\sql\compiler.py", line 1063, in execute_sql
    cursor = self.connection.cursor()
  File "C:\Python372\mecheck\lib\site-packages\django\db\backends\base\base.py", line 255, in cursor
    return self._cursor()
  File "C:\Python372\mecheck\lib\site-packages\django\db\backends\base\base.py", line 232, in _cursor
    self.ensure_connection()
  File "C:\Python372\mecheck\lib\site-packages\django\db\backends\base\base.py", line 216, in ensure_connection
    self.connect()
  File "C:\Python372\mecheck\lib\site-packages\django\db\utils.py", line 89, in __exit__
    raise dj_exc_value.with_traceback(traceback) from exc_value
  File "C:\Python372\mecheck\lib\site-packages\django\db\backends\base\base.py", line 216, in ensure_connection
    self.connect()
  File "C:\Python372\mecheck\lib\site-packages\django\db\backends\base\base.py", line 194, in connect
    self.connection = self.get_new_connection(conn_params)
  File "C:\Python372\mecheck\lib\site-packages\django\db\backends\mysql\base.py", line 227, in get_new_connection
    return Database.connect(**conn_params)
  File "C:\Python372\mecheck\lib\site-packages\pymysql\__init__.py", line 94, in Connect
    return Connection(*args, **kwargs)
  File "C:\Python372\mecheck\lib\site-packages\pymysql\connections.py", line 325, in __init__
    self.connect()
  File "C:\Python372\mecheck\lib\site-packages\pymysql\connections.py", line 630, in connect
    raise exc
django.db.utils.OperationalError: (2003, "Can't connect to MySQL server on '127.0.0.1' ([WinError 10048] 通常每个套接字地址(协议/网络地址/端口)只允许使用一次。)")
[2025-02-24 07:58:34,520] [log.py:228] [log:log_response] [ERROR]- Internal Server Error: /Navigations/
Traceback (most recent call last):
  File "C:\Python372\mecheck\lib\site-packages\django\contrib\sessions\backends\base.py", line 190, in _get_session
    return self._session_cache
AttributeError: 'SessionStore' object has no attribute '_session_cache'

During handling of the above exception, another exception occurred:

Traceback (most recent call last):
  File "C:\Python372\mecheck\lib\site-packages\pymysql\connections.py", line 583, in connect
    **kwargs)
  File "C:\Python372\lib\socket.py", line 727, in create_connection
    raise err
  File "C:\Python372\lib\socket.py", line 716, in create_connection
    sock.connect(sa)
OSError: [WinError 10048] 通常每个套接字地址(协议/网络地址/端口)只允许使用一次。

During handling of the above exception, another exception occurred:

Traceback (most recent call last):
  File "C:\Python372\mecheck\lib\site-packages\django\db\backends\base\base.py", line 216, in ensure_connection
    self.connect()
  File "C:\Python372\mecheck\lib\site-packages\django\db\backends\base\base.py", line 194, in connect
    self.connection = self.get_new_connection(conn_params)
  File "C:\Python372\mecheck\lib\site-packages\django\db\backends\mysql\base.py", line 227, in get_new_connection
    return Database.connect(**conn_params)
  File "C:\Python372\mecheck\lib\site-packages\pymysql\__init__.py", line 94, in Connect
    return Connection(*args, **kwargs)
  File "C:\Python372\mecheck\lib\site-packages\pymysql\connections.py", line 325, in __init__
    self.connect()
  File "C:\Python372\mecheck\lib\site-packages\pymysql\connections.py", line 630, in connect
    raise exc
pymysql.err.OperationalError: (2003, "Can't connect to MySQL server on '127.0.0.1' ([WinError 10048] 通常每个套接字地址(协议/网络地址/端口)只允许使用一次。)")

The above exception was the direct cause of the following exception:

Traceback (most recent call last):
  File "C:\Python372\mecheck\lib\site-packages\django\core\handlers\exception.py", line 34, in inner
    response = get_response(request)
  File "C:\djangoproject\Reliability_Row_data\middleware\checkper.py", line 14, in __call__
    response = self.process_request(request)
  File "C:\djangoproject\Reliability_Row_data\middleware\checkper.py", line 32, in process_request
    permission_url = request.session.get(settings.SESSION_PERMISSION_URL_KEY)
  File "C:\Python372\mecheck\lib\site-packages\django\contrib\sessions\backends\base.py", line 66, in get
    return self._session.get(key, default)
  File "C:\Python372\mecheck\lib\site-packages\django\contrib\sessions\backends\base.py", line 195, in _get_session
    self._session_cache = self.load()
  File "C:\Python372\mecheck\lib\site-packages\django\contrib\sessions\backends\db.py", line 43, in load
    s = self._get_session_from_db()
  File "C:\Python372\mecheck\lib\site-packages\django\contrib\sessions\backends\db.py", line 34, in _get_session_from_db
    expire_date__gt=timezone.now()
  File "C:\Python372\mecheck\lib\site-packages\django\db\models\manager.py", line 82, in manager_method
    return getattr(self.get_queryset(), name)(*args, **kwargs)
  File "C:\Python372\mecheck\lib\site-packages\django\db\models\query.py", line 393, in get
    num = len(clone)
  File "C:\Python372\mecheck\lib\site-packages\django\db\models\query.py", line 250, in __len__
    self._fetch_all()
  File "C:\Python372\mecheck\lib\site-packages\django\db\models\query.py", line 1186, in _fetch_all
    self._result_cache = list(self._iterable_class(self))
  File "C:\Python372\mecheck\lib\site-packages\django\db\models\query.py", line 54, in __iter__
    results = compiler.execute_sql(chunked_fetch=self.chunked_fetch, chunk_size=self.chunk_size)
  File "C:\Python372\mecheck\lib\site-packages\django\db\models\sql\compiler.py", line 1063, in execute_sql
    cursor = self.connection.cursor()
  File "C:\Python372\mecheck\lib\site-packages\django\db\backends\base\base.py", line 255, in cursor
    return self._cursor()
  File "C:\Python372\mecheck\lib\site-packages\django\db\backends\base\base.py", line 232, in _cursor
    self.ensure_connection()
  File "C:\Python372\mecheck\lib\site-packages\django\db\backends\base\base.py", line 216, in ensure_connection
    self.connect()
  File "C:\Python372\mecheck\lib\site-packages\django\db\utils.py", line 89, in __exit__
    raise dj_exc_value.with_traceback(traceback) from exc_value
  File "C:\Python372\mecheck\lib\site-packages\django\db\backends\base\base.py", line 216, in ensure_connection
    self.connect()
  File "C:\Python372\mecheck\lib\site-packages\django\db\backends\base\base.py", line 194, in connect
    self.connection = self.get_new_connection(conn_params)
  File "C:\Python372\mecheck\lib\site-packages\django\db\backends\mysql\base.py", line 227, in get_new_connection
    return Database.connect(**conn_params)
  File "C:\Python372\mecheck\lib\site-packages\pymysql\__init__.py", line 94, in Connect
    return Connection(*args, **kwargs)
  File "C:\Python372\mecheck\lib\site-packages\pymysql\connections.py", line 325, in __init__
    self.connect()
  File "C:\Python372\mecheck\lib\site-packages\pymysql\connections.py", line 630, in connect
    raise exc
django.db.utils.OperationalError: (2003, "Can't connect to MySQL server on '127.0.0.1' ([WinError 10048] 通常每个套接字地址(协议/网络地址/端口)只允许使用一次。)")
[2025-02-24 07:58:34,741] [log.py:228] [log:log_response] [ERROR]- Internal Server Error: /Navigations/
Traceback (most recent call last):
  File "C:\Python372\mecheck\lib\site-packages\django\contrib\sessions\backends\base.py", line 190, in _get_session
    return self._session_cache
AttributeError: 'SessionStore' object has no attribute '_session_cache'

During handling of the above exception, another exception occurred:

Traceback (most recent call last):
  File "C:\Python372\mecheck\lib\site-packages\pymysql\connections.py", line 583, in connect
    **kwargs)
  File "C:\Python372\lib\socket.py", line 727, in create_connection
    raise err
  File "C:\Python372\lib\socket.py", line 716, in create_connection
    sock.connect(sa)
OSError: [WinError 10048] 通常每个套接字地址(协议/网络地址/端口)只允许使用一次。

During handling of the above exception, another exception occurred:

Traceback (most recent call last):
  File "C:\Python372\mecheck\lib\site-packages\django\db\backends\base\base.py", line 216, in ensure_connection
    self.connect()
  File "C:\Python372\mecheck\lib\site-packages\django\db\backends\base\base.py", line 194, in connect
    self.connection = self.get_new_connection(conn_params)
  File "C:\Python372\mecheck\lib\site-packages\django\db\backends\mysql\base.py", line 227, in get_new_connection
    return Database.connect(**conn_params)
  File "C:\Python372\mecheck\lib\site-packages\pymysql\__init__.py", line 94, in Connect
    return Connection(*args, **kwargs)
  File "C:\Python372\mecheck\lib\site-packages\pymysql\connections.py", line 325, in __init__
    self.connect()
  File "C:\Python372\mecheck\lib\site-packages\pymysql\connections.py", line 630, in connect
    raise exc
pymysql.err.OperationalError: (2003, "Can't connect to MySQL server on '127.0.0.1' ([WinError 10048] 通常每个套接字地址(协议/网络地址/端口)只允许使用一次。)")

The above exception was the direct cause of the following exception:

Traceback (most recent call last):
  File "C:\Python372\mecheck\lib\site-packages\django\core\handlers\exception.py", line 34, in inner
    response = get_response(request)
  File "C:\Python372\mecheck\lib\site-packages\django\utils\deprecation.py", line 93, in __call__
    response = self.process_response(request, response)
  File "C:\Python372\mecheck\lib\site-packages\django\contrib\sessions\middleware.py", line 47, in process_response
    if request.session.get_expire_at_browser_close():
  File "C:\Python372\mecheck\lib\site-packages\django\contrib\sessions\backends\base.py", line 279, in get_expire_at_browser_close
    if self.get('_session_expiry') is None:
  File "C:\Python372\mecheck\lib\site-packages\django\contrib\sessions\backends\base.py", line 66, in get
    return self._session.get(key, default)
  File "C:\Python372\mecheck\lib\site-packages\django\contrib\sessions\backends\base.py", line 195, in _get_session
    self._session_cache = self.load()
  File "C:\Python372\mecheck\lib\site-packages\django\contrib\sessions\backends\db.py", line 43, in load
    s = self._get_session_from_db()
  File "C:\Python372\mecheck\lib\site-packages\django\contrib\sessions\backends\db.py", line 34, in _get_session_from_db
    expire_date__gt=timezone.now()
  File "C:\Python372\mecheck\lib\site-packages\django\db\models\manager.py", line 82, in manager_method
    return getattr(self.get_queryset(), name)(*args, **kwargs)
  File "C:\Python372\mecheck\lib\site-packages\django\db\models\query.py", line 393, in get
    num = len(clone)
  File "C:\Python372\mecheck\lib\site-packages\django\db\models\query.py", line 250, in __len__
    self._fetch_all()
  File "C:\Python372\mecheck\lib\site-packages\django\db\models\query.py", line 1186, in _fetch_all
    self._result_cache = list(self._iterable_class(self))
  File "C:\Python372\mecheck\lib\site-packages\django\db\models\query.py", line 54, in __iter__
    results = compiler.execute_sql(chunked_fetch=self.chunked_fetch, chunk_size=self.chunk_size)
  File "C:\Python372\mecheck\lib\site-packages\django\db\models\sql\compiler.py", line 1063, in execute_sql
    cursor = self.connection.cursor()
  File "C:\Python372\mecheck\lib\site-packages\django\db\backends\base\base.py", line 255, in cursor
    return self._cursor()
  File "C:\Python372\mecheck\lib\site-packages\django\db\backends\base\base.py", line 232, in _cursor
    self.ensure_connection()
  File "C:\Python372\mecheck\lib\site-packages\django\db\backends\base\base.py", line 216, in ensure_connection
    self.connect()
  File "C:\Python372\mecheck\lib\site-packages\django\db\utils.py", line 89, in __exit__
    raise dj_exc_value.with_traceback(traceback) from exc_value
  File "C:\Python372\mecheck\lib\site-packages\django\db\backends\base\base.py", line 216, in ensure_connection
    self.connect()
  File "C:\Python372\mecheck\lib\site-packages\django\db\backends\base\base.py", line 194, in connect
    self.connection = self.get_new_connection(conn_params)
  File "C:\Python372\mecheck\lib\site-packages\django\db\backends\mysql\base.py", line 227, in get_new_connection
    return Database.connect(**conn_params)
  File "C:\Python372\mecheck\lib\site-packages\pymysql\__init__.py", line 94, in Connect
    return Connection(*args, **kwargs)
  File "C:\Python372\mecheck\lib\site-packages\pymysql\connections.py", line 325, in __init__
    self.connect()
  File "C:\Python372\mecheck\lib\site-packages\pymysql\connections.py", line 630, in connect
    raise exc
django.db.utils.OperationalError: (2003, "Can't connect to MySQL server on '127.0.0.1' ([WinError 10048] 通常每个套接字地址(协议/网络地址/端口)只允许使用一次。)")
[2025-02-24 07:58:34,745] [runserver.py:154] [runserver:log_action] [ERROR]- HTTP GET /Navigations/ 500 [0.67, 127.0.0.1:55145]
[2025-02-25 08:42:05,839] [log.py:228] [log:log_response] [ERROR]- Internal Server Error: /Navigations_system/CapitalExpenditure/
Traceback (most recent call last):
  File "C:\Python372\mecheck\lib\site-packages\django\contrib\sessions\backends\base.py", line 190, in _get_session
    return self._session_cache
AttributeError: 'SessionStore' object has no attribute '_session_cache'

During handling of the above exception, another exception occurred:

Traceback (most recent call last):
  File "C:\Python372\mecheck\lib\site-packages\pymysql\connections.py", line 583, in connect
    **kwargs)
  File "C:\Python372\lib\socket.py", line 727, in create_connection
    raise err
  File "C:\Python372\lib\socket.py", line 716, in create_connection
    sock.connect(sa)
OSError: [WinError 10055] 由于系统缓冲区空间不足或队列已满，不能执行套接字上的操作。

During handling of the above exception, another exception occurred:

Traceback (most recent call last):
  File "C:\Python372\mecheck\lib\site-packages\django\db\backends\base\base.py", line 216, in ensure_connection
    self.connect()
  File "C:\Python372\mecheck\lib\site-packages\django\db\backends\base\base.py", line 194, in connect
    self.connection = self.get_new_connection(conn_params)
  File "C:\Python372\mecheck\lib\site-packages\django\db\backends\mysql\base.py", line 227, in get_new_connection
    return Database.connect(**conn_params)
  File "C:\Python372\mecheck\lib\site-packages\pymysql\__init__.py", line 94, in Connect
    return Connection(*args, **kwargs)
  File "C:\Python372\mecheck\lib\site-packages\pymysql\connections.py", line 325, in __init__
    self.connect()
  File "C:\Python372\mecheck\lib\site-packages\pymysql\connections.py", line 630, in connect
    raise exc
pymysql.err.OperationalError: (2003, "Can't connect to MySQL server on '127.0.0.1' ([WinError 10055] 由于系统缓冲区空间不足或队列已满，不能执行套接字上的操作。)")

The above exception was the direct cause of the following exception:

Traceback (most recent call last):
  File "C:\Python372\mecheck\lib\site-packages\django\core\handlers\exception.py", line 34, in inner
    response = get_response(request)
  File "C:\Python372\mecheck\lib\site-packages\django\core\handlers\base.py", line 126, in _get_response
    response = self.process_exception_by_middleware(e, request)
  File "C:\Python372\mecheck\lib\site-packages\django\core\handlers\base.py", line 124, in _get_response
    response = wrapped_callback(request, *callback_args, **callback_kwargs)
  File "C:\Python372\mecheck\lib\site-packages\django\views\decorators\csrf.py", line 54, in wrapped_view
    return view_func(*args, **kwargs)
  File "C:\djangoproject\Reliability_Row_data\app01\views.py", line 1369, in Navigations_system
    if not request.session.get('is_login', None):
  File "C:\Python372\mecheck\lib\site-packages\django\contrib\sessions\backends\base.py", line 66, in get
    return self._session.get(key, default)
  File "C:\Python372\mecheck\lib\site-packages\django\contrib\sessions\backends\base.py", line 195, in _get_session
    self._session_cache = self.load()
  File "C:\Python372\mecheck\lib\site-packages\django\contrib\sessions\backends\db.py", line 43, in load
    s = self._get_session_from_db()
  File "C:\Python372\mecheck\lib\site-packages\django\contrib\sessions\backends\db.py", line 34, in _get_session_from_db
    expire_date__gt=timezone.now()
  File "C:\Python372\mecheck\lib\site-packages\django\db\models\manager.py", line 82, in manager_method
    return getattr(self.get_queryset(), name)(*args, **kwargs)
  File "C:\Python372\mecheck\lib\site-packages\django\db\models\query.py", line 393, in get
    num = len(clone)
  File "C:\Python372\mecheck\lib\site-packages\django\db\models\query.py", line 250, in __len__
    self._fetch_all()
  File "C:\Python372\mecheck\lib\site-packages\django\db\models\query.py", line 1186, in _fetch_all
    self._result_cache = list(self._iterable_class(self))
  File "C:\Python372\mecheck\lib\site-packages\django\db\models\query.py", line 54, in __iter__
    results = compiler.execute_sql(chunked_fetch=self.chunked_fetch, chunk_size=self.chunk_size)
  File "C:\Python372\mecheck\lib\site-packages\django\db\models\sql\compiler.py", line 1063, in execute_sql
    cursor = self.connection.cursor()
  File "C:\Python372\mecheck\lib\site-packages\django\db\backends\base\base.py", line 255, in cursor
    return self._cursor()
  File "C:\Python372\mecheck\lib\site-packages\django\db\backends\base\base.py", line 232, in _cursor
    self.ensure_connection()
  File "C:\Python372\mecheck\lib\site-packages\django\db\backends\base\base.py", line 216, in ensure_connection
    self.connect()
  File "C:\Python372\mecheck\lib\site-packages\django\db\utils.py", line 89, in __exit__
    raise dj_exc_value.with_traceback(traceback) from exc_value
  File "C:\Python372\mecheck\lib\site-packages\django\db\backends\base\base.py", line 216, in ensure_connection
    self.connect()
  File "C:\Python372\mecheck\lib\site-packages\django\db\backends\base\base.py", line 194, in connect
    self.connection = self.get_new_connection(conn_params)
  File "C:\Python372\mecheck\lib\site-packages\django\db\backends\mysql\base.py", line 227, in get_new_connection
    return Database.connect(**conn_params)
  File "C:\Python372\mecheck\lib\site-packages\pymysql\__init__.py", line 94, in Connect
    return Connection(*args, **kwargs)
  File "C:\Python372\mecheck\lib\site-packages\pymysql\connections.py", line 325, in __init__
    self.connect()
  File "C:\Python372\mecheck\lib\site-packages\pymysql\connections.py", line 630, in connect
    raise exc
django.db.utils.OperationalError: (2003, "Can't connect to MySQL server on '127.0.0.1' ([WinError 10055] 由于系统缓冲区空间不足或队列已满，不能执行套接字上的操作。)")
[2025-02-25 08:42:06,067] [log.py:228] [log:log_response] [ERROR]- Internal Server Error: /Navigations_system/CapitalExpenditure/
Traceback (most recent call last):
  File "C:\Python372\mecheck\lib\site-packages\django\contrib\sessions\backends\base.py", line 190, in _get_session
    return self._session_cache
AttributeError: 'SessionStore' object has no attribute '_session_cache'

During handling of the above exception, another exception occurred:

Traceback (most recent call last):
  File "C:\Python372\mecheck\lib\site-packages\pymysql\connections.py", line 583, in connect
    **kwargs)
  File "C:\Python372\lib\socket.py", line 727, in create_connection
    raise err
  File "C:\Python372\lib\socket.py", line 716, in create_connection
    sock.connect(sa)
OSError: [WinError 10055] 由于系统缓冲区空间不足或队列已满，不能执行套接字上的操作。

During handling of the above exception, another exception occurred:

Traceback (most recent call last):
  File "C:\Python372\mecheck\lib\site-packages\django\db\backends\base\base.py", line 216, in ensure_connection
    self.connect()
  File "C:\Python372\mecheck\lib\site-packages\django\db\backends\base\base.py", line 194, in connect
    self.connection = self.get_new_connection(conn_params)
  File "C:\Python372\mecheck\lib\site-packages\django\db\backends\mysql\base.py", line 227, in get_new_connection
    return Database.connect(**conn_params)
  File "C:\Python372\mecheck\lib\site-packages\pymysql\__init__.py", line 94, in Connect
    return Connection(*args, **kwargs)
  File "C:\Python372\mecheck\lib\site-packages\pymysql\connections.py", line 325, in __init__
    self.connect()
  File "C:\Python372\mecheck\lib\site-packages\pymysql\connections.py", line 630, in connect
    raise exc
pymysql.err.OperationalError: (2003, "Can't connect to MySQL server on '127.0.0.1' ([WinError 10055] 由于系统缓冲区空间不足或队列已满，不能执行套接字上的操作。)")

The above exception was the direct cause of the following exception:

Traceback (most recent call last):
  File "C:\Python372\mecheck\lib\site-packages\django\core\handlers\exception.py", line 34, in inner
    response = get_response(request)
  File "C:\djangoproject\Reliability_Row_data\middleware\checkper.py", line 14, in __call__
    response = self.process_request(request)
  File "C:\djangoproject\Reliability_Row_data\middleware\checkper.py", line 32, in process_request
    permission_url = request.session.get(settings.SESSION_PERMISSION_URL_KEY)
  File "C:\Python372\mecheck\lib\site-packages\django\contrib\sessions\backends\base.py", line 66, in get
    return self._session.get(key, default)
  File "C:\Python372\mecheck\lib\site-packages\django\contrib\sessions\backends\base.py", line 195, in _get_session
    self._session_cache = self.load()
  File "C:\Python372\mecheck\lib\site-packages\django\contrib\sessions\backends\db.py", line 43, in load
    s = self._get_session_from_db()
  File "C:\Python372\mecheck\lib\site-packages\django\contrib\sessions\backends\db.py", line 34, in _get_session_from_db
    expire_date__gt=timezone.now()
  File "C:\Python372\mecheck\lib\site-packages\django\db\models\manager.py", line 82, in manager_method
    return getattr(self.get_queryset(), name)(*args, **kwargs)
  File "C:\Python372\mecheck\lib\site-packages\django\db\models\query.py", line 393, in get
    num = len(clone)
  File "C:\Python372\mecheck\lib\site-packages\django\db\models\query.py", line 250, in __len__
    self._fetch_all()
  File "C:\Python372\mecheck\lib\site-packages\django\db\models\query.py", line 1186, in _fetch_all
    self._result_cache = list(self._iterable_class(self))
  File "C:\Python372\mecheck\lib\site-packages\django\db\models\query.py", line 54, in __iter__
    results = compiler.execute_sql(chunked_fetch=self.chunked_fetch, chunk_size=self.chunk_size)
  File "C:\Python372\mecheck\lib\site-packages\django\db\models\sql\compiler.py", line 1063, in execute_sql
    cursor = self.connection.cursor()
  File "C:\Python372\mecheck\lib\site-packages\django\db\backends\base\base.py", line 255, in cursor
    return self._cursor()
  File "C:\Python372\mecheck\lib\site-packages\django\db\backends\base\base.py", line 232, in _cursor
    self.ensure_connection()
  File "C:\Python372\mecheck\lib\site-packages\django\db\backends\base\base.py", line 216, in ensure_connection
    self.connect()
  File "C:\Python372\mecheck\lib\site-packages\django\db\utils.py", line 89, in __exit__
    raise dj_exc_value.with_traceback(traceback) from exc_value
  File "C:\Python372\mecheck\lib\site-packages\django\db\backends\base\base.py", line 216, in ensure_connection
    self.connect()
  File "C:\Python372\mecheck\lib\site-packages\django\db\backends\base\base.py", line 194, in connect
    self.connection = self.get_new_connection(conn_params)
  File "C:\Python372\mecheck\lib\site-packages\django\db\backends\mysql\base.py", line 227, in get_new_connection
    return Database.connect(**conn_params)
  File "C:\Python372\mecheck\lib\site-packages\pymysql\__init__.py", line 94, in Connect
    return Connection(*args, **kwargs)
  File "C:\Python372\mecheck\lib\site-packages\pymysql\connections.py", line 325, in __init__
    self.connect()
  File "C:\Python372\mecheck\lib\site-packages\pymysql\connections.py", line 630, in connect
    raise exc
django.db.utils.OperationalError: (2003, "Can't connect to MySQL server on '127.0.0.1' ([WinError 10055] 由于系统缓冲区空间不足或队列已满，不能执行套接字上的操作。)")
[2025-02-25 08:42:06,280] [log.py:228] [log:log_response] [ERROR]- Internal Server Error: /Navigations_system/CapitalExpenditure/
Traceback (most recent call last):
  File "C:\Python372\mecheck\lib\site-packages\django\contrib\sessions\backends\base.py", line 190, in _get_session
    return self._session_cache
AttributeError: 'SessionStore' object has no attribute '_session_cache'

During handling of the above exception, another exception occurred:

Traceback (most recent call last):
  File "C:\Python372\mecheck\lib\site-packages\pymysql\connections.py", line 583, in connect
    **kwargs)
  File "C:\Python372\lib\socket.py", line 727, in create_connection
    raise err
  File "C:\Python372\lib\socket.py", line 716, in create_connection
    sock.connect(sa)
OSError: [WinError 10055] 由于系统缓冲区空间不足或队列已满，不能执行套接字上的操作。

During handling of the above exception, another exception occurred:

Traceback (most recent call last):
  File "C:\Python372\mecheck\lib\site-packages\django\db\backends\base\base.py", line 216, in ensure_connection
    self.connect()
  File "C:\Python372\mecheck\lib\site-packages\django\db\backends\base\base.py", line 194, in connect
    self.connection = self.get_new_connection(conn_params)
  File "C:\Python372\mecheck\lib\site-packages\django\db\backends\mysql\base.py", line 227, in get_new_connection
    return Database.connect(**conn_params)
  File "C:\Python372\mecheck\lib\site-packages\pymysql\__init__.py", line 94, in Connect
    return Connection(*args, **kwargs)
  File "C:\Python372\mecheck\lib\site-packages\pymysql\connections.py", line 325, in __init__
    self.connect()
  File "C:\Python372\mecheck\lib\site-packages\pymysql\connections.py", line 630, in connect
    raise exc
pymysql.err.OperationalError: (2003, "Can't connect to MySQL server on '127.0.0.1' ([WinError 10055] 由于系统缓冲区空间不足或队列已满，不能执行套接字上的操作。)")

The above exception was the direct cause of the following exception:

Traceback (most recent call last):
  File "C:\Python372\mecheck\lib\site-packages\django\core\handlers\exception.py", line 34, in inner
    response = get_response(request)
  File "C:\Python372\mecheck\lib\site-packages\django\utils\deprecation.py", line 93, in __call__
    response = self.process_response(request, response)
  File "C:\Python372\mecheck\lib\site-packages\django\contrib\sessions\middleware.py", line 47, in process_response
    if request.session.get_expire_at_browser_close():
  File "C:\Python372\mecheck\lib\site-packages\django\contrib\sessions\backends\base.py", line 279, in get_expire_at_browser_close
    if self.get('_session_expiry') is None:
  File "C:\Python372\mecheck\lib\site-packages\django\contrib\sessions\backends\base.py", line 66, in get
    return self._session.get(key, default)
  File "C:\Python372\mecheck\lib\site-packages\django\contrib\sessions\backends\base.py", line 195, in _get_session
    self._session_cache = self.load()
  File "C:\Python372\mecheck\lib\site-packages\django\contrib\sessions\backends\db.py", line 43, in load
    s = self._get_session_from_db()
  File "C:\Python372\mecheck\lib\site-packages\django\contrib\sessions\backends\db.py", line 34, in _get_session_from_db
    expire_date__gt=timezone.now()
  File "C:\Python372\mecheck\lib\site-packages\django\db\models\manager.py", line 82, in manager_method
    return getattr(self.get_queryset(), name)(*args, **kwargs)
  File "C:\Python372\mecheck\lib\site-packages\django\db\models\query.py", line 393, in get
    num = len(clone)
  File "C:\Python372\mecheck\lib\site-packages\django\db\models\query.py", line 250, in __len__
    self._fetch_all()
  File "C:\Python372\mecheck\lib\site-packages\django\db\models\query.py", line 1186, in _fetch_all
    self._result_cache = list(self._iterable_class(self))
  File "C:\Python372\mecheck\lib\site-packages\django\db\models\query.py", line 54, in __iter__
    results = compiler.execute_sql(chunked_fetch=self.chunked_fetch, chunk_size=self.chunk_size)
  File "C:\Python372\mecheck\lib\site-packages\django\db\models\sql\compiler.py", line 1063, in execute_sql
    cursor = self.connection.cursor()
  File "C:\Python372\mecheck\lib\site-packages\django\db\backends\base\base.py", line 255, in cursor
    return self._cursor()
  File "C:\Python372\mecheck\lib\site-packages\django\db\backends\base\base.py", line 232, in _cursor
    self.ensure_connection()
  File "C:\Python372\mecheck\lib\site-packages\django\db\backends\base\base.py", line 216, in ensure_connection
    self.connect()
  File "C:\Python372\mecheck\lib\site-packages\django\db\utils.py", line 89, in __exit__
    raise dj_exc_value.with_traceback(traceback) from exc_value
  File "C:\Python372\mecheck\lib\site-packages\django\db\backends\base\base.py", line 216, in ensure_connection
    self.connect()
  File "C:\Python372\mecheck\lib\site-packages\django\db\backends\base\base.py", line 194, in connect
    self.connection = self.get_new_connection(conn_params)
  File "C:\Python372\mecheck\lib\site-packages\django\db\backends\mysql\base.py", line 227, in get_new_connection
    return Database.connect(**conn_params)
  File "C:\Python372\mecheck\lib\site-packages\pymysql\__init__.py", line 94, in Connect
    return Connection(*args, **kwargs)
  File "C:\Python372\mecheck\lib\site-packages\pymysql\connections.py", line 325, in __init__
    self.connect()
  File "C:\Python372\mecheck\lib\site-packages\pymysql\connections.py", line 630, in connect
    raise exc
django.db.utils.OperationalError: (2003, "Can't connect to MySQL server on '127.0.0.1' ([WinError 10055] 由于系统缓冲区空间不足或队列已满，不能执行套接字上的操作。)")
[2025-02-25 08:42:07,141] [log.py:228] [log:log_response] [ERROR]- Internal Server Error: /admin/
Traceback (most recent call last):
  File "C:\Python372\mecheck\lib\site-packages\django\contrib\sessions\backends\base.py", line 190, in _get_session
    return self._session_cache
AttributeError: 'SessionStore' object has no attribute '_session_cache'

During handling of the above exception, another exception occurred:

Traceback (most recent call last):
  File "C:\Python372\mecheck\lib\site-packages\pymysql\connections.py", line 583, in connect
    **kwargs)
  File "C:\Python372\lib\socket.py", line 727, in create_connection
    raise err
  File "C:\Python372\lib\socket.py", line 716, in create_connection
    sock.connect(sa)
OSError: [WinError 10055] 由于系统缓冲区空间不足或队列已满，不能执行套接字上的操作。

During handling of the above exception, another exception occurred:

Traceback (most recent call last):
  File "C:\Python372\mecheck\lib\site-packages\django\db\backends\base\base.py", line 216, in ensure_connection
    self.connect()
  File "C:\Python372\mecheck\lib\site-packages\django\db\backends\base\base.py", line 194, in connect
    self.connection = self.get_new_connection(conn_params)
  File "C:\Python372\mecheck\lib\site-packages\django\db\backends\mysql\base.py", line 227, in get_new_connection
    return Database.connect(**conn_params)
  File "C:\Python372\mecheck\lib\site-packages\pymysql\__init__.py", line 94, in Connect
    return Connection(*args, **kwargs)
  File "C:\Python372\mecheck\lib\site-packages\pymysql\connections.py", line 325, in __init__
    self.connect()
  File "C:\Python372\mecheck\lib\site-packages\pymysql\connections.py", line 630, in connect
    raise exc
pymysql.err.OperationalError: (2003, "Can't connect to MySQL server on '127.0.0.1' ([WinError 10055] 由于系统缓冲区空间不足或队列已满，不能执行套接字上的操作。)")

The above exception was the direct cause of the following exception:

Traceback (most recent call last):
  File "C:\Python372\mecheck\lib\site-packages\django\core\handlers\exception.py", line 34, in inner
    response = get_response(request)
  File "C:\Python372\mecheck\lib\site-packages\django\core\handlers\base.py", line 126, in _get_response
    response = self.process_exception_by_middleware(e, request)
  File "C:\Python372\mecheck\lib\site-packages\django\core\handlers\base.py", line 124, in _get_response
    response = wrapped_callback(request, *callback_args, **callback_kwargs)
  File "C:\Python372\mecheck\lib\site-packages\django\contrib\admin\sites.py", line 241, in wrapper
    return self.admin_view(view, cacheable)(*args, **kwargs)
  File "C:\Python372\mecheck\lib\site-packages\django\utils\decorators.py", line 142, in _wrapped_view
    response = view_func(request, *args, **kwargs)
  File "C:\Python372\mecheck\lib\site-packages\django\views\decorators\cache.py", line 44, in _wrapped_view_func
    response = view_func(request, *args, **kwargs)
  File "C:\Python372\mecheck\lib\site-packages\django\contrib\admin\sites.py", line 212, in inner
    if not self.has_permission(request):
  File "C:\Python372\mecheck\lib\site-packages\django\contrib\admin\sites.py", line 186, in has_permission
    return request.user.is_active and request.user.is_staff
  File "C:\Python372\mecheck\lib\site-packages\django\utils\functional.py", line 213, in inner
    self._setup()
  File "C:\Python372\mecheck\lib\site-packages\django\utils\functional.py", line 347, in _setup
    self._wrapped = self._setupfunc()
  File "C:\Python372\mecheck\lib\site-packages\django\contrib\auth\middleware.py", line 24, in <lambda>
    request.user = SimpleLazyObject(lambda: get_user(request))
  File "C:\Python372\mecheck\lib\site-packages\django\contrib\auth\middleware.py", line 12, in get_user
    request._cached_user = auth.get_user(request)
  File "C:\Python372\mecheck\lib\site-packages\django\contrib\auth\__init__.py", line 182, in get_user
    user_id = _get_user_session_key(request)
  File "C:\Python372\mecheck\lib\site-packages\django\contrib\auth\__init__.py", line 59, in _get_user_session_key
    return get_user_model()._meta.pk.to_python(request.session[SESSION_KEY])
  File "C:\Python372\mecheck\lib\site-packages\django\contrib\sessions\backends\base.py", line 55, in __getitem__
    return self._session[key]
  File "C:\Python372\mecheck\lib\site-packages\django\contrib\sessions\backends\base.py", line 195, in _get_session
    self._session_cache = self.load()
  File "C:\Python372\mecheck\lib\site-packages\django\contrib\sessions\backends\db.py", line 43, in load
    s = self._get_session_from_db()
  File "C:\Python372\mecheck\lib\site-packages\django\contrib\sessions\backends\db.py", line 34, in _get_session_from_db
    expire_date__gt=timezone.now()
  File "C:\Python372\mecheck\lib\site-packages\django\db\models\manager.py", line 82, in manager_method
    return getattr(self.get_queryset(), name)(*args, **kwargs)
  File "C:\Python372\mecheck\lib\site-packages\django\db\models\query.py", line 393, in get
    num = len(clone)
  File "C:\Python372\mecheck\lib\site-packages\django\db\models\query.py", line 250, in __len__
    self._fetch_all()
  File "C:\Python372\mecheck\lib\site-packages\django\db\models\query.py", line 1186, in _fetch_all
    self._result_cache = list(self._iterable_class(self))
  File "C:\Python372\mecheck\lib\site-packages\django\db\models\query.py", line 54, in __iter__
    results = compiler.execute_sql(chunked_fetch=self.chunked_fetch, chunk_size=self.chunk_size)
  File "C:\Python372\mecheck\lib\site-packages\django\db\models\sql\compiler.py", line 1063, in execute_sql
    cursor = self.connection.cursor()
  File "C:\Python372\mecheck\lib\site-packages\django\db\backends\base\base.py", line 255, in cursor
    return self._cursor()
  File "C:\Python372\mecheck\lib\site-packages\django\db\backends\base\base.py", line 232, in _cursor
    self.ensure_connection()
  File "C:\Python372\mecheck\lib\site-packages\django\db\backends\base\base.py", line 216, in ensure_connection
    self.connect()
  File "C:\Python372\mecheck\lib\site-packages\django\db\utils.py", line 89, in __exit__
    raise dj_exc_value.with_traceback(traceback) from exc_value
  File "C:\Python372\mecheck\lib\site-packages\django\db\backends\base\base.py", line 216, in ensure_connection
    self.connect()
  File "C:\Python372\mecheck\lib\site-packages\django\db\backends\base\base.py", line 194, in connect
    self.connection = self.get_new_connection(conn_params)
  File "C:\Python372\mecheck\lib\site-packages\django\db\backends\mysql\base.py", line 227, in get_new_connection
    return Database.connect(**conn_params)
  File "C:\Python372\mecheck\lib\site-packages\pymysql\__init__.py", line 94, in Connect
    return Connection(*args, **kwargs)
  File "C:\Python372\mecheck\lib\site-packages\pymysql\connections.py", line 325, in __init__
    self.connect()
  File "C:\Python372\mecheck\lib\site-packages\pymysql\connections.py", line 630, in connect
    raise exc
django.db.utils.OperationalError: (2003, "Can't connect to MySQL server on '127.0.0.1' ([WinError 10055] 由于系统缓冲区空间不足或队列已满，不能执行套接字上的操作。)")
[2025-02-25 08:42:07,335] [log.py:228] [log:log_response] [ERROR]- Internal Server Error: /admin/
Traceback (most recent call last):
  File "C:\Python372\mecheck\lib\site-packages\django\contrib\sessions\backends\base.py", line 190, in _get_session
    return self._session_cache
AttributeError: 'SessionStore' object has no attribute '_session_cache'

During handling of the above exception, another exception occurred:

Traceback (most recent call last):
  File "C:\Python372\mecheck\lib\site-packages\pymysql\connections.py", line 583, in connect
    **kwargs)
  File "C:\Python372\lib\socket.py", line 727, in create_connection
    raise err
  File "C:\Python372\lib\socket.py", line 716, in create_connection
    sock.connect(sa)
OSError: [WinError 10055] 由于系统缓冲区空间不足或队列已满，不能执行套接字上的操作。

During handling of the above exception, another exception occurred:

Traceback (most recent call last):
  File "C:\Python372\mecheck\lib\site-packages\django\db\backends\base\base.py", line 216, in ensure_connection
    self.connect()
  File "C:\Python372\mecheck\lib\site-packages\django\db\backends\base\base.py", line 194, in connect
    self.connection = self.get_new_connection(conn_params)
  File "C:\Python372\mecheck\lib\site-packages\django\db\backends\mysql\base.py", line 227, in get_new_connection
    return Database.connect(**conn_params)
  File "C:\Python372\mecheck\lib\site-packages\pymysql\__init__.py", line 94, in Connect
    return Connection(*args, **kwargs)
  File "C:\Python372\mecheck\lib\site-packages\pymysql\connections.py", line 325, in __init__
    self.connect()
  File "C:\Python372\mecheck\lib\site-packages\pymysql\connections.py", line 630, in connect
    raise exc
pymysql.err.OperationalError: (2003, "Can't connect to MySQL server on '127.0.0.1' ([WinError 10055] 由于系统缓冲区空间不足或队列已满，不能执行套接字上的操作。)")

The above exception was the direct cause of the following exception:

Traceback (most recent call last):
  File "C:\Python372\mecheck\lib\site-packages\django\core\handlers\exception.py", line 34, in inner
    response = get_response(request)
  File "C:\djangoproject\Reliability_Row_data\middleware\checkper.py", line 14, in __call__
    response = self.process_request(request)
  File "C:\djangoproject\Reliability_Row_data\middleware\checkper.py", line 32, in process_request
    permission_url = request.session.get(settings.SESSION_PERMISSION_URL_KEY)
  File "C:\Python372\mecheck\lib\site-packages\django\contrib\sessions\backends\base.py", line 66, in get
    return self._session.get(key, default)
  File "C:\Python372\mecheck\lib\site-packages\django\contrib\sessions\backends\base.py", line 195, in _get_session
    self._session_cache = self.load()
  File "C:\Python372\mecheck\lib\site-packages\django\contrib\sessions\backends\db.py", line 43, in load
    s = self._get_session_from_db()
  File "C:\Python372\mecheck\lib\site-packages\django\contrib\sessions\backends\db.py", line 34, in _get_session_from_db
    expire_date__gt=timezone.now()
  File "C:\Python372\mecheck\lib\site-packages\django\db\models\manager.py", line 82, in manager_method
    return getattr(self.get_queryset(), name)(*args, **kwargs)
  File "C:\Python372\mecheck\lib\site-packages\django\db\models\query.py", line 393, in get
    num = len(clone)
  File "C:\Python372\mecheck\lib\site-packages\django\db\models\query.py", line 250, in __len__
    self._fetch_all()
  File "C:\Python372\mecheck\lib\site-packages\django\db\models\query.py", line 1186, in _fetch_all
    self._result_cache = list(self._iterable_class(self))
  File "C:\Python372\mecheck\lib\site-packages\django\db\models\query.py", line 54, in __iter__
    results = compiler.execute_sql(chunked_fetch=self.chunked_fetch, chunk_size=self.chunk_size)
  File "C:\Python372\mecheck\lib\site-packages\django\db\models\sql\compiler.py", line 1063, in execute_sql
    cursor = self.connection.cursor()
  File "C:\Python372\mecheck\lib\site-packages\django\db\backends\base\base.py", line 255, in cursor
    return self._cursor()
  File "C:\Python372\mecheck\lib\site-packages\django\db\backends\base\base.py", line 232, in _cursor
    self.ensure_connection()
  File "C:\Python372\mecheck\lib\site-packages\django\db\backends\base\base.py", line 216, in ensure_connection
    self.connect()
  File "C:\Python372\mecheck\lib\site-packages\django\db\utils.py", line 89, in __exit__
    raise dj_exc_value.with_traceback(traceback) from exc_value
  File "C:\Python372\mecheck\lib\site-packages\django\db\backends\base\base.py", line 216, in ensure_connection
    self.connect()
  File "C:\Python372\mecheck\lib\site-packages\django\db\backends\base\base.py", line 194, in connect
    self.connection = self.get_new_connection(conn_params)
  File "C:\Python372\mecheck\lib\site-packages\django\db\backends\mysql\base.py", line 227, in get_new_connection
    return Database.connect(**conn_params)
  File "C:\Python372\mecheck\lib\site-packages\pymysql\__init__.py", line 94, in Connect
    return Connection(*args, **kwargs)
  File "C:\Python372\mecheck\lib\site-packages\pymysql\connections.py", line 325, in __init__
    self.connect()
  File "C:\Python372\mecheck\lib\site-packages\pymysql\connections.py", line 630, in connect
    raise exc
django.db.utils.OperationalError: (2003, "Can't connect to MySQL server on '127.0.0.1' ([WinError 10055] 由于系统缓冲区空间不足或队列已满，不能执行套接字上的操作。)")
[2025-02-25 08:42:07,524] [log.py:228] [log:log_response] [ERROR]- Internal Server Error: /admin/
Traceback (most recent call last):
  File "C:\Python372\mecheck\lib\site-packages\django\contrib\sessions\backends\base.py", line 190, in _get_session
    return self._session_cache
AttributeError: 'SessionStore' object has no attribute '_session_cache'

During handling of the above exception, another exception occurred:

Traceback (most recent call last):
  File "C:\Python372\mecheck\lib\site-packages\pymysql\connections.py", line 583, in connect
    **kwargs)
  File "C:\Python372\lib\socket.py", line 727, in create_connection
    raise err
  File "C:\Python372\lib\socket.py", line 716, in create_connection
    sock.connect(sa)
OSError: [WinError 10055] 由于系统缓冲区空间不足或队列已满，不能执行套接字上的操作。

During handling of the above exception, another exception occurred:

Traceback (most recent call last):
  File "C:\Python372\mecheck\lib\site-packages\django\db\backends\base\base.py", line 216, in ensure_connection
    self.connect()
  File "C:\Python372\mecheck\lib\site-packages\django\db\backends\base\base.py", line 194, in connect
    self.connection = self.get_new_connection(conn_params)
  File "C:\Python372\mecheck\lib\site-packages\django\db\backends\mysql\base.py", line 227, in get_new_connection
    return Database.connect(**conn_params)
  File "C:\Python372\mecheck\lib\site-packages\pymysql\__init__.py", line 94, in Connect
    return Connection(*args, **kwargs)
  File "C:\Python372\mecheck\lib\site-packages\pymysql\connections.py", line 325, in __init__
    self.connect()
  File "C:\Python372\mecheck\lib\site-packages\pymysql\connections.py", line 630, in connect
    raise exc
pymysql.err.OperationalError: (2003, "Can't connect to MySQL server on '127.0.0.1' ([WinError 10055] 由于系统缓冲区空间不足或队列已满，不能执行套接字上的操作。)")

The above exception was the direct cause of the following exception:

Traceback (most recent call last):
  File "C:\Python372\mecheck\lib\site-packages\django\core\handlers\exception.py", line 34, in inner
    response = get_response(request)
  File "C:\Python372\mecheck\lib\site-packages\django\utils\deprecation.py", line 93, in __call__
    response = self.process_response(request, response)
  File "C:\Python372\mecheck\lib\site-packages\django\contrib\sessions\middleware.py", line 47, in process_response
    if request.session.get_expire_at_browser_close():
  File "C:\Python372\mecheck\lib\site-packages\django\contrib\sessions\backends\base.py", line 279, in get_expire_at_browser_close
    if self.get('_session_expiry') is None:
  File "C:\Python372\mecheck\lib\site-packages\django\contrib\sessions\backends\base.py", line 66, in get
    return self._session.get(key, default)
  File "C:\Python372\mecheck\lib\site-packages\django\contrib\sessions\backends\base.py", line 195, in _get_session
    self._session_cache = self.load()
  File "C:\Python372\mecheck\lib\site-packages\django\contrib\sessions\backends\db.py", line 43, in load
    s = self._get_session_from_db()
  File "C:\Python372\mecheck\lib\site-packages\django\contrib\sessions\backends\db.py", line 34, in _get_session_from_db
    expire_date__gt=timezone.now()
  File "C:\Python372\mecheck\lib\site-packages\django\db\models\manager.py", line 82, in manager_method
    return getattr(self.get_queryset(), name)(*args, **kwargs)
  File "C:\Python372\mecheck\lib\site-packages\django\db\models\query.py", line 393, in get
    num = len(clone)
  File "C:\Python372\mecheck\lib\site-packages\django\db\models\query.py", line 250, in __len__
    self._fetch_all()
  File "C:\Python372\mecheck\lib\site-packages\django\db\models\query.py", line 1186, in _fetch_all
    self._result_cache = list(self._iterable_class(self))
  File "C:\Python372\mecheck\lib\site-packages\django\db\models\query.py", line 54, in __iter__
    results = compiler.execute_sql(chunked_fetch=self.chunked_fetch, chunk_size=self.chunk_size)
  File "C:\Python372\mecheck\lib\site-packages\django\db\models\sql\compiler.py", line 1063, in execute_sql
    cursor = self.connection.cursor()
  File "C:\Python372\mecheck\lib\site-packages\django\db\backends\base\base.py", line 255, in cursor
    return self._cursor()
  File "C:\Python372\mecheck\lib\site-packages\django\db\backends\base\base.py", line 232, in _cursor
    self.ensure_connection()
  File "C:\Python372\mecheck\lib\site-packages\django\db\backends\base\base.py", line 216, in ensure_connection
    self.connect()
  File "C:\Python372\mecheck\lib\site-packages\django\db\utils.py", line 89, in __exit__
    raise dj_exc_value.with_traceback(traceback) from exc_value
  File "C:\Python372\mecheck\lib\site-packages\django\db\backends\base\base.py", line 216, in ensure_connection
    self.connect()
  File "C:\Python372\mecheck\lib\site-packages\django\db\backends\base\base.py", line 194, in connect
    self.connection = self.get_new_connection(conn_params)
  File "C:\Python372\mecheck\lib\site-packages\django\db\backends\mysql\base.py", line 227, in get_new_connection
    return Database.connect(**conn_params)
  File "C:\Python372\mecheck\lib\site-packages\pymysql\__init__.py", line 94, in Connect
    return Connection(*args, **kwargs)
  File "C:\Python372\mecheck\lib\site-packages\pymysql\connections.py", line 325, in __init__
    self.connect()
  File "C:\Python372\mecheck\lib\site-packages\pymysql\connections.py", line 630, in connect
    raise exc
django.db.utils.OperationalError: (2003, "Can't connect to MySQL server on '127.0.0.1' ([WinError 10055] 由于系统缓冲区空间不足或队列已满，不能执行套接字上的操作。)")
[2025-02-25 08:42:07,548] [runserver.py:154] [runserver:log_action] [ERROR]- HTTP GET /admin/ 500 [0.66, 127.0.0.1:64780]
[2025-02-25 08:42:07,870] [log.py:228] [log:log_response] [ERROR]- Internal Server Error: /favicon.ico
Traceback (most recent call last):
  File "C:\Python372\mecheck\lib\site-packages\django\contrib\sessions\backends\base.py", line 190, in _get_session
    return self._session_cache
AttributeError: 'SessionStore' object has no attribute '_session_cache'

During handling of the above exception, another exception occurred:

Traceback (most recent call last):
  File "C:\Python372\mecheck\lib\site-packages\pymysql\connections.py", line 583, in connect
    **kwargs)
  File "C:\Python372\lib\socket.py", line 727, in create_connection
    raise err
  File "C:\Python372\lib\socket.py", line 716, in create_connection
    sock.connect(sa)
OSError: [WinError 10055] 由于系统缓冲区空间不足或队列已满，不能执行套接字上的操作。

During handling of the above exception, another exception occurred:

Traceback (most recent call last):
  File "C:\Python372\mecheck\lib\site-packages\django\db\backends\base\base.py", line 216, in ensure_connection
    self.connect()
  File "C:\Python372\mecheck\lib\site-packages\django\db\backends\base\base.py", line 194, in connect
    self.connection = self.get_new_connection(conn_params)
  File "C:\Python372\mecheck\lib\site-packages\django\db\backends\mysql\base.py", line 227, in get_new_connection
    return Database.connect(**conn_params)
  File "C:\Python372\mecheck\lib\site-packages\pymysql\__init__.py", line 94, in Connect
    return Connection(*args, **kwargs)
  File "C:\Python372\mecheck\lib\site-packages\pymysql\connections.py", line 325, in __init__
    self.connect()
  File "C:\Python372\mecheck\lib\site-packages\pymysql\connections.py", line 630, in connect
    raise exc
pymysql.err.OperationalError: (2003, "Can't connect to MySQL server on '127.0.0.1' ([WinError 10055] 由于系统缓冲区空间不足或队列已满，不能执行套接字上的操作。)")

The above exception was the direct cause of the following exception:

Traceback (most recent call last):
  File "C:\Python372\mecheck\lib\site-packages\django\core\handlers\exception.py", line 34, in inner
    response = get_response(request)
  File "C:\djangoproject\Reliability_Row_data\middleware\checkper.py", line 14, in __call__
    response = self.process_request(request)
  File "C:\djangoproject\Reliability_Row_data\middleware\checkper.py", line 32, in process_request
    permission_url = request.session.get(settings.SESSION_PERMISSION_URL_KEY)
  File "C:\Python372\mecheck\lib\site-packages\django\contrib\sessions\backends\base.py", line 66, in get
    return self._session.get(key, default)
  File "C:\Python372\mecheck\lib\site-packages\django\contrib\sessions\backends\base.py", line 195, in _get_session
    self._session_cache = self.load()
  File "C:\Python372\mecheck\lib\site-packages\django\contrib\sessions\backends\db.py", line 43, in load
    s = self._get_session_from_db()
  File "C:\Python372\mecheck\lib\site-packages\django\contrib\sessions\backends\db.py", line 34, in _get_session_from_db
    expire_date__gt=timezone.now()
  File "C:\Python372\mecheck\lib\site-packages\django\db\models\manager.py", line 82, in manager_method
    return getattr(self.get_queryset(), name)(*args, **kwargs)
  File "C:\Python372\mecheck\lib\site-packages\django\db\models\query.py", line 393, in get
    num = len(clone)
  File "C:\Python372\mecheck\lib\site-packages\django\db\models\query.py", line 250, in __len__
    self._fetch_all()
  File "C:\Python372\mecheck\lib\site-packages\django\db\models\query.py", line 1186, in _fetch_all
    self._result_cache = list(self._iterable_class(self))
  File "C:\Python372\mecheck\lib\site-packages\django\db\models\query.py", line 54, in __iter__
    results = compiler.execute_sql(chunked_fetch=self.chunked_fetch, chunk_size=self.chunk_size)
  File "C:\Python372\mecheck\lib\site-packages\django\db\models\sql\compiler.py", line 1063, in execute_sql
    cursor = self.connection.cursor()
  File "C:\Python372\mecheck\lib\site-packages\django\db\backends\base\base.py", line 255, in cursor
    return self._cursor()
  File "C:\Python372\mecheck\lib\site-packages\django\db\backends\base\base.py", line 232, in _cursor
    self.ensure_connection()
  File "C:\Python372\mecheck\lib\site-packages\django\db\backends\base\base.py", line 216, in ensure_connection
    self.connect()
  File "C:\Python372\mecheck\lib\site-packages\django\db\utils.py", line 89, in __exit__
    raise dj_exc_value.with_traceback(traceback) from exc_value
  File "C:\Python372\mecheck\lib\site-packages\django\db\backends\base\base.py", line 216, in ensure_connection
    self.connect()
  File "C:\Python372\mecheck\lib\site-packages\django\db\backends\base\base.py", line 194, in connect
    self.connection = self.get_new_connection(conn_params)
  File "C:\Python372\mecheck\lib\site-packages\django\db\backends\mysql\base.py", line 227, in get_new_connection
    return Database.connect(**conn_params)
  File "C:\Python372\mecheck\lib\site-packages\pymysql\__init__.py", line 94, in Connect
    return Connection(*args, **kwargs)
  File "C:\Python372\mecheck\lib\site-packages\pymysql\connections.py", line 325, in __init__
    self.connect()
  File "C:\Python372\mecheck\lib\site-packages\pymysql\connections.py", line 630, in connect
    raise exc
django.db.utils.OperationalError: (2003, "Can't connect to MySQL server on '127.0.0.1' ([WinError 10055] 由于系统缓冲区空间不足或队列已满，不能执行套接字上的操作。)")
[2025-02-25 08:42:08,054] [log.py:228] [log:log_response] [ERROR]- Internal Server Error: /favicon.ico
Traceback (most recent call last):
  File "C:\Python372\mecheck\lib\site-packages\django\contrib\sessions\backends\base.py", line 190, in _get_session
    return self._session_cache
AttributeError: 'SessionStore' object has no attribute '_session_cache'

During handling of the above exception, another exception occurred:

Traceback (most recent call last):
  File "C:\Python372\mecheck\lib\site-packages\pymysql\connections.py", line 583, in connect
    **kwargs)
  File "C:\Python372\lib\socket.py", line 727, in create_connection
    raise err
  File "C:\Python372\lib\socket.py", line 716, in create_connection
    sock.connect(sa)
OSError: [WinError 10055] 由于系统缓冲区空间不足或队列已满，不能执行套接字上的操作。

During handling of the above exception, another exception occurred:

Traceback (most recent call last):
  File "C:\Python372\mecheck\lib\site-packages\django\db\backends\base\base.py", line 216, in ensure_connection
    self.connect()
  File "C:\Python372\mecheck\lib\site-packages\django\db\backends\base\base.py", line 194, in connect
    self.connection = self.get_new_connection(conn_params)
  File "C:\Python372\mecheck\lib\site-packages\django\db\backends\mysql\base.py", line 227, in get_new_connection
    return Database.connect(**conn_params)
  File "C:\Python372\mecheck\lib\site-packages\pymysql\__init__.py", line 94, in Connect
    return Connection(*args, **kwargs)
  File "C:\Python372\mecheck\lib\site-packages\pymysql\connections.py", line 325, in __init__
    self.connect()
  File "C:\Python372\mecheck\lib\site-packages\pymysql\connections.py", line 630, in connect
    raise exc
pymysql.err.OperationalError: (2003, "Can't connect to MySQL server on '127.0.0.1' ([WinError 10055] 由于系统缓冲区空间不足或队列已满，不能执行套接字上的操作。)")

The above exception was the direct cause of the following exception:

Traceback (most recent call last):
  File "C:\Python372\mecheck\lib\site-packages\django\core\handlers\exception.py", line 34, in inner
    response = get_response(request)
  File "C:\Python372\mecheck\lib\site-packages\django\utils\deprecation.py", line 93, in __call__
    response = self.process_response(request, response)
  File "C:\Python372\mecheck\lib\site-packages\django\contrib\sessions\middleware.py", line 47, in process_response
    if request.session.get_expire_at_browser_close():
  File "C:\Python372\mecheck\lib\site-packages\django\contrib\sessions\backends\base.py", line 279, in get_expire_at_browser_close
    if self.get('_session_expiry') is None:
  File "C:\Python372\mecheck\lib\site-packages\django\contrib\sessions\backends\base.py", line 66, in get
    return self._session.get(key, default)
  File "C:\Python372\mecheck\lib\site-packages\django\contrib\sessions\backends\base.py", line 195, in _get_session
    self._session_cache = self.load()
  File "C:\Python372\mecheck\lib\site-packages\django\contrib\sessions\backends\db.py", line 43, in load
    s = self._get_session_from_db()
  File "C:\Python372\mecheck\lib\site-packages\django\contrib\sessions\backends\db.py", line 34, in _get_session_from_db
    expire_date__gt=timezone.now()
  File "C:\Python372\mecheck\lib\site-packages\django\db\models\manager.py", line 82, in manager_method
    return getattr(self.get_queryset(), name)(*args, **kwargs)
  File "C:\Python372\mecheck\lib\site-packages\django\db\models\query.py", line 393, in get
    num = len(clone)
  File "C:\Python372\mecheck\lib\site-packages\django\db\models\query.py", line 250, in __len__
    self._fetch_all()
  File "C:\Python372\mecheck\lib\site-packages\django\db\models\query.py", line 1186, in _fetch_all
    self._result_cache = list(self._iterable_class(self))
  File "C:\Python372\mecheck\lib\site-packages\django\db\models\query.py", line 54, in __iter__
    results = compiler.execute_sql(chunked_fetch=self.chunked_fetch, chunk_size=self.chunk_size)
  File "C:\Python372\mecheck\lib\site-packages\django\db\models\sql\compiler.py", line 1063, in execute_sql
    cursor = self.connection.cursor()
  File "C:\Python372\mecheck\lib\site-packages\django\db\backends\base\base.py", line 255, in cursor
    return self._cursor()
  File "C:\Python372\mecheck\lib\site-packages\django\db\backends\base\base.py", line 232, in _cursor
    self.ensure_connection()
  File "C:\Python372\mecheck\lib\site-packages\django\db\backends\base\base.py", line 216, in ensure_connection
    self.connect()
  File "C:\Python372\mecheck\lib\site-packages\django\db\utils.py", line 89, in __exit__
    raise dj_exc_value.with_traceback(traceback) from exc_value
  File "C:\Python372\mecheck\lib\site-packages\django\db\backends\base\base.py", line 216, in ensure_connection
    self.connect()
  File "C:\Python372\mecheck\lib\site-packages\django\db\backends\base\base.py", line 194, in connect
    self.connection = self.get_new_connection(conn_params)
  File "C:\Python372\mecheck\lib\site-packages\django\db\backends\mysql\base.py", line 227, in get_new_connection
    return Database.connect(**conn_params)
  File "C:\Python372\mecheck\lib\site-packages\pymysql\__init__.py", line 94, in Connect
    return Connection(*args, **kwargs)
  File "C:\Python372\mecheck\lib\site-packages\pymysql\connections.py", line 325, in __init__
    self.connect()
  File "C:\Python372\mecheck\lib\site-packages\pymysql\connections.py", line 630, in connect
    raise exc
django.db.utils.OperationalError: (2003, "Can't connect to MySQL server on '127.0.0.1' ([WinError 10055] 由于系统缓冲区空间不足或队列已满，不能执行套接字上的操作。)")
