[2025-10-17 10:27:54,486] [log.py:228] [log:log_response] [ERROR]- Internal Server Error: /AutoResult/AutoItem_edit/
Traceback (most recent call last):
  File "C:\Python3129\mecheck\lib\site-packages\django\core\handlers\exception.py", line 34, in inner
    response = get_response(request)
  File "C:\Python3129\mecheck\lib\site-packages\django\core\handlers\base.py", line 126, in _get_response
    response = self.process_exception_by_middleware(e, request)
  File "C:\Python3129\mecheck\lib\site-packages\django\core\handlers\base.py", line 124, in _get_response
    response = wrapped_callback(request, *callback_args, **callback_kwargs)
  File "C:\Python3129\mecheck\lib\site-packages\django\views\decorators\csrf.py", line 54, in wrapped_view
    return view_func(*args, **kwargs)
  File "C:\djangoproject\Reliability_Row_data\AutoResult\views.py", line 218, in AutoItem_edit
    AutoItems_object.Attachment.add(empt)
AttributeError: 'int' object has no attribute 'Attachment'
[2025-10-17 10:27:54,509] [runserver.py:154] [runserver:log_action] [ERROR]- HTTP POST /AutoResult/AutoItem_edit/ 500 [1.12, 127.0.0.1:56136]
[2025-10-17 14:33:00,898] [log.py:228] [log:log_response] [ERROR]- Internal Server Error: /AutoResult/AutoResult_edit/
Traceback (most recent call last):
  File "C:\Python3129\mecheck\lib\site-packages\django\core\handlers\exception.py", line 34, in inner
    response = get_response(request)
  File "C:\Python3129\mecheck\lib\site-packages\django\core\handlers\base.py", line 126, in _get_response
    response = self.process_exception_by_middleware(e, request)
  File "C:\Python3129\mecheck\lib\site-packages\django\core\handlers\base.py", line 124, in _get_response
    response = wrapped_callback(request, *callback_args, **callback_kwargs)
  File "C:\Python3129\mecheck\lib\site-packages\django\views\decorators\csrf.py", line 54, in wrapped_view
    return view_func(*args, **kwargs)
  File "C:\djangoproject\Reliability_Row_data\AutoResult\views.py", line 965, in AutoResult_edit
    return HttpResponse(json.dumps(data), content_type="application/json")
  File "C:\Python372\lib\json\__init__.py", line 231, in dumps
    return _default_encoder.encode(obj)
  File "C:\Python372\lib\json\encoder.py", line 199, in encode
    chunks = self.iterencode(o, _one_shot=True)
  File "C:\Python372\lib\json\encoder.py", line 257, in iterencode
    return _iterencode(o, 0)
  File "C:\Python372\lib\json\encoder.py", line 179, in default
    raise TypeError(f'Object of type {o.__class__.__name__} '
TypeError: Object of type date is not JSON serializable
[2025-10-17 14:33:00,909] [runserver.py:154] [runserver:log_action] [ERROR]- HTTP POST /AutoResult/AutoResult_edit/ 500 [3.08, 127.0.0.1:53537]
