[2025-05-22 10:48:01,022] [log.py:228] [log:log_response] [ERROR]- Internal Server Error: /CommonDevice/CommonDevice_edit/
Traceback (most recent call last):
  File "C:\Python3129\mecheck\lib\site-packages\django\db\backends\utils.py", line 85, in _execute
    return self.cursor.execute(sql, params)
  File "C:\Python3129\mecheck\lib\site-packages\django\db\backends\mysql\base.py", line 71, in execute
    return self.cursor.execute(query, args)
  File "C:\Python3129\mecheck\lib\site-packages\pymysql\cursors.py", line 170, in execute
    result = self._query(query)
  File "C:\Python3129\mecheck\lib\site-packages\pymysql\cursors.py", line 328, in _query
    conn.query(q)
  File "C:\Python3129\mecheck\lib\site-packages\pymysql\connections.py", line 517, in query
    self._affected_rows = self._read_query_result(unbuffered=unbuffered)
  File "C:\Python3129\mecheck\lib\site-packages\pymysql\connections.py", line 732, in _read_query_result
    result.read()
  File "C:\Python3129\mecheck\lib\site-packages\pymysql\connections.py", line 1075, in read
    first_packet = self.connection._read_packet()
  File "C:\Python3129\mecheck\lib\site-packages\pymysql\connections.py", line 684, in _read_packet
    packet.check_error()
  File "C:\Python3129\mecheck\lib\site-packages\pymysql\protocol.py", line 220, in check_error
    err.raise_mysql_exception(self._data)
  File "C:\Python3129\mecheck\lib\site-packages\pymysql\err.py", line 109, in raise_mysql_exception
    raise errorclass(errno, errval)
pymysql.err.InternalError: (1054, "Unknown column 'CommonDevice_commondevice.Status' in 'field list'")

The above exception was the direct cause of the following exception:

Traceback (most recent call last):
  File "C:\Python3129\mecheck\lib\site-packages\django\core\handlers\exception.py", line 34, in inner
    response = get_response(request)
  File "C:\Python3129\mecheck\lib\site-packages\django\core\handlers\base.py", line 126, in _get_response
    response = self.process_exception_by_middleware(e, request)
  File "C:\Python3129\mecheck\lib\site-packages\django\core\handlers\base.py", line 124, in _get_response
    response = wrapped_callback(request, *callback_args, **callback_kwargs)
  File "C:\Python3129\mecheck\lib\site-packages\django\views\decorators\csrf.py", line 54, in wrapped_view
    return view_func(*args, **kwargs)
  File "C:\djangoproject\Reliability_Row_data\CommonDevice\views.py", line 239, in CommonDevice_edit
    for i in mock_obj:
  File "C:\Python3129\mecheck\lib\site-packages\django\db\models\query.py", line 268, in __iter__
    self._fetch_all()
  File "C:\Python3129\mecheck\lib\site-packages\django\db\models\query.py", line 1186, in _fetch_all
    self._result_cache = list(self._iterable_class(self))
  File "C:\Python3129\mecheck\lib\site-packages\django\db\models\query.py", line 54, in __iter__
    results = compiler.execute_sql(chunked_fetch=self.chunked_fetch, chunk_size=self.chunk_size)
  File "C:\Python3129\mecheck\lib\site-packages\django\db\models\sql\compiler.py", line 1065, in execute_sql
    cursor.execute(sql, params)
  File "C:\Python3129\mecheck\lib\site-packages\django\db\backends\utils.py", line 100, in execute
    return super().execute(sql, params)
  File "C:\Python3129\mecheck\lib\site-packages\django\db\backends\utils.py", line 68, in execute
    return self._execute_with_wrappers(sql, params, many=False, executor=self._execute)
  File "C:\Python3129\mecheck\lib\site-packages\django\db\backends\utils.py", line 77, in _execute_with_wrappers
    return executor(sql, params, many, context)
  File "C:\Python3129\mecheck\lib\site-packages\django\db\backends\utils.py", line 85, in _execute
    return self.cursor.execute(sql, params)
  File "C:\Python3129\mecheck\lib\site-packages\django\db\utils.py", line 89, in __exit__
    raise dj_exc_value.with_traceback(traceback) from exc_value
  File "C:\Python3129\mecheck\lib\site-packages\django\db\backends\utils.py", line 85, in _execute
    return self.cursor.execute(sql, params)
  File "C:\Python3129\mecheck\lib\site-packages\django\db\backends\mysql\base.py", line 71, in execute
    return self.cursor.execute(query, args)
  File "C:\Python3129\mecheck\lib\site-packages\pymysql\cursors.py", line 170, in execute
    result = self._query(query)
  File "C:\Python3129\mecheck\lib\site-packages\pymysql\cursors.py", line 328, in _query
    conn.query(q)
  File "C:\Python3129\mecheck\lib\site-packages\pymysql\connections.py", line 517, in query
    self._affected_rows = self._read_query_result(unbuffered=unbuffered)
  File "C:\Python3129\mecheck\lib\site-packages\pymysql\connections.py", line 732, in _read_query_result
    result.read()
  File "C:\Python3129\mecheck\lib\site-packages\pymysql\connections.py", line 1075, in read
    first_packet = self.connection._read_packet()
  File "C:\Python3129\mecheck\lib\site-packages\pymysql\connections.py", line 684, in _read_packet
    packet.check_error()
  File "C:\Python3129\mecheck\lib\site-packages\pymysql\protocol.py", line 220, in check_error
    err.raise_mysql_exception(self._data)
  File "C:\Python3129\mecheck\lib\site-packages\pymysql\err.py", line 109, in raise_mysql_exception
    raise errorclass(errno, errval)
django.db.utils.InternalError: (1054, "Unknown column 'CommonDevice_commondevice.Status' in 'field list'")
[2025-05-22 10:48:01,046] [runserver.py:154] [runserver:log_action] [ERROR]- HTTP POST /CommonDevice/CommonDevice_edit/ 500 [0.61, 127.0.0.1:63556]
[2025-05-22 10:58:31,000] [log.py:228] [log:log_response] [ERROR]- Internal Server Error: /admin/CommonDevice/commondevice/
Traceback (most recent call last):
  File "C:\Python3129\mecheck\lib\site-packages\django\db\backends\utils.py", line 85, in _execute
    return self.cursor.execute(sql, params)
  File "C:\Python3129\mecheck\lib\site-packages\django\db\backends\mysql\base.py", line 71, in execute
    return self.cursor.execute(query, args)
  File "C:\Python3129\mecheck\lib\site-packages\pymysql\cursors.py", line 170, in execute
    result = self._query(query)
  File "C:\Python3129\mecheck\lib\site-packages\pymysql\cursors.py", line 328, in _query
    conn.query(q)
  File "C:\Python3129\mecheck\lib\site-packages\pymysql\connections.py", line 517, in query
    self._affected_rows = self._read_query_result(unbuffered=unbuffered)
  File "C:\Python3129\mecheck\lib\site-packages\pymysql\connections.py", line 732, in _read_query_result
    result.read()
  File "C:\Python3129\mecheck\lib\site-packages\pymysql\connections.py", line 1075, in read
    first_packet = self.connection._read_packet()
  File "C:\Python3129\mecheck\lib\site-packages\pymysql\connections.py", line 684, in _read_packet
    packet.check_error()
  File "C:\Python3129\mecheck\lib\site-packages\pymysql\protocol.py", line 220, in check_error
    err.raise_mysql_exception(self._data)
  File "C:\Python3129\mecheck\lib\site-packages\pymysql\err.py", line 109, in raise_mysql_exception
    raise errorclass(errno, errval)
pymysql.err.InternalError: (1054, "Unknown column 'CommonDevice_commondevice.Category_id' in 'field list'")

The above exception was the direct cause of the following exception:

Traceback (most recent call last):
  File "C:\Python3129\mecheck\lib\site-packages\django\core\handlers\exception.py", line 34, in inner
    response = get_response(request)
  File "C:\Python3129\mecheck\lib\site-packages\django\core\handlers\base.py", line 126, in _get_response
    response = self.process_exception_by_middleware(e, request)
  File "C:\Python3129\mecheck\lib\site-packages\django\core\handlers\base.py", line 124, in _get_response
    response = wrapped_callback(request, *callback_args, **callback_kwargs)
  File "C:\Python3129\mecheck\lib\site-packages\django\contrib\admin\options.py", line 604, in wrapper
    return self.admin_site.admin_view(view)(*args, **kwargs)
  File "C:\Python3129\mecheck\lib\site-packages\django\utils\decorators.py", line 142, in _wrapped_view
    response = view_func(request, *args, **kwargs)
  File "C:\Python3129\mecheck\lib\site-packages\django\views\decorators\cache.py", line 44, in _wrapped_view_func
    response = view_func(request, *args, **kwargs)
  File "C:\Python3129\mecheck\lib\site-packages\django\contrib\admin\sites.py", line 223, in inner
    return view(request, *args, **kwargs)
  File "C:\Python3129\mecheck\lib\site-packages\django\utils\decorators.py", line 45, in _wrapper
    return bound_method(*args, **kwargs)
  File "C:\Python3129\mecheck\lib\site-packages\django\utils\decorators.py", line 142, in _wrapped_view
    response = view_func(request, *args, **kwargs)
  File "C:\Python3129\mecheck\lib\site-packages\django\contrib\admin\options.py", line 1717, in changelist_view
    response = self.response_action(request, queryset=cl.get_queryset(request))
  File "C:\Python3129\mecheck\lib\site-packages\django\contrib\admin\options.py", line 1400, in response_action
    response = func(self, request, queryset)
  File "C:\Python3129\mecheck\lib\site-packages\django\contrib\admin\actions.py", line 28, in delete_selected
    deletable_objects, model_count, perms_needed, protected = modeladmin.get_deleted_objects(queryset, request)
  File "C:\Python3129\mecheck\lib\site-packages\django\contrib\admin\options.py", line 1823, in get_deleted_objects
    return get_deleted_objects(objs, request, self.admin_site)
  File "C:\Python3129\mecheck\lib\site-packages\django\contrib\admin\utils.py", line 128, in get_deleted_objects
    obj = objs[0]
  File "C:\Python3129\mecheck\lib\site-packages\django\db\models\query.py", line 302, in __getitem__
    qs._fetch_all()
  File "C:\Python3129\mecheck\lib\site-packages\django\db\models\query.py", line 1186, in _fetch_all
    self._result_cache = list(self._iterable_class(self))
  File "C:\Python3129\mecheck\lib\site-packages\django\db\models\query.py", line 54, in __iter__
    results = compiler.execute_sql(chunked_fetch=self.chunked_fetch, chunk_size=self.chunk_size)
  File "C:\Python3129\mecheck\lib\site-packages\django\db\models\sql\compiler.py", line 1065, in execute_sql
    cursor.execute(sql, params)
  File "C:\Python3129\mecheck\lib\site-packages\django\db\backends\utils.py", line 100, in execute
    return super().execute(sql, params)
  File "C:\Python3129\mecheck\lib\site-packages\django\db\backends\utils.py", line 68, in execute
    return self._execute_with_wrappers(sql, params, many=False, executor=self._execute)
  File "C:\Python3129\mecheck\lib\site-packages\django\db\backends\utils.py", line 77, in _execute_with_wrappers
    return executor(sql, params, many, context)
  File "C:\Python3129\mecheck\lib\site-packages\django\db\backends\utils.py", line 85, in _execute
    return self.cursor.execute(sql, params)
  File "C:\Python3129\mecheck\lib\site-packages\django\db\utils.py", line 89, in __exit__
    raise dj_exc_value.with_traceback(traceback) from exc_value
  File "C:\Python3129\mecheck\lib\site-packages\django\db\backends\utils.py", line 85, in _execute
    return self.cursor.execute(sql, params)
  File "C:\Python3129\mecheck\lib\site-packages\django\db\backends\mysql\base.py", line 71, in execute
    return self.cursor.execute(query, args)
  File "C:\Python3129\mecheck\lib\site-packages\pymysql\cursors.py", line 170, in execute
    result = self._query(query)
  File "C:\Python3129\mecheck\lib\site-packages\pymysql\cursors.py", line 328, in _query
    conn.query(q)
  File "C:\Python3129\mecheck\lib\site-packages\pymysql\connections.py", line 517, in query
    self._affected_rows = self._read_query_result(unbuffered=unbuffered)
  File "C:\Python3129\mecheck\lib\site-packages\pymysql\connections.py", line 732, in _read_query_result
    result.read()
  File "C:\Python3129\mecheck\lib\site-packages\pymysql\connections.py", line 1075, in read
    first_packet = self.connection._read_packet()
  File "C:\Python3129\mecheck\lib\site-packages\pymysql\connections.py", line 684, in _read_packet
    packet.check_error()
  File "C:\Python3129\mecheck\lib\site-packages\pymysql\protocol.py", line 220, in check_error
    err.raise_mysql_exception(self._data)
  File "C:\Python3129\mecheck\lib\site-packages\pymysql\err.py", line 109, in raise_mysql_exception
    raise errorclass(errno, errval)
django.db.utils.InternalError: (1054, "Unknown column 'CommonDevice_commondevice.Category_id' in 'field list'")
[2025-05-22 10:58:31,056] [runserver.py:154] [runserver:log_action] [ERROR]- HTTP POST /admin/CommonDevice/commondevice/ 500 [1.24, 127.0.0.1:63716]
[2025-05-22 10:59:20,844] [log.py:228] [log:log_response] [ERROR]- Internal Server Error: /admin/CommonDevice/commondevice/
Traceback (most recent call last):
  File "C:\Python3129\mecheck\lib\site-packages\django\db\backends\utils.py", line 85, in _execute
    return self.cursor.execute(sql, params)
  File "C:\Python3129\mecheck\lib\site-packages\django\db\backends\mysql\base.py", line 71, in execute
    return self.cursor.execute(query, args)
  File "C:\Python3129\mecheck\lib\site-packages\pymysql\cursors.py", line 170, in execute
    result = self._query(query)
  File "C:\Python3129\mecheck\lib\site-packages\pymysql\cursors.py", line 328, in _query
    conn.query(q)
  File "C:\Python3129\mecheck\lib\site-packages\pymysql\connections.py", line 517, in query
    self._affected_rows = self._read_query_result(unbuffered=unbuffered)
  File "C:\Python3129\mecheck\lib\site-packages\pymysql\connections.py", line 732, in _read_query_result
    result.read()
  File "C:\Python3129\mecheck\lib\site-packages\pymysql\connections.py", line 1075, in read
    first_packet = self.connection._read_packet()
  File "C:\Python3129\mecheck\lib\site-packages\pymysql\connections.py", line 684, in _read_packet
    packet.check_error()
  File "C:\Python3129\mecheck\lib\site-packages\pymysql\protocol.py", line 220, in check_error
    err.raise_mysql_exception(self._data)
  File "C:\Python3129\mecheck\lib\site-packages\pymysql\err.py", line 109, in raise_mysql_exception
    raise errorclass(errno, errval)
pymysql.err.InternalError: (1054, "Unknown column 'CommonDevice_commondevice.Category_id' in 'field list'")

The above exception was the direct cause of the following exception:

Traceback (most recent call last):
  File "C:\Python3129\mecheck\lib\site-packages\django\core\handlers\exception.py", line 34, in inner
    response = get_response(request)
  File "C:\Python3129\mecheck\lib\site-packages\django\core\handlers\base.py", line 126, in _get_response
    response = self.process_exception_by_middleware(e, request)
  File "C:\Python3129\mecheck\lib\site-packages\django\core\handlers\base.py", line 124, in _get_response
    response = wrapped_callback(request, *callback_args, **callback_kwargs)
  File "C:\Python3129\mecheck\lib\site-packages\django\contrib\admin\options.py", line 604, in wrapper
    return self.admin_site.admin_view(view)(*args, **kwargs)
  File "C:\Python3129\mecheck\lib\site-packages\django\utils\decorators.py", line 142, in _wrapped_view
    response = view_func(request, *args, **kwargs)
  File "C:\Python3129\mecheck\lib\site-packages\django\views\decorators\cache.py", line 44, in _wrapped_view_func
    response = view_func(request, *args, **kwargs)
  File "C:\Python3129\mecheck\lib\site-packages\django\contrib\admin\sites.py", line 223, in inner
    return view(request, *args, **kwargs)
  File "C:\Python3129\mecheck\lib\site-packages\django\utils\decorators.py", line 45, in _wrapper
    return bound_method(*args, **kwargs)
  File "C:\Python3129\mecheck\lib\site-packages\django\utils\decorators.py", line 142, in _wrapped_view
    response = view_func(request, *args, **kwargs)
  File "C:\Python3129\mecheck\lib\site-packages\django\contrib\admin\options.py", line 1793, in changelist_view
    'selection_note': _('0 of %(cnt)s selected') % {'cnt': len(cl.result_list)},
  File "C:\Python3129\mecheck\lib\site-packages\django\db\models\query.py", line 250, in __len__
    self._fetch_all()
  File "C:\Python3129\mecheck\lib\site-packages\django\db\models\query.py", line 1186, in _fetch_all
    self._result_cache = list(self._iterable_class(self))
  File "C:\Python3129\mecheck\lib\site-packages\django\db\models\query.py", line 54, in __iter__
    results = compiler.execute_sql(chunked_fetch=self.chunked_fetch, chunk_size=self.chunk_size)
  File "C:\Python3129\mecheck\lib\site-packages\django\db\models\sql\compiler.py", line 1065, in execute_sql
    cursor.execute(sql, params)
  File "C:\Python3129\mecheck\lib\site-packages\django\db\backends\utils.py", line 100, in execute
    return super().execute(sql, params)
  File "C:\Python3129\mecheck\lib\site-packages\django\db\backends\utils.py", line 68, in execute
    return self._execute_with_wrappers(sql, params, many=False, executor=self._execute)
  File "C:\Python3129\mecheck\lib\site-packages\django\db\backends\utils.py", line 77, in _execute_with_wrappers
    return executor(sql, params, many, context)
  File "C:\Python3129\mecheck\lib\site-packages\django\db\backends\utils.py", line 85, in _execute
    return self.cursor.execute(sql, params)
  File "C:\Python3129\mecheck\lib\site-packages\django\db\utils.py", line 89, in __exit__
    raise dj_exc_value.with_traceback(traceback) from exc_value
  File "C:\Python3129\mecheck\lib\site-packages\django\db\backends\utils.py", line 85, in _execute
    return self.cursor.execute(sql, params)
  File "C:\Python3129\mecheck\lib\site-packages\django\db\backends\mysql\base.py", line 71, in execute
    return self.cursor.execute(query, args)
  File "C:\Python3129\mecheck\lib\site-packages\pymysql\cursors.py", line 170, in execute
    result = self._query(query)
  File "C:\Python3129\mecheck\lib\site-packages\pymysql\cursors.py", line 328, in _query
    conn.query(q)
  File "C:\Python3129\mecheck\lib\site-packages\pymysql\connections.py", line 517, in query
    self._affected_rows = self._read_query_result(unbuffered=unbuffered)
  File "C:\Python3129\mecheck\lib\site-packages\pymysql\connections.py", line 732, in _read_query_result
    result.read()
  File "C:\Python3129\mecheck\lib\site-packages\pymysql\connections.py", line 1075, in read
    first_packet = self.connection._read_packet()
  File "C:\Python3129\mecheck\lib\site-packages\pymysql\connections.py", line 684, in _read_packet
    packet.check_error()
  File "C:\Python3129\mecheck\lib\site-packages\pymysql\protocol.py", line 220, in check_error
    err.raise_mysql_exception(self._data)
  File "C:\Python3129\mecheck\lib\site-packages\pymysql\err.py", line 109, in raise_mysql_exception
    raise errorclass(errno, errval)
django.db.utils.InternalError: (1054, "Unknown column 'CommonDevice_commondevice.Category_id' in 'field list'")
[2025-05-22 10:59:20,859] [runserver.py:154] [runserver:log_action] [ERROR]- HTTP GET /admin/CommonDevice/commondevice/ 500 [0.15, 127.0.0.1:63716]
[2025-05-22 10:59:38,684] [log.py:228] [log:log_response] [ERROR]- Internal Server Error: /admin/CommonDevice/commondevice/
Traceback (most recent call last):
  File "C:\Python3129\mecheck\lib\site-packages\django\db\backends\utils.py", line 85, in _execute
    return self.cursor.execute(sql, params)
  File "C:\Python3129\mecheck\lib\site-packages\django\db\backends\mysql\base.py", line 71, in execute
    return self.cursor.execute(query, args)
  File "C:\Python3129\mecheck\lib\site-packages\pymysql\cursors.py", line 170, in execute
    result = self._query(query)
  File "C:\Python3129\mecheck\lib\site-packages\pymysql\cursors.py", line 328, in _query
    conn.query(q)
  File "C:\Python3129\mecheck\lib\site-packages\pymysql\connections.py", line 517, in query
    self._affected_rows = self._read_query_result(unbuffered=unbuffered)
  File "C:\Python3129\mecheck\lib\site-packages\pymysql\connections.py", line 732, in _read_query_result
    result.read()
  File "C:\Python3129\mecheck\lib\site-packages\pymysql\connections.py", line 1075, in read
    first_packet = self.connection._read_packet()
  File "C:\Python3129\mecheck\lib\site-packages\pymysql\connections.py", line 684, in _read_packet
    packet.check_error()
  File "C:\Python3129\mecheck\lib\site-packages\pymysql\protocol.py", line 220, in check_error
    err.raise_mysql_exception(self._data)
  File "C:\Python3129\mecheck\lib\site-packages\pymysql\err.py", line 109, in raise_mysql_exception
    raise errorclass(errno, errval)
pymysql.err.InternalError: (1054, "Unknown column 'CommonDevice_commondevice.Category_id' in 'field list'")

The above exception was the direct cause of the following exception:

Traceback (most recent call last):
  File "C:\Python3129\mecheck\lib\site-packages\django\core\handlers\exception.py", line 34, in inner
    response = get_response(request)
  File "C:\Python3129\mecheck\lib\site-packages\django\core\handlers\base.py", line 126, in _get_response
    response = self.process_exception_by_middleware(e, request)
  File "C:\Python3129\mecheck\lib\site-packages\django\core\handlers\base.py", line 124, in _get_response
    response = wrapped_callback(request, *callback_args, **callback_kwargs)
  File "C:\Python3129\mecheck\lib\site-packages\django\contrib\admin\options.py", line 604, in wrapper
    return self.admin_site.admin_view(view)(*args, **kwargs)
  File "C:\Python3129\mecheck\lib\site-packages\django\utils\decorators.py", line 142, in _wrapped_view
    response = view_func(request, *args, **kwargs)
  File "C:\Python3129\mecheck\lib\site-packages\django\views\decorators\cache.py", line 44, in _wrapped_view_func
    response = view_func(request, *args, **kwargs)
  File "C:\Python3129\mecheck\lib\site-packages\django\contrib\admin\sites.py", line 223, in inner
    return view(request, *args, **kwargs)
  File "C:\Python3129\mecheck\lib\site-packages\django\utils\decorators.py", line 45, in _wrapper
    return bound_method(*args, **kwargs)
  File "C:\Python3129\mecheck\lib\site-packages\django\utils\decorators.py", line 142, in _wrapped_view
    response = view_func(request, *args, **kwargs)
  File "C:\Python3129\mecheck\lib\site-packages\django\contrib\admin\options.py", line 1793, in changelist_view
    'selection_note': _('0 of %(cnt)s selected') % {'cnt': len(cl.result_list)},
  File "C:\Python3129\mecheck\lib\site-packages\django\db\models\query.py", line 250, in __len__
    self._fetch_all()
  File "C:\Python3129\mecheck\lib\site-packages\django\db\models\query.py", line 1186, in _fetch_all
    self._result_cache = list(self._iterable_class(self))
  File "C:\Python3129\mecheck\lib\site-packages\django\db\models\query.py", line 54, in __iter__
    results = compiler.execute_sql(chunked_fetch=self.chunked_fetch, chunk_size=self.chunk_size)
  File "C:\Python3129\mecheck\lib\site-packages\django\db\models\sql\compiler.py", line 1065, in execute_sql
    cursor.execute(sql, params)
  File "C:\Python3129\mecheck\lib\site-packages\django\db\backends\utils.py", line 100, in execute
    return super().execute(sql, params)
  File "C:\Python3129\mecheck\lib\site-packages\django\db\backends\utils.py", line 68, in execute
    return self._execute_with_wrappers(sql, params, many=False, executor=self._execute)
  File "C:\Python3129\mecheck\lib\site-packages\django\db\backends\utils.py", line 77, in _execute_with_wrappers
    return executor(sql, params, many, context)
  File "C:\Python3129\mecheck\lib\site-packages\django\db\backends\utils.py", line 85, in _execute
    return self.cursor.execute(sql, params)
  File "C:\Python3129\mecheck\lib\site-packages\django\db\utils.py", line 89, in __exit__
    raise dj_exc_value.with_traceback(traceback) from exc_value
  File "C:\Python3129\mecheck\lib\site-packages\django\db\backends\utils.py", line 85, in _execute
    return self.cursor.execute(sql, params)
  File "C:\Python3129\mecheck\lib\site-packages\django\db\backends\mysql\base.py", line 71, in execute
    return self.cursor.execute(query, args)
  File "C:\Python3129\mecheck\lib\site-packages\pymysql\cursors.py", line 170, in execute
    result = self._query(query)
  File "C:\Python3129\mecheck\lib\site-packages\pymysql\cursors.py", line 328, in _query
    conn.query(q)
  File "C:\Python3129\mecheck\lib\site-packages\pymysql\connections.py", line 517, in query
    self._affected_rows = self._read_query_result(unbuffered=unbuffered)
  File "C:\Python3129\mecheck\lib\site-packages\pymysql\connections.py", line 732, in _read_query_result
    result.read()
  File "C:\Python3129\mecheck\lib\site-packages\pymysql\connections.py", line 1075, in read
    first_packet = self.connection._read_packet()
  File "C:\Python3129\mecheck\lib\site-packages\pymysql\connections.py", line 684, in _read_packet
    packet.check_error()
  File "C:\Python3129\mecheck\lib\site-packages\pymysql\protocol.py", line 220, in check_error
    err.raise_mysql_exception(self._data)
  File "C:\Python3129\mecheck\lib\site-packages\pymysql\err.py", line 109, in raise_mysql_exception
    raise errorclass(errno, errval)
django.db.utils.InternalError: (1054, "Unknown column 'CommonDevice_commondevice.Category_id' in 'field list'")
[2025-05-22 10:59:38,721] [runserver.py:154] [runserver:log_action] [ERROR]- HTTP GET /admin/CommonDevice/commondevice/ 500 [0.26, 127.0.0.1:63716]
[2025-05-22 11:00:37,756] [log.py:228] [log:log_response] [ERROR]- Internal Server Error: /admin/CommonDevice/commondevice/
Traceback (most recent call last):
  File "C:\Python3129\mecheck\lib\site-packages\django\db\backends\utils.py", line 85, in _execute
    return self.cursor.execute(sql, params)
  File "C:\Python3129\mecheck\lib\site-packages\django\db\backends\mysql\base.py", line 71, in execute
    return self.cursor.execute(query, args)
  File "C:\Python3129\mecheck\lib\site-packages\pymysql\cursors.py", line 170, in execute
    result = self._query(query)
  File "C:\Python3129\mecheck\lib\site-packages\pymysql\cursors.py", line 328, in _query
    conn.query(q)
  File "C:\Python3129\mecheck\lib\site-packages\pymysql\connections.py", line 517, in query
    self._affected_rows = self._read_query_result(unbuffered=unbuffered)
  File "C:\Python3129\mecheck\lib\site-packages\pymysql\connections.py", line 732, in _read_query_result
    result.read()
  File "C:\Python3129\mecheck\lib\site-packages\pymysql\connections.py", line 1075, in read
    first_packet = self.connection._read_packet()
  File "C:\Python3129\mecheck\lib\site-packages\pymysql\connections.py", line 684, in _read_packet
    packet.check_error()
  File "C:\Python3129\mecheck\lib\site-packages\pymysql\protocol.py", line 220, in check_error
    err.raise_mysql_exception(self._data)
  File "C:\Python3129\mecheck\lib\site-packages\pymysql\err.py", line 109, in raise_mysql_exception
    raise errorclass(errno, errval)
pymysql.err.InternalError: (1054, "Unknown column 'CommonDevice_commondevice.Category_id' in 'field list'")

The above exception was the direct cause of the following exception:

Traceback (most recent call last):
  File "C:\Python3129\mecheck\lib\site-packages\django\core\handlers\exception.py", line 34, in inner
    response = get_response(request)
  File "C:\Python3129\mecheck\lib\site-packages\django\core\handlers\base.py", line 126, in _get_response
    response = self.process_exception_by_middleware(e, request)
  File "C:\Python3129\mecheck\lib\site-packages\django\core\handlers\base.py", line 124, in _get_response
    response = wrapped_callback(request, *callback_args, **callback_kwargs)
  File "C:\Python3129\mecheck\lib\site-packages\django\contrib\admin\options.py", line 604, in wrapper
    return self.admin_site.admin_view(view)(*args, **kwargs)
  File "C:\Python3129\mecheck\lib\site-packages\django\utils\decorators.py", line 142, in _wrapped_view
    response = view_func(request, *args, **kwargs)
  File "C:\Python3129\mecheck\lib\site-packages\django\views\decorators\cache.py", line 44, in _wrapped_view_func
    response = view_func(request, *args, **kwargs)
  File "C:\Python3129\mecheck\lib\site-packages\django\contrib\admin\sites.py", line 223, in inner
    return view(request, *args, **kwargs)
  File "C:\Python3129\mecheck\lib\site-packages\django\utils\decorators.py", line 45, in _wrapper
    return bound_method(*args, **kwargs)
  File "C:\Python3129\mecheck\lib\site-packages\django\utils\decorators.py", line 142, in _wrapped_view
    response = view_func(request, *args, **kwargs)
  File "C:\Python3129\mecheck\lib\site-packages\django\contrib\admin\options.py", line 1793, in changelist_view
    'selection_note': _('0 of %(cnt)s selected') % {'cnt': len(cl.result_list)},
  File "C:\Python3129\mecheck\lib\site-packages\django\db\models\query.py", line 250, in __len__
    self._fetch_all()
  File "C:\Python3129\mecheck\lib\site-packages\django\db\models\query.py", line 1186, in _fetch_all
    self._result_cache = list(self._iterable_class(self))
  File "C:\Python3129\mecheck\lib\site-packages\django\db\models\query.py", line 54, in __iter__
    results = compiler.execute_sql(chunked_fetch=self.chunked_fetch, chunk_size=self.chunk_size)
  File "C:\Python3129\mecheck\lib\site-packages\django\db\models\sql\compiler.py", line 1065, in execute_sql
    cursor.execute(sql, params)
  File "C:\Python3129\mecheck\lib\site-packages\django\db\backends\utils.py", line 100, in execute
    return super().execute(sql, params)
  File "C:\Python3129\mecheck\lib\site-packages\django\db\backends\utils.py", line 68, in execute
    return self._execute_with_wrappers(sql, params, many=False, executor=self._execute)
  File "C:\Python3129\mecheck\lib\site-packages\django\db\backends\utils.py", line 77, in _execute_with_wrappers
    return executor(sql, params, many, context)
  File "C:\Python3129\mecheck\lib\site-packages\django\db\backends\utils.py", line 85, in _execute
    return self.cursor.execute(sql, params)
  File "C:\Python3129\mecheck\lib\site-packages\django\db\utils.py", line 89, in __exit__
    raise dj_exc_value.with_traceback(traceback) from exc_value
  File "C:\Python3129\mecheck\lib\site-packages\django\db\backends\utils.py", line 85, in _execute
    return self.cursor.execute(sql, params)
  File "C:\Python3129\mecheck\lib\site-packages\django\db\backends\mysql\base.py", line 71, in execute
    return self.cursor.execute(query, args)
  File "C:\Python3129\mecheck\lib\site-packages\pymysql\cursors.py", line 170, in execute
    result = self._query(query)
  File "C:\Python3129\mecheck\lib\site-packages\pymysql\cursors.py", line 328, in _query
    conn.query(q)
  File "C:\Python3129\mecheck\lib\site-packages\pymysql\connections.py", line 517, in query
    self._affected_rows = self._read_query_result(unbuffered=unbuffered)
  File "C:\Python3129\mecheck\lib\site-packages\pymysql\connections.py", line 732, in _read_query_result
    result.read()
  File "C:\Python3129\mecheck\lib\site-packages\pymysql\connections.py", line 1075, in read
    first_packet = self.connection._read_packet()
  File "C:\Python3129\mecheck\lib\site-packages\pymysql\connections.py", line 684, in _read_packet
    packet.check_error()
  File "C:\Python3129\mecheck\lib\site-packages\pymysql\protocol.py", line 220, in check_error
    err.raise_mysql_exception(self._data)
  File "C:\Python3129\mecheck\lib\site-packages\pymysql\err.py", line 109, in raise_mysql_exception
    raise errorclass(errno, errval)
django.db.utils.InternalError: (1054, "Unknown column 'CommonDevice_commondevice.Category_id' in 'field list'")
[2025-05-22 11:00:37,785] [runserver.py:154] [runserver:log_action] [ERROR]- HTTP GET /admin/CommonDevice/commondevice/ 500 [0.22, 127.0.0.1:65197]
[2025-05-22 12:02:19,939] [log.py:228] [log:log_response] [ERROR]- Internal Server Error: /CommonDevice/CommonDevice_edit/
Traceback (most recent call last):
  File "C:\Python3129\mecheck\lib\site-packages\django\core\handlers\exception.py", line 34, in inner
    response = get_response(request)
  File "C:\Python3129\mecheck\lib\site-packages\django\core\handlers\base.py", line 126, in _get_response
    response = self.process_exception_by_middleware(e, request)
  File "C:\Python3129\mecheck\lib\site-packages\django\core\handlers\base.py", line 124, in _get_response
    response = wrapped_callback(request, *callback_args, **callback_kwargs)
  File "C:\Python3129\mecheck\lib\site-packages\django\views\decorators\csrf.py", line 54, in wrapped_view
    return view_func(*args, **kwargs)
  File "C:\djangoproject\Reliability_Row_data\CommonDevice\views.py", line 38, in CommonDevice_edit
    for j in SubCategory.objects.filter(category=i['name']).values('name').distinct():
  File "C:\Python3129\mecheck\lib\site-packages\django\db\models\manager.py", line 82, in manager_method
    return getattr(self.get_queryset(), name)(*args, **kwargs)
  File "C:\Python3129\mecheck\lib\site-packages\django\db\models\query.py", line 844, in filter
    return self._filter_or_exclude(False, *args, **kwargs)
  File "C:\Python3129\mecheck\lib\site-packages\django\db\models\query.py", line 862, in _filter_or_exclude
    clone.query.add_q(Q(*args, **kwargs))
  File "C:\Python3129\mecheck\lib\site-packages\django\db\models\sql\query.py", line 1263, in add_q
    clause, _ = self._add_q(q_object, self.used_aliases)
  File "C:\Python3129\mecheck\lib\site-packages\django\db\models\sql\query.py", line 1287, in _add_q
    split_subq=split_subq,
  File "C:\Python3129\mecheck\lib\site-packages\django\db\models\sql\query.py", line 1225, in build_filter
    condition = self.build_lookup(lookups, col, value)
  File "C:\Python3129\mecheck\lib\site-packages\django\db\models\sql\query.py", line 1096, in build_lookup
    lookup = lookup_class(lhs, rhs)
  File "C:\Python3129\mecheck\lib\site-packages\django\db\models\lookups.py", line 20, in __init__
    self.rhs = self.get_prep_lookup()
  File "C:\Python3129\mecheck\lib\site-packages\django\db\models\fields\related_lookups.py", line 115, in get_prep_lookup
    self.rhs = target_field.get_prep_value(self.rhs)
  File "C:\Python3129\mecheck\lib\site-packages\django\db\models\fields\__init__.py", line 965, in get_prep_value
    return int(value)
ValueError: invalid literal for int() with base 10: '網絡設備'
[2025-05-22 12:02:19,962] [runserver.py:154] [runserver:log_action] [ERROR]- HTTP GET /CommonDevice/CommonDevice_edit/ 500 [0.43, 127.0.0.1:61597]
[2025-05-22 13:07:13,299] [log.py:228] [log:log_response] [ERROR]- Internal Server Error: /CommonDevice/CommonDevice_edit/
Traceback (most recent call last):
  File "C:\Python3129\mecheck\lib\site-packages\django\core\handlers\exception.py", line 34, in inner
    response = get_response(request)
  File "C:\Python3129\mecheck\lib\site-packages\django\core\handlers\base.py", line 126, in _get_response
    response = self.process_exception_by_middleware(e, request)
  File "C:\Python3129\mecheck\lib\site-packages\django\core\handlers\base.py", line 124, in _get_response
    response = wrapped_callback(request, *callback_args, **callback_kwargs)
  File "C:\Python3129\mecheck\lib\site-packages\django\views\decorators\csrf.py", line 54, in wrapped_view
    return view_func(*args, **kwargs)
  File "C:\djangoproject\Reliability_Row_data\CommonDevice\views.py", line 288, in CommonDevice_edit
    "Status": i.Status,
AttributeError: 'CommonDevice' object has no attribute 'Status'
[2025-05-22 13:07:13,308] [runserver.py:154] [runserver:log_action] [ERROR]- HTTP POST /CommonDevice/CommonDevice_edit/ 500 [0.58, 127.0.0.1:64819]
[2025-05-22 13:08:33,824] [log.py:228] [log:log_response] [ERROR]- Internal Server Error: /CommonDevice/CommonDevice_edit/
Traceback (most recent call last):
  File "C:\Python3129\mecheck\lib\site-packages\django\core\handlers\exception.py", line 34, in inner
    response = get_response(request)
  File "C:\Python3129\mecheck\lib\site-packages\django\core\handlers\base.py", line 126, in _get_response
    response = self.process_exception_by_middleware(e, request)
  File "C:\Python3129\mecheck\lib\site-packages\django\core\handlers\base.py", line 124, in _get_response
    response = wrapped_callback(request, *callback_args, **callback_kwargs)
  File "C:\Python3129\mecheck\lib\site-packages\django\views\decorators\csrf.py", line 54, in wrapped_view
    return view_func(*args, **kwargs)
  File "C:\djangoproject\Reliability_Row_data\CommonDevice\views.py", line 314, in CommonDevice_edit
    return HttpResponse(json.dumps(data), content_type="application/json")
  File "C:\Python372\lib\json\__init__.py", line 231, in dumps
    return _default_encoder.encode(obj)
  File "C:\Python372\lib\json\encoder.py", line 199, in encode
    chunks = self.iterencode(o, _one_shot=True)
  File "C:\Python372\lib\json\encoder.py", line 257, in iterencode
    return _iterencode(o, 0)
  File "C:\Python372\lib\json\encoder.py", line 179, in default
    raise TypeError(f'Object of type {o.__class__.__name__} '
TypeError: Object of type Category is not JSON serializable
[2025-05-22 13:08:33,831] [runserver.py:154] [runserver:log_action] [ERROR]- HTTP POST /CommonDevice/CommonDevice_edit/ 500 [0.60, 127.0.0.1:50878]
[2025-05-22 13:10:30,078] [log.py:228] [log:log_response] [ERROR]- Internal Server Error: /CommonDevice/CommonDevice_edit/
Traceback (most recent call last):
  File "C:\Python3129\mecheck\lib\site-packages\django\core\handlers\exception.py", line 34, in inner
    response = get_response(request)
  File "C:\Python3129\mecheck\lib\site-packages\django\core\handlers\base.py", line 126, in _get_response
    response = self.process_exception_by_middleware(e, request)
  File "C:\Python3129\mecheck\lib\site-packages\django\core\handlers\base.py", line 124, in _get_response
    response = wrapped_callback(request, *callback_args, **callback_kwargs)
  File "C:\Python3129\mecheck\lib\site-packages\django\views\decorators\csrf.py", line 54, in wrapped_view
    return view_func(*args, **kwargs)
  File "C:\djangoproject\Reliability_Row_data\CommonDevice\views.py", line 316, in CommonDevice_edit
    return HttpResponse(json.dumps(data), content_type="application/json")
  File "C:\Python372\lib\json\__init__.py", line 231, in dumps
    return _default_encoder.encode(obj)
  File "C:\Python372\lib\json\encoder.py", line 199, in encode
    chunks = self.iterencode(o, _one_shot=True)
  File "C:\Python372\lib\json\encoder.py", line 257, in iterencode
    return _iterencode(o, 0)
  File "C:\Python372\lib\json\encoder.py", line 179, in default
    raise TypeError(f'Object of type {o.__class__.__name__} '
TypeError: Object of type Category is not JSON serializable
[2025-05-22 13:10:30,086] [runserver.py:154] [runserver:log_action] [ERROR]- HTTP POST /CommonDevice/CommonDevice_edit/ 500 [0.54, 127.0.0.1:53966]
[2025-05-22 13:12:04,569] [log.py:228] [log:log_response] [ERROR]- Internal Server Error: /CommonDevice/CommonDevice_edit/
Traceback (most recent call last):
  File "C:\Python3129\mecheck\lib\site-packages\django\core\handlers\exception.py", line 34, in inner
    response = get_response(request)
  File "C:\Python3129\mecheck\lib\site-packages\django\core\handlers\base.py", line 126, in _get_response
    response = self.process_exception_by_middleware(e, request)
  File "C:\Python3129\mecheck\lib\site-packages\django\core\handlers\base.py", line 124, in _get_response
    response = wrapped_callback(request, *callback_args, **callback_kwargs)
  File "C:\Python3129\mecheck\lib\site-packages\django\views\decorators\csrf.py", line 54, in wrapped_view
    return view_func(*args, **kwargs)
  File "C:\djangoproject\Reliability_Row_data\CommonDevice\views.py", line 316, in CommonDevice_edit
    return HttpResponse(json.dumps(data), content_type="application/json")
  File "C:\Python372\lib\json\__init__.py", line 231, in dumps
    return _default_encoder.encode(obj)
  File "C:\Python372\lib\json\encoder.py", line 199, in encode
    chunks = self.iterencode(o, _one_shot=True)
  File "C:\Python372\lib\json\encoder.py", line 257, in iterencode
    return _iterencode(o, 0)
  File "C:\Python372\lib\json\encoder.py", line 179, in default
    raise TypeError(f'Object of type {o.__class__.__name__} '
TypeError: Object of type Category is not JSON serializable
[2025-05-22 13:12:04,577] [runserver.py:154] [runserver:log_action] [ERROR]- HTTP POST /CommonDevice/CommonDevice_edit/ 500 [0.44, 127.0.0.1:56385]
[2025-05-22 13:13:31,652] [log.py:228] [log:log_response] [ERROR]- Internal Server Error: /CommonDevice/CommonDevice_edit/
Traceback (most recent call last):
  File "C:\Python3129\mecheck\lib\site-packages\django\core\handlers\exception.py", line 34, in inner
    response = get_response(request)
  File "C:\Python3129\mecheck\lib\site-packages\django\core\handlers\base.py", line 126, in _get_response
    response = self.process_exception_by_middleware(e, request)
  File "C:\Python3129\mecheck\lib\site-packages\django\core\handlers\base.py", line 124, in _get_response
    response = wrapped_callback(request, *callback_args, **callback_kwargs)
  File "C:\Python3129\mecheck\lib\site-packages\django\views\decorators\csrf.py", line 54, in wrapped_view
    return view_func(*args, **kwargs)
  File "C:\djangoproject\Reliability_Row_data\CommonDevice\views.py", line 317, in CommonDevice_edit
    return HttpResponse(json.dumps(data), content_type="application/json")
  File "C:\Python372\lib\json\__init__.py", line 231, in dumps
    return _default_encoder.encode(obj)
  File "C:\Python372\lib\json\encoder.py", line 199, in encode
    chunks = self.iterencode(o, _one_shot=True)
  File "C:\Python372\lib\json\encoder.py", line 257, in iterencode
    return _iterencode(o, 0)
  File "C:\Python372\lib\json\encoder.py", line 179, in default
    raise TypeError(f'Object of type {o.__class__.__name__} '
TypeError: Object of type Category is not JSON serializable
[2025-05-22 13:13:31,662] [runserver.py:154] [runserver:log_action] [ERROR]- HTTP POST /CommonDevice/CommonDevice_edit/ 500 [0.53, 127.0.0.1:58624]
[2025-05-22 13:15:59,644] [log.py:228] [log:log_response] [ERROR]- Internal Server Error: /CommonDevice/CommonDevice_edit/
Traceback (most recent call last):
  File "C:\Python3129\mecheck\lib\site-packages\django\core\handlers\exception.py", line 34, in inner
    response = get_response(request)
  File "C:\Python3129\mecheck\lib\site-packages\django\core\handlers\base.py", line 126, in _get_response
    response = self.process_exception_by_middleware(e, request)
  File "C:\Python3129\mecheck\lib\site-packages\django\core\handlers\base.py", line 124, in _get_response
    response = wrapped_callback(request, *callback_args, **callback_kwargs)
  File "C:\Python3129\mecheck\lib\site-packages\django\views\decorators\csrf.py", line 54, in wrapped_view
    return view_func(*args, **kwargs)
  File "C:\djangoproject\Reliability_Row_data\CommonDevice\views.py", line 311, in CommonDevice_edit
    return HttpResponse(json.dumps(data), content_type="application/json")
  File "C:\Python372\lib\json\__init__.py", line 231, in dumps
    return _default_encoder.encode(obj)
  File "C:\Python372\lib\json\encoder.py", line 199, in encode
    chunks = self.iterencode(o, _one_shot=True)
  File "C:\Python372\lib\json\encoder.py", line 257, in iterencode
    return _iterencode(o, 0)
  File "C:\Python372\lib\json\encoder.py", line 179, in default
    raise TypeError(f'Object of type {o.__class__.__name__} '
TypeError: Object of type Category is not JSON serializable
[2025-05-22 13:15:59,652] [runserver.py:154] [runserver:log_action] [ERROR]- HTTP POST /CommonDevice/CommonDevice_edit/ 500 [0.48, 127.0.0.1:62602]
[2025-05-22 13:18:09,268] [log.py:228] [log:log_response] [ERROR]- Internal Server Error: /CommonDevice/CommonDevice_edit/
Traceback (most recent call last):
  File "C:\Python3129\mecheck\lib\site-packages\django\core\handlers\exception.py", line 34, in inner
    response = get_response(request)
  File "C:\Python3129\mecheck\lib\site-packages\django\core\handlers\base.py", line 126, in _get_response
    response = self.process_exception_by_middleware(e, request)
  File "C:\Python3129\mecheck\lib\site-packages\django\core\handlers\base.py", line 124, in _get_response
    response = wrapped_callback(request, *callback_args, **callback_kwargs)
  File "C:\Python3129\mecheck\lib\site-packages\django\views\decorators\csrf.py", line 54, in wrapped_view
    return view_func(*args, **kwargs)
  File "C:\djangoproject\Reliability_Row_data\CommonDevice\views.py", line 311, in CommonDevice_edit
    return HttpResponse(json.dumps(data), content_type="application/json")
  File "C:\Python372\lib\json\__init__.py", line 231, in dumps
    return _default_encoder.encode(obj)
  File "C:\Python372\lib\json\encoder.py", line 199, in encode
    chunks = self.iterencode(o, _one_shot=True)
  File "C:\Python372\lib\json\encoder.py", line 257, in iterencode
    return _iterencode(o, 0)
  File "C:\Python372\lib\json\encoder.py", line 179, in default
    raise TypeError(f'Object of type {o.__class__.__name__} '
TypeError: Object of type Category is not JSON serializable
[2025-05-22 13:18:09,275] [runserver.py:154] [runserver:log_action] [ERROR]- HTTP POST /CommonDevice/CommonDevice_edit/ 500 [0.42, 127.0.0.1:49893]
[2025-05-22 13:19:16,392] [log.py:228] [log:log_response] [ERROR]- Internal Server Error: /CommonDevice/CommonDevice_edit/
Traceback (most recent call last):
  File "C:\Python3129\mecheck\lib\site-packages\django\core\handlers\exception.py", line 34, in inner
    response = get_response(request)
  File "C:\Python3129\mecheck\lib\site-packages\django\core\handlers\base.py", line 126, in _get_response
    response = self.process_exception_by_middleware(e, request)
  File "C:\Python3129\mecheck\lib\site-packages\django\core\handlers\base.py", line 124, in _get_response
    response = wrapped_callback(request, *callback_args, **callback_kwargs)
  File "C:\Python3129\mecheck\lib\site-packages\django\views\decorators\csrf.py", line 54, in wrapped_view
    return view_func(*args, **kwargs)
  File "C:\djangoproject\Reliability_Row_data\CommonDevice\views.py", line 311, in CommonDevice_edit
    return HttpResponse(json.dumps(data), content_type="application/json")
  File "C:\Python372\lib\json\__init__.py", line 231, in dumps
    return _default_encoder.encode(obj)
  File "C:\Python372\lib\json\encoder.py", line 199, in encode
    chunks = self.iterencode(o, _one_shot=True)
  File "C:\Python372\lib\json\encoder.py", line 257, in iterencode
    return _iterencode(o, 0)
  File "C:\Python372\lib\json\encoder.py", line 179, in default
    raise TypeError(f'Object of type {o.__class__.__name__} '
TypeError: Object of type Category is not JSON serializable
[2025-05-22 13:19:16,400] [runserver.py:154] [runserver:log_action] [ERROR]- HTTP POST /CommonDevice/CommonDevice_edit/ 500 [0.51, 127.0.0.1:51707]
[2025-05-22 15:35:10,103] [log.py:228] [log:log_response] [ERROR]- Internal Server Error: /CommonDevice/CommonDevice_edit/
Traceback (most recent call last):
  File "C:\Python3129\mecheck\lib\site-packages\django\db\backends\utils.py", line 85, in _execute
    return self.cursor.execute(sql, params)
  File "C:\Python3129\mecheck\lib\site-packages\django\db\backends\mysql\base.py", line 71, in execute
    return self.cursor.execute(query, args)
  File "C:\Python3129\mecheck\lib\site-packages\pymysql\cursors.py", line 170, in execute
    result = self._query(query)
  File "C:\Python3129\mecheck\lib\site-packages\pymysql\cursors.py", line 328, in _query
    conn.query(q)
  File "C:\Python3129\mecheck\lib\site-packages\pymysql\connections.py", line 517, in query
    self._affected_rows = self._read_query_result(unbuffered=unbuffered)
  File "C:\Python3129\mecheck\lib\site-packages\pymysql\connections.py", line 732, in _read_query_result
    result.read()
  File "C:\Python3129\mecheck\lib\site-packages\pymysql\connections.py", line 1075, in read
    first_packet = self.connection._read_packet()
  File "C:\Python3129\mecheck\lib\site-packages\pymysql\connections.py", line 684, in _read_packet
    packet.check_error()
  File "C:\Python3129\mecheck\lib\site-packages\pymysql\protocol.py", line 220, in check_error
    err.raise_mysql_exception(self._data)
  File "C:\Python3129\mecheck\lib\site-packages\pymysql\err.py", line 109, in raise_mysql_exception
    raise errorclass(errno, errval)
pymysql.err.IntegrityError: (1048, "Column 'Category_id' cannot be null")

The above exception was the direct cause of the following exception:

Traceback (most recent call last):
  File "C:\Python3129\mecheck\lib\site-packages\django\core\handlers\exception.py", line 34, in inner
    response = get_response(request)
  File "C:\Python3129\mecheck\lib\site-packages\django\core\handlers\base.py", line 126, in _get_response
    response = self.process_exception_by_middleware(e, request)
  File "C:\Python3129\mecheck\lib\site-packages\django\core\handlers\base.py", line 124, in _get_response
    response = wrapped_callback(request, *callback_args, **callback_kwargs)
  File "C:\Python3129\mecheck\lib\site-packages\django\views\decorators\csrf.py", line 54, in wrapped_view
    return view_func(*args, **kwargs)
  File "C:\djangoproject\Reliability_Row_data\CommonDevice\views.py", line 174, in CommonDevice_edit
    Comdevice = CommonDevice.objects.create(**create_dic)
  File "C:\Python3129\mecheck\lib\site-packages\django\db\models\manager.py", line 82, in manager_method
    return getattr(self.get_queryset(), name)(*args, **kwargs)
  File "C:\Python3129\mecheck\lib\site-packages\django\db\models\query.py", line 413, in create
    obj.save(force_insert=True, using=self.db)
  File "C:\Python3129\mecheck\lib\site-packages\django\db\models\base.py", line 718, in save
    force_update=force_update, update_fields=update_fields)
  File "C:\Python3129\mecheck\lib\site-packages\django\db\models\base.py", line 748, in save_base
    updated = self._save_table(raw, cls, force_insert, force_update, using, update_fields)
  File "C:\Python3129\mecheck\lib\site-packages\django\db\models\base.py", line 831, in _save_table
    result = self._do_insert(cls._base_manager, using, fields, update_pk, raw)
  File "C:\Python3129\mecheck\lib\site-packages\django\db\models\base.py", line 869, in _do_insert
    using=using, raw=raw)
  File "C:\Python3129\mecheck\lib\site-packages\django\db\models\manager.py", line 82, in manager_method
    return getattr(self.get_queryset(), name)(*args, **kwargs)
  File "C:\Python3129\mecheck\lib\site-packages\django\db\models\query.py", line 1136, in _insert
    return query.get_compiler(using=using).execute_sql(return_id)
  File "C:\Python3129\mecheck\lib\site-packages\django\db\models\sql\compiler.py", line 1289, in execute_sql
    cursor.execute(sql, params)
  File "C:\Python3129\mecheck\lib\site-packages\django\db\backends\utils.py", line 100, in execute
    return super().execute(sql, params)
  File "C:\Python3129\mecheck\lib\site-packages\django\db\backends\utils.py", line 68, in execute
    return self._execute_with_wrappers(sql, params, many=False, executor=self._execute)
  File "C:\Python3129\mecheck\lib\site-packages\django\db\backends\utils.py", line 77, in _execute_with_wrappers
    return executor(sql, params, many, context)
  File "C:\Python3129\mecheck\lib\site-packages\django\db\backends\utils.py", line 85, in _execute
    return self.cursor.execute(sql, params)
  File "C:\Python3129\mecheck\lib\site-packages\django\db\utils.py", line 89, in __exit__
    raise dj_exc_value.with_traceback(traceback) from exc_value
  File "C:\Python3129\mecheck\lib\site-packages\django\db\backends\utils.py", line 85, in _execute
    return self.cursor.execute(sql, params)
  File "C:\Python3129\mecheck\lib\site-packages\django\db\backends\mysql\base.py", line 71, in execute
    return self.cursor.execute(query, args)
  File "C:\Python3129\mecheck\lib\site-packages\pymysql\cursors.py", line 170, in execute
    result = self._query(query)
  File "C:\Python3129\mecheck\lib\site-packages\pymysql\cursors.py", line 328, in _query
    conn.query(q)
  File "C:\Python3129\mecheck\lib\site-packages\pymysql\connections.py", line 517, in query
    self._affected_rows = self._read_query_result(unbuffered=unbuffered)
  File "C:\Python3129\mecheck\lib\site-packages\pymysql\connections.py", line 732, in _read_query_result
    result.read()
  File "C:\Python3129\mecheck\lib\site-packages\pymysql\connections.py", line 1075, in read
    first_packet = self.connection._read_packet()
  File "C:\Python3129\mecheck\lib\site-packages\pymysql\connections.py", line 684, in _read_packet
    packet.check_error()
  File "C:\Python3129\mecheck\lib\site-packages\pymysql\protocol.py", line 220, in check_error
    err.raise_mysql_exception(self._data)
  File "C:\Python3129\mecheck\lib\site-packages\pymysql\err.py", line 109, in raise_mysql_exception
    raise errorclass(errno, errval)
django.db.utils.IntegrityError: (1048, "Column 'Category_id' cannot be null")
[2025-05-22 15:35:10,143] [runserver.py:154] [runserver:log_action] [ERROR]- HTTP POST /CommonDevice/CommonDevice_edit/ 500 [0.54, 127.0.0.1:55401]
