[2024-07-31 09:04:14,379] [log.py:228] [log:log_response] [ERROR]- Internal Server Error: /Navigations_quality/
Traceback (most recent call last):
  File "C:\Python372\mecheck\lib\site-packages\django\core\handlers\exception.py", line 34, in inner
    response = get_response(request)
  File "C:\Python372\mecheck\lib\site-packages\django\core\handlers\base.py", line 126, in _get_response
    response = self.process_exception_by_middleware(e, request)
  File "C:\Python372\mecheck\lib\site-packages\django\core\handlers\base.py", line 124, in _get_response
    response = wrapped_callback(request, *callback_args, **callback_kwargs)
  File "C:\djangoproject\Reliability_Row_data\app01\views.py", line 610, in Navigations_quality
    return render(request, 'Navigations/品質管控.html', locals())
  File "C:\Python372\mecheck\lib\site-packages\django\shortcuts.py", line 36, in render
    content = loader.render_to_string(template_name, context, request, using=using)
  File "C:\Python372\mecheck\lib\site-packages\django\template\loader.py", line 62, in render_to_string
    return template.render(context, request)
  File "C:\Python372\mecheck\lib\site-packages\django\template\backends\django.py", line 61, in render
    return self.template.render(context)
  File "C:\Python372\mecheck\lib\site-packages\django\template\base.py", line 171, in render
    return self._render(context)
  File "C:\Python372\mecheck\lib\site-packages\django\template\base.py", line 163, in _render
    return self.nodelist.render(context)
  File "C:\Python372\mecheck\lib\site-packages\django\template\base.py", line 937, in render
    bit = node.render_annotated(context)
  File "C:\Python372\mecheck\lib\site-packages\django\template\base.py", line 904, in render_annotated
    return self.render(context)
  File "C:\Python372\mecheck\lib\site-packages\django\template\loader_tags.py", line 150, in render
    return compiled_parent._render(context)
  File "C:\Python372\mecheck\lib\site-packages\django\template\base.py", line 163, in _render
    return self.nodelist.render(context)
  File "C:\Python372\mecheck\lib\site-packages\django\template\base.py", line 937, in render
    bit = node.render_annotated(context)
  File "C:\Python372\mecheck\lib\site-packages\django\template\base.py", line 904, in render_annotated
    return self.render(context)
  File "C:\Python372\mecheck\lib\site-packages\django\template\loader_tags.py", line 62, in render
    result = block.nodelist.render(context)
  File "C:\Python372\mecheck\lib\site-packages\django\template\base.py", line 937, in render
    bit = node.render_annotated(context)
  File "C:\Python372\mecheck\lib\site-packages\django\template\base.py", line 904, in render_annotated
    return self.render(context)
  File "C:\Python372\mecheck\lib\site-packages\django\template\defaulttags.py", line 442, in render
    url = reverse(view_name, args=args, kwargs=kwargs, current_app=current_app)
  File "C:\Python372\mecheck\lib\site-packages\django\urls\base.py", line 90, in reverse
    return iri_to_uri(resolver._reverse_with_prefix(view, prefix, *args, **kwargs))
  File "C:\Python372\mecheck\lib\site-packages\django\urls\resolvers.py", line 622, in _reverse_with_prefix
    raise NoReverseMatch(msg)
django.urls.exceptions.NoReverseMatch: Reverse for 'Navigations_system' with arguments '('',)' not found. 1 pattern(s) tried: ['Navigations_system/(?P<name>[^/]+)/$']
[2024-07-31 09:04:14,390] [runserver.py:154] [runserver:log_action] [ERROR]- HTTP GET /Navigations_quality/ 500 [0.44, 127.0.0.1:53809]
[2024-07-31 09:08:23,428] [log.py:228] [log:log_response] [ERROR]- Internal Server Error: /Navigations_system/test/
Traceback (most recent call last):
  File "C:\Python372\mecheck\lib\site-packages\django\core\handlers\exception.py", line 34, in inner
    response = get_response(request)
  File "C:\Python372\mecheck\lib\site-packages\django\core\handlers\base.py", line 126, in _get_response
    response = self.process_exception_by_middleware(e, request)
  File "C:\Python372\mecheck\lib\site-packages\django\core\handlers\base.py", line 124, in _get_response
    response = wrapped_callback(request, *callback_args, **callback_kwargs)
  File "C:\djangoproject\Reliability_Row_data\app01\views.py", line 632, in Navigations_system
    return render(request, 'Navigations/品質管控.html', locals())
  File "C:\Python372\mecheck\lib\site-packages\django\shortcuts.py", line 36, in render
    content = loader.render_to_string(template_name, context, request, using=using)
  File "C:\Python372\mecheck\lib\site-packages\django\template\loader.py", line 62, in render_to_string
    return template.render(context, request)
  File "C:\Python372\mecheck\lib\site-packages\django\template\backends\django.py", line 61, in render
    return self.template.render(context)
  File "C:\Python372\mecheck\lib\site-packages\django\template\base.py", line 171, in render
    return self._render(context)
  File "C:\Python372\mecheck\lib\site-packages\django\template\base.py", line 163, in _render
    return self.nodelist.render(context)
  File "C:\Python372\mecheck\lib\site-packages\django\template\base.py", line 937, in render
    bit = node.render_annotated(context)
  File "C:\Python372\mecheck\lib\site-packages\django\template\base.py", line 904, in render_annotated
    return self.render(context)
  File "C:\Python372\mecheck\lib\site-packages\django\template\loader_tags.py", line 150, in render
    return compiled_parent._render(context)
  File "C:\Python372\mecheck\lib\site-packages\django\template\base.py", line 163, in _render
    return self.nodelist.render(context)
  File "C:\Python372\mecheck\lib\site-packages\django\template\base.py", line 937, in render
    bit = node.render_annotated(context)
  File "C:\Python372\mecheck\lib\site-packages\django\template\base.py", line 904, in render_annotated
    return self.render(context)
  File "C:\Python372\mecheck\lib\site-packages\django\template\loader_tags.py", line 62, in render
    result = block.nodelist.render(context)
  File "C:\Python372\mecheck\lib\site-packages\django\template\base.py", line 937, in render
    bit = node.render_annotated(context)
  File "C:\Python372\mecheck\lib\site-packages\django\template\base.py", line 904, in render_annotated
    return self.render(context)
  File "C:\Python372\mecheck\lib\site-packages\django\template\defaulttags.py", line 442, in render
    url = reverse(view_name, args=args, kwargs=kwargs, current_app=current_app)
  File "C:\Python372\mecheck\lib\site-packages\django\urls\base.py", line 90, in reverse
    return iri_to_uri(resolver._reverse_with_prefix(view, prefix, *args, **kwargs))
  File "C:\Python372\mecheck\lib\site-packages\django\urls\resolvers.py", line 622, in _reverse_with_prefix
    raise NoReverseMatch(msg)
django.urls.exceptions.NoReverseMatch: Reverse for 'Navigations_system' with arguments '('',)' not found. 1 pattern(s) tried: ['Navigations_system/(?P<name>[^/]+)/$']
[2024-07-31 09:08:38,405] [log.py:228] [log:log_response] [ERROR]- Internal Server Error: /Navigations_quality/
Traceback (most recent call last):
  File "C:\Python372\mecheck\lib\site-packages\django\core\handlers\exception.py", line 34, in inner
    response = get_response(request)
  File "C:\Python372\mecheck\lib\site-packages\django\core\handlers\base.py", line 126, in _get_response
    response = self.process_exception_by_middleware(e, request)
  File "C:\Python372\mecheck\lib\site-packages\django\core\handlers\base.py", line 124, in _get_response
    response = wrapped_callback(request, *callback_args, **callback_kwargs)
  File "C:\djangoproject\Reliability_Row_data\app01\views.py", line 610, in Navigations_quality
    return render(request, 'Navigations/品質管控.html', locals())
  File "C:\Python372\mecheck\lib\site-packages\django\shortcuts.py", line 36, in render
    content = loader.render_to_string(template_name, context, request, using=using)
  File "C:\Python372\mecheck\lib\site-packages\django\template\loader.py", line 62, in render_to_string
    return template.render(context, request)
  File "C:\Python372\mecheck\lib\site-packages\django\template\backends\django.py", line 61, in render
    return self.template.render(context)
  File "C:\Python372\mecheck\lib\site-packages\django\template\base.py", line 171, in render
    return self._render(context)
  File "C:\Python372\mecheck\lib\site-packages\django\template\base.py", line 163, in _render
    return self.nodelist.render(context)
  File "C:\Python372\mecheck\lib\site-packages\django\template\base.py", line 937, in render
    bit = node.render_annotated(context)
  File "C:\Python372\mecheck\lib\site-packages\django\template\base.py", line 904, in render_annotated
    return self.render(context)
  File "C:\Python372\mecheck\lib\site-packages\django\template\loader_tags.py", line 150, in render
    return compiled_parent._render(context)
  File "C:\Python372\mecheck\lib\site-packages\django\template\base.py", line 163, in _render
    return self.nodelist.render(context)
  File "C:\Python372\mecheck\lib\site-packages\django\template\base.py", line 937, in render
    bit = node.render_annotated(context)
  File "C:\Python372\mecheck\lib\site-packages\django\template\base.py", line 904, in render_annotated
    return self.render(context)
  File "C:\Python372\mecheck\lib\site-packages\django\template\loader_tags.py", line 62, in render
    result = block.nodelist.render(context)
  File "C:\Python372\mecheck\lib\site-packages\django\template\base.py", line 937, in render
    bit = node.render_annotated(context)
  File "C:\Python372\mecheck\lib\site-packages\django\template\base.py", line 904, in render_annotated
    return self.render(context)
  File "C:\Python372\mecheck\lib\site-packages\django\template\defaulttags.py", line 442, in render
    url = reverse(view_name, args=args, kwargs=kwargs, current_app=current_app)
  File "C:\Python372\mecheck\lib\site-packages\django\urls\base.py", line 90, in reverse
    return iri_to_uri(resolver._reverse_with_prefix(view, prefix, *args, **kwargs))
  File "C:\Python372\mecheck\lib\site-packages\django\urls\resolvers.py", line 622, in _reverse_with_prefix
    raise NoReverseMatch(msg)
django.urls.exceptions.NoReverseMatch: Reverse for 'Navigations_system' with arguments '('',)' not found. 1 pattern(s) tried: ['Navigations_system/(?P<name>[^/]+)/$']
[2024-07-31 09:08:38,414] [runserver.py:154] [runserver:log_action] [ERROR]- HTTP GET /Navigations_quality/ 500 [0.17, 127.0.0.1:55277]
[2024-07-31 09:10:03,887] [log.py:228] [log:log_response] [ERROR]- Internal Server Error: /Navigations_quality/
Traceback (most recent call last):
  File "C:\Python372\mecheck\lib\site-packages\django\core\handlers\exception.py", line 34, in inner
    response = get_response(request)
  File "C:\Python372\mecheck\lib\site-packages\django\core\handlers\base.py", line 126, in _get_response
    response = self.process_exception_by_middleware(e, request)
  File "C:\Python372\mecheck\lib\site-packages\django\core\handlers\base.py", line 124, in _get_response
    response = wrapped_callback(request, *callback_args, **callback_kwargs)
  File "C:\djangoproject\Reliability_Row_data\app01\views.py", line 610, in Navigations_quality
    return render(request, 'Navigations/品質管控.html', locals())
  File "C:\Python372\mecheck\lib\site-packages\django\shortcuts.py", line 36, in render
    content = loader.render_to_string(template_name, context, request, using=using)
  File "C:\Python372\mecheck\lib\site-packages\django\template\loader.py", line 61, in render_to_string
    template = get_template(template_name, using=using)
  File "C:\Python372\mecheck\lib\site-packages\django\template\loader.py", line 15, in get_template
    return engine.get_template(template_name)
  File "C:\Python372\mecheck\lib\site-packages\django\template\backends\django.py", line 34, in get_template
    return Template(self.engine.get_template(template_name), self)
  File "C:\Python372\mecheck\lib\site-packages\django\template\engine.py", line 144, in get_template
    template, origin = self.find_template(template_name)
  File "C:\Python372\mecheck\lib\site-packages\django\template\engine.py", line 126, in find_template
    template = loader.get_template(name, skip=skip)
  File "C:\Python372\mecheck\lib\site-packages\django\template\loaders\base.py", line 30, in get_template
    contents, origin, origin.template_name, self.engine,
  File "C:\Python372\mecheck\lib\site-packages\django\template\base.py", line 156, in __init__
    self.nodelist = self.compile_nodelist()
  File "C:\Python372\mecheck\lib\site-packages\django\template\base.py", line 194, in compile_nodelist
    return parser.parse()
  File "C:\Python372\mecheck\lib\site-packages\django\template\base.py", line 478, in parse
    raise self.error(token, e)
  File "C:\Python372\mecheck\lib\site-packages\django\template\base.py", line 476, in parse
    compiled_result = compile_func(self, token)
  File "C:\Python372\mecheck\lib\site-packages\django\template\loader_tags.py", line 266, in do_extends
    nodelist = parser.parse()
  File "C:\Python372\mecheck\lib\site-packages\django\template\base.py", line 478, in parse
    raise self.error(token, e)
  File "C:\Python372\mecheck\lib\site-packages\django\template\base.py", line 476, in parse
    compiled_result = compile_func(self, token)
  File "C:\Python372\mecheck\lib\site-packages\django\template\loader_tags.py", line 209, in do_block
    nodelist = parser.parse(('endblock',))
  File "C:\Python372\mecheck\lib\site-packages\django\template\base.py", line 478, in parse
    raise self.error(token, e)
  File "C:\Python372\mecheck\lib\site-packages\django\template\base.py", line 476, in parse
    compiled_result = compile_func(self, token)
  File "C:\Python372\mecheck\lib\site-packages\django\template\defaulttags.py", line 1375, in url
    args.append(parser.compile_filter(value))
  File "C:\Python372\mecheck\lib\site-packages\django\template\base.py", line 563, in compile_filter
    return FilterExpression(token, self)
  File "C:\Python372\mecheck\lib\site-packages\django\template\base.py", line 663, in __init__
    "from '%s'" % (token[upto:], token))
django.template.exceptions.TemplateSyntaxError: Could not parse the remainder: '${' from '${'
[2024-07-31 09:10:03,893] [runserver.py:154] [runserver:log_action] [ERROR]- HTTP GET /Navigations_quality/ 500 [0.09, 127.0.0.1:55395]
[2024-07-31 13:20:59,360] [log.py:228] [log:log_response] [ERROR]- Internal Server Error: /Navigations_system/
Traceback (most recent call last):
  File "C:\Python372\mecheck\lib\site-packages\django\core\handlers\exception.py", line 34, in inner
    response = get_response(request)
  File "C:\Python372\mecheck\lib\site-packages\django\core\handlers\base.py", line 126, in _get_response
    response = self.process_exception_by_middleware(e, request)
  File "C:\Python372\mecheck\lib\site-packages\django\core\handlers\base.py", line 124, in _get_response
    response = wrapped_callback(request, *callback_args, **callback_kwargs)
  File "C:\Python372\mecheck\lib\site-packages\django\views\decorators\csrf.py", line 54, in wrapped_view
    return view_func(*args, **kwargs)
TypeError: Navigations_system_axios() missing 1 required positional argument: 'name'
[2024-07-31 13:20:59,371] [runserver.py:154] [runserver:log_action] [ERROR]- HTTP POST /Navigations_system/ 500 [0.95, 127.0.0.1:62250]
[2024-07-31 13:21:02,924] [log.py:228] [log:log_response] [ERROR]- Internal Server Error: /Navigations_system/
Traceback (most recent call last):
  File "C:\Python372\mecheck\lib\site-packages\django\core\handlers\exception.py", line 34, in inner
    response = get_response(request)
  File "C:\Python372\mecheck\lib\site-packages\django\core\handlers\base.py", line 126, in _get_response
    response = self.process_exception_by_middleware(e, request)
  File "C:\Python372\mecheck\lib\site-packages\django\core\handlers\base.py", line 124, in _get_response
    response = wrapped_callback(request, *callback_args, **callback_kwargs)
  File "C:\Python372\mecheck\lib\site-packages\django\views\decorators\csrf.py", line 54, in wrapped_view
    return view_func(*args, **kwargs)
TypeError: Navigations_system_axios() missing 1 required positional argument: 'name'
[2024-07-31 13:21:02,932] [runserver.py:154] [runserver:log_action] [ERROR]- HTTP POST /Navigations_system/ 500 [0.07, 127.0.0.1:62289]
[2024-07-31 13:21:47,145] [log.py:228] [log:log_response] [ERROR]- Internal Server Error: /Navigations_system/
Traceback (most recent call last):
  File "C:\Python372\mecheck\lib\site-packages\django\core\handlers\exception.py", line 34, in inner
    response = get_response(request)
  File "C:\Python372\mecheck\lib\site-packages\django\core\handlers\base.py", line 126, in _get_response
    response = self.process_exception_by_middleware(e, request)
  File "C:\Python372\mecheck\lib\site-packages\django\core\handlers\base.py", line 124, in _get_response
    response = wrapped_callback(request, *callback_args, **callback_kwargs)
  File "C:\Python372\mecheck\lib\site-packages\django\views\decorators\csrf.py", line 54, in wrapped_view
    return view_func(*args, **kwargs)
  File "C:\djangoproject\Reliability_Row_data\app01\views.py", line 678, in Navigations_system_axios
    print(request.method, name)
NameError: name 'name' is not defined
[2024-07-31 13:21:47,151] [runserver.py:154] [runserver:log_action] [ERROR]- HTTP POST /Navigations_system/ 500 [0.37, 127.0.0.1:62394]
[2024-07-31 15:35:24,166] [runserver.py:154] [runserver:log_action] [ERROR]- HTTP GET /ABOTestPlan/ABOTestPlan_summary/ 500 [0.21, 127.0.0.1:56001]
[2024-07-31 15:35:25,170] [runserver.py:154] [runserver:log_action] [ERROR]- HTTP GET /favicon.ico 500 [0.95, 127.0.0.1:56001]
[2024-07-31 15:35:31,218] [runserver.py:154] [runserver:log_action] [ERROR]- HTTP GET /TestPlanSW/TestPlanSW-summary/ 500 [0.58, 127.0.0.1:56001]
[2024-07-31 15:35:32,230] [runserver.py:154] [runserver:log_action] [ERROR]- HTTP GET /favicon.ico 500 [1.00, 127.0.0.1:56001]
[2024-07-31 15:35:38,277] [runserver.py:154] [runserver:log_action] [ERROR]- HTTP GET /favicon.ico 500 [0.63, 127.0.0.1:56001]
[2024-07-31 15:35:49,366] [runserver.py:154] [runserver:log_action] [ERROR]- HTTP GET /ABOTestPlan/ABOTestPlan_summary/ 500 [0.57, 127.0.0.1:56001]
[2024-07-31 15:35:50,381] [runserver.py:154] [runserver:log_action] [ERROR]- HTTP GET /favicon.ico 500 [0.99, 127.0.0.1:56001]
[2024-07-31 15:39:25,918] [runserver.py:154] [runserver:log_action] [ERROR]- HTTP GET /INVGantt/INVGantt-summary/ 500 [0.63, 127.0.0.1:56284]
[2024-07-31 15:39:26,932] [runserver.py:154] [runserver:log_action] [ERROR]- HTTP GET /favicon.ico 500 [0.96, 127.0.0.1:56284]
[2024-07-31 15:40:06,243] [runserver.py:154] [runserver:log_action] [ERROR]- HTTP GET /TestPlanSWOS/TestPlanSWOS-summary/ 500 [0.44, 127.0.0.1:56284]
[2024-07-31 15:40:07,245] [runserver.py:154] [runserver:log_action] [ERROR]- HTTP GET /favicon.ico 500 [0.85, 127.0.0.1:56321]
[2024-07-31 15:40:15,305] [runserver.py:154] [runserver:log_action] [ERROR]- HTTP GET /MQM/MQM_search/ 500 [0.48, 127.0.0.1:56321]
[2024-07-31 15:40:16,312] [runserver.py:154] [runserver:log_action] [ERROR]- HTTP GET /favicon.ico 500 [0.98, 127.0.0.1:56321]
