[2025-03-04 11:17:17,937] [log.py:228] [log:log_response] [ERROR]- Internal Server Error: /MiscellaneousPurchases/Budget/
Traceback (most recent call last):
  File "C:\Python372\mecheck\lib\site-packages\django\core\handlers\exception.py", line 34, in inner
    response = get_response(request)
  File "C:\Python372\mecheck\lib\site-packages\django\core\handlers\base.py", line 126, in _get_response
    response = self.process_exception_by_middleware(e, request)
  File "C:\Python372\mecheck\lib\site-packages\django\core\handlers\base.py", line 124, in _get_response
    response = wrapped_callback(request, *callback_args, **callback_kwargs)
  File "C:\Python372\mecheck\lib\site-packages\django\views\decorators\csrf.py", line 54, in wrapped_view
    return view_func(*args, **kwargs)
  File "C:\djangoproject\Reliability_Row_data\MiscellaneousPurchases\views.py", line 90, in Budget
    for i in Budget.objects.all().values("Year"):
AttributeError: 'function' object has no attribute 'objects'
[2025-03-04 11:17:17,989] [runserver.py:154] [runserver:log_action] [ERROR]- HTTP GET /MiscellaneousPurchases/Budget/ 500 [7.16, 127.0.0.1:61248]
[2025-03-04 11:20:02,931] [log.py:228] [log:log_response] [ERROR]- Internal Server Error: /MiscellaneousPurchases/Budget/
Traceback (most recent call last):
  File "C:\Python372\mecheck\lib\site-packages\django\core\handlers\exception.py", line 34, in inner
    response = get_response(request)
  File "C:\Python372\mecheck\lib\site-packages\django\core\handlers\base.py", line 126, in _get_response
    response = self.process_exception_by_middleware(e, request)
  File "C:\Python372\mecheck\lib\site-packages\django\core\handlers\base.py", line 124, in _get_response
    response = wrapped_callback(request, *callback_args, **callback_kwargs)
  File "C:\Python372\mecheck\lib\site-packages\django\views\decorators\csrf.py", line 54, in wrapped_view
    return view_func(*args, **kwargs)
  File "C:\djangoproject\Reliability_Row_data\MiscellaneousPurchases\views.py", line 92, in Budget
    for i in Budget.objects.all().values("Year").distinct().order_by("Year"):
AttributeError: 'function' object has no attribute 'objects'
[2025-03-04 11:20:02,948] [runserver.py:154] [runserver:log_action] [ERROR]- HTTP GET /MiscellaneousPurchases/Budget/ 500 [0.58, 127.0.0.1:61631]
[2025-03-04 11:21:47,855] [log.py:228] [log:log_response] [ERROR]- Internal Server Error: /MiscellaneousPurchases/Budget/
Traceback (most recent call last):
  File "C:\Python372\mecheck\lib\site-packages\django\core\handlers\exception.py", line 34, in inner
    response = get_response(request)
  File "C:\Python372\mecheck\lib\site-packages\django\core\handlers\base.py", line 126, in _get_response
    response = self.process_exception_by_middleware(e, request)
  File "C:\Python372\mecheck\lib\site-packages\django\core\handlers\base.py", line 124, in _get_response
    response = wrapped_callback(request, *callback_args, **callback_kwargs)
  File "C:\Python372\mecheck\lib\site-packages\django\views\decorators\csrf.py", line 54, in wrapped_view
    return view_func(*args, **kwargs)
  File "C:\djangoproject\Reliability_Row_data\MiscellaneousPurchases\views.py", line 92, in Budget
    for i in Budget.objects.all().values("Year").distinct().order_by("Year"):
AttributeError: 'function' object has no attribute 'objects'
[2025-03-04 11:21:47,866] [runserver.py:154] [runserver:log_action] [ERROR]- HTTP GET /MiscellaneousPurchases/Budget/ 500 [0.40, 127.0.0.1:61957]
[2025-03-04 11:22:43,490] [log.py:228] [log:log_response] [ERROR]- Internal Server Error: /MiscellaneousPurchases/Budget/
Traceback (most recent call last):
  File "C:\Python372\mecheck\lib\site-packages\django\core\handlers\exception.py", line 34, in inner
    response = get_response(request)
  File "C:\Python372\mecheck\lib\site-packages\django\core\handlers\base.py", line 126, in _get_response
    response = self.process_exception_by_middleware(e, request)
  File "C:\Python372\mecheck\lib\site-packages\django\core\handlers\base.py", line 124, in _get_response
    response = wrapped_callback(request, *callback_args, **callback_kwargs)
  File "C:\Python372\mecheck\lib\site-packages\django\views\decorators\csrf.py", line 54, in wrapped_view
    return view_func(*args, **kwargs)
  File "C:\djangoproject\Reliability_Row_data\MiscellaneousPurchases\views.py", line 92, in Budget
    for i in Budget.objects.all().values("Year").distinct().order_by("Year"):
AttributeError: 'function' object has no attribute 'objects'
[2025-03-04 11:22:43,511] [runserver.py:154] [runserver:log_action] [ERROR]- HTTP GET /MiscellaneousPurchases/Budget/ 500 [0.42, 127.0.0.1:62133]
[2025-03-04 11:25:57,767] [log.py:228] [log:log_response] [ERROR]- Internal Server Error: /MiscellaneousPurchases/Budget/
Traceback (most recent call last):
  File "C:\Python372\mecheck\lib\site-packages\django\db\backends\utils.py", line 85, in _execute
    return self.cursor.execute(sql, params)
  File "C:\Python372\mecheck\lib\site-packages\django\db\backends\mysql\base.py", line 71, in execute
    return self.cursor.execute(query, args)
  File "C:\Python372\mecheck\lib\site-packages\pymysql\cursors.py", line 170, in execute
    result = self._query(query)
  File "C:\Python372\mecheck\lib\site-packages\pymysql\cursors.py", line 328, in _query
    conn.query(q)
  File "C:\Python372\mecheck\lib\site-packages\pymysql\connections.py", line 517, in query
    self._affected_rows = self._read_query_result(unbuffered=unbuffered)
  File "C:\Python372\mecheck\lib\site-packages\pymysql\connections.py", line 732, in _read_query_result
    result.read()
  File "C:\Python372\mecheck\lib\site-packages\pymysql\connections.py", line 1075, in read
    first_packet = self.connection._read_packet()
  File "C:\Python372\mecheck\lib\site-packages\pymysql\connections.py", line 684, in _read_packet
    packet.check_error()
  File "C:\Python372\mecheck\lib\site-packages\pymysql\protocol.py", line 220, in check_error
    err.raise_mysql_exception(self._data)
  File "C:\Python372\mecheck\lib\site-packages\pymysql\err.py", line 109, in raise_mysql_exception
    raise errorclass(errno, errval)
pymysql.err.ProgrammingError: (1146, "Table 'reliabilityrowdata.miscellaneouspurchases_budget' doesn't exist")

The above exception was the direct cause of the following exception:

Traceback (most recent call last):
  File "C:\Python372\mecheck\lib\site-packages\django\core\handlers\exception.py", line 34, in inner
    response = get_response(request)
  File "C:\Python372\mecheck\lib\site-packages\django\core\handlers\base.py", line 126, in _get_response
    response = self.process_exception_by_middleware(e, request)
  File "C:\Python372\mecheck\lib\site-packages\django\core\handlers\base.py", line 124, in _get_response
    response = wrapped_callback(request, *callback_args, **callback_kwargs)
  File "C:\Python372\mecheck\lib\site-packages\django\views\decorators\csrf.py", line 54, in wrapped_view
    return view_func(*args, **kwargs)
  File "C:\djangoproject\Reliability_Row_data\MiscellaneousPurchases\views.py", line 92, in Budget_view
    for i in Budget.objects.all().values("Year").distinct().order_by("Year"):
  File "C:\Python372\mecheck\lib\site-packages\django\db\models\query.py", line 268, in __iter__
    self._fetch_all()
  File "C:\Python372\mecheck\lib\site-packages\django\db\models\query.py", line 1186, in _fetch_all
    self._result_cache = list(self._iterable_class(self))
  File "C:\Python372\mecheck\lib\site-packages\django\db\models\query.py", line 106, in __iter__
    for row in compiler.results_iter(chunked_fetch=self.chunked_fetch, chunk_size=self.chunk_size):
  File "C:\Python372\mecheck\lib\site-packages\django\db\models\sql\compiler.py", line 1017, in results_iter
    results = self.execute_sql(MULTI, chunked_fetch=chunked_fetch, chunk_size=chunk_size)
  File "C:\Python372\mecheck\lib\site-packages\django\db\models\sql\compiler.py", line 1065, in execute_sql
    cursor.execute(sql, params)
  File "C:\Python372\mecheck\lib\site-packages\django\db\backends\utils.py", line 100, in execute
    return super().execute(sql, params)
  File "C:\Python372\mecheck\lib\site-packages\django\db\backends\utils.py", line 68, in execute
    return self._execute_with_wrappers(sql, params, many=False, executor=self._execute)
  File "C:\Python372\mecheck\lib\site-packages\django\db\backends\utils.py", line 77, in _execute_with_wrappers
    return executor(sql, params, many, context)
  File "C:\Python372\mecheck\lib\site-packages\django\db\backends\utils.py", line 85, in _execute
    return self.cursor.execute(sql, params)
  File "C:\Python372\mecheck\lib\site-packages\django\db\utils.py", line 89, in __exit__
    raise dj_exc_value.with_traceback(traceback) from exc_value
  File "C:\Python372\mecheck\lib\site-packages\django\db\backends\utils.py", line 85, in _execute
    return self.cursor.execute(sql, params)
  File "C:\Python372\mecheck\lib\site-packages\django\db\backends\mysql\base.py", line 71, in execute
    return self.cursor.execute(query, args)
  File "C:\Python372\mecheck\lib\site-packages\pymysql\cursors.py", line 170, in execute
    result = self._query(query)
  File "C:\Python372\mecheck\lib\site-packages\pymysql\cursors.py", line 328, in _query
    conn.query(q)
  File "C:\Python372\mecheck\lib\site-packages\pymysql\connections.py", line 517, in query
    self._affected_rows = self._read_query_result(unbuffered=unbuffered)
  File "C:\Python372\mecheck\lib\site-packages\pymysql\connections.py", line 732, in _read_query_result
    result.read()
  File "C:\Python372\mecheck\lib\site-packages\pymysql\connections.py", line 1075, in read
    first_packet = self.connection._read_packet()
  File "C:\Python372\mecheck\lib\site-packages\pymysql\connections.py", line 684, in _read_packet
    packet.check_error()
  File "C:\Python372\mecheck\lib\site-packages\pymysql\protocol.py", line 220, in check_error
    err.raise_mysql_exception(self._data)
  File "C:\Python372\mecheck\lib\site-packages\pymysql\err.py", line 109, in raise_mysql_exception
    raise errorclass(errno, errval)
django.db.utils.ProgrammingError: (1146, "Table 'reliabilityrowdata.miscellaneouspurchases_budget' doesn't exist")
[2025-03-04 11:25:57,796] [runserver.py:154] [runserver:log_action] [ERROR]- HTTP GET /MiscellaneousPurchases/Budget/ 500 [0.61, 127.0.0.1:62585]
[2025-03-04 11:28:39,031] [log.py:228] [log:log_response] [ERROR]- Internal Server Error: /MiscellaneousPurchases/Budget/
Traceback (most recent call last):
  File "C:\Python372\mecheck\lib\site-packages\django\db\backends\utils.py", line 85, in _execute
    return self.cursor.execute(sql, params)
  File "C:\Python372\mecheck\lib\site-packages\django\db\backends\mysql\base.py", line 71, in execute
    return self.cursor.execute(query, args)
  File "C:\Python372\mecheck\lib\site-packages\pymysql\cursors.py", line 170, in execute
    result = self._query(query)
  File "C:\Python372\mecheck\lib\site-packages\pymysql\cursors.py", line 328, in _query
    conn.query(q)
  File "C:\Python372\mecheck\lib\site-packages\pymysql\connections.py", line 517, in query
    self._affected_rows = self._read_query_result(unbuffered=unbuffered)
  File "C:\Python372\mecheck\lib\site-packages\pymysql\connections.py", line 732, in _read_query_result
    result.read()
  File "C:\Python372\mecheck\lib\site-packages\pymysql\connections.py", line 1075, in read
    first_packet = self.connection._read_packet()
  File "C:\Python372\mecheck\lib\site-packages\pymysql\connections.py", line 684, in _read_packet
    packet.check_error()
  File "C:\Python372\mecheck\lib\site-packages\pymysql\protocol.py", line 220, in check_error
    err.raise_mysql_exception(self._data)
  File "C:\Python372\mecheck\lib\site-packages\pymysql\err.py", line 109, in raise_mysql_exception
    raise errorclass(errno, errval)
pymysql.err.ProgrammingError: (1146, "Table 'reliabilityrowdata.miscellaneouspurchases_budget' doesn't exist")

The above exception was the direct cause of the following exception:

Traceback (most recent call last):
  File "C:\Python372\mecheck\lib\site-packages\django\core\handlers\exception.py", line 34, in inner
    response = get_response(request)
  File "C:\Python372\mecheck\lib\site-packages\django\core\handlers\base.py", line 126, in _get_response
    response = self.process_exception_by_middleware(e, request)
  File "C:\Python372\mecheck\lib\site-packages\django\core\handlers\base.py", line 124, in _get_response
    response = wrapped_callback(request, *callback_args, **callback_kwargs)
  File "C:\Python372\mecheck\lib\site-packages\django\views\decorators\csrf.py", line 54, in wrapped_view
    return view_func(*args, **kwargs)
  File "C:\djangoproject\Reliability_Row_data\MiscellaneousPurchases\views.py", line 92, in Budget_view
    for i in Budget.objects.all().values("Year").distinct().order_by("Year"):
  File "C:\Python372\mecheck\lib\site-packages\django\db\models\query.py", line 268, in __iter__
    self._fetch_all()
  File "C:\Python372\mecheck\lib\site-packages\django\db\models\query.py", line 1186, in _fetch_all
    self._result_cache = list(self._iterable_class(self))
  File "C:\Python372\mecheck\lib\site-packages\django\db\models\query.py", line 106, in __iter__
    for row in compiler.results_iter(chunked_fetch=self.chunked_fetch, chunk_size=self.chunk_size):
  File "C:\Python372\mecheck\lib\site-packages\django\db\models\sql\compiler.py", line 1017, in results_iter
    results = self.execute_sql(MULTI, chunked_fetch=chunked_fetch, chunk_size=chunk_size)
  File "C:\Python372\mecheck\lib\site-packages\django\db\models\sql\compiler.py", line 1065, in execute_sql
    cursor.execute(sql, params)
  File "C:\Python372\mecheck\lib\site-packages\django\db\backends\utils.py", line 100, in execute
    return super().execute(sql, params)
  File "C:\Python372\mecheck\lib\site-packages\django\db\backends\utils.py", line 68, in execute
    return self._execute_with_wrappers(sql, params, many=False, executor=self._execute)
  File "C:\Python372\mecheck\lib\site-packages\django\db\backends\utils.py", line 77, in _execute_with_wrappers
    return executor(sql, params, many, context)
  File "C:\Python372\mecheck\lib\site-packages\django\db\backends\utils.py", line 85, in _execute
    return self.cursor.execute(sql, params)
  File "C:\Python372\mecheck\lib\site-packages\django\db\utils.py", line 89, in __exit__
    raise dj_exc_value.with_traceback(traceback) from exc_value
  File "C:\Python372\mecheck\lib\site-packages\django\db\backends\utils.py", line 85, in _execute
    return self.cursor.execute(sql, params)
  File "C:\Python372\mecheck\lib\site-packages\django\db\backends\mysql\base.py", line 71, in execute
    return self.cursor.execute(query, args)
  File "C:\Python372\mecheck\lib\site-packages\pymysql\cursors.py", line 170, in execute
    result = self._query(query)
  File "C:\Python372\mecheck\lib\site-packages\pymysql\cursors.py", line 328, in _query
    conn.query(q)
  File "C:\Python372\mecheck\lib\site-packages\pymysql\connections.py", line 517, in query
    self._affected_rows = self._read_query_result(unbuffered=unbuffered)
  File "C:\Python372\mecheck\lib\site-packages\pymysql\connections.py", line 732, in _read_query_result
    result.read()
  File "C:\Python372\mecheck\lib\site-packages\pymysql\connections.py", line 1075, in read
    first_packet = self.connection._read_packet()
  File "C:\Python372\mecheck\lib\site-packages\pymysql\connections.py", line 684, in _read_packet
    packet.check_error()
  File "C:\Python372\mecheck\lib\site-packages\pymysql\protocol.py", line 220, in check_error
    err.raise_mysql_exception(self._data)
  File "C:\Python372\mecheck\lib\site-packages\pymysql\err.py", line 109, in raise_mysql_exception
    raise errorclass(errno, errval)
django.db.utils.ProgrammingError: (1146, "Table 'reliabilityrowdata.miscellaneouspurchases_budget' doesn't exist")
[2025-03-04 11:28:39,058] [runserver.py:154] [runserver:log_action] [ERROR]- HTTP GET /MiscellaneousPurchases/Budget/ 500 [0.46, 127.0.0.1:62941]
[2025-03-04 12:59:39,471] [log.py:228] [log:log_response] [ERROR]- Internal Server Error: /MiscellaneousPurchases/Budget/
Traceback (most recent call last):
  File "C:\Python372\mecheck\lib\site-packages\django\core\handlers\exception.py", line 34, in inner
    response = get_response(request)
  File "C:\Python372\mecheck\lib\site-packages\django\core\handlers\base.py", line 126, in _get_response
    response = self.process_exception_by_middleware(e, request)
  File "C:\Python372\mecheck\lib\site-packages\django\core\handlers\base.py", line 124, in _get_response
    response = wrapped_callback(request, *callback_args, **callback_kwargs)
  File "C:\Python372\mecheck\lib\site-packages\django\views\decorators\csrf.py", line 54, in wrapped_view
    return view_func(*args, **kwargs)
  File "C:\djangoproject\Reliability_Row_data\MiscellaneousPurchases\views.py", line 93, in Budget_view
    yearOptions.append(i.Year)
AttributeError: 'dict' object has no attribute 'Year'
[2025-03-04 12:59:39,482] [runserver.py:154] [runserver:log_action] [ERROR]- HTTP GET /MiscellaneousPurchases/Budget/ 500 [1.08, 127.0.0.1:61504]
[2025-03-04 13:21:06,815] [log.py:228] [log:log_response] [ERROR]- Internal Server Error: /MiscellaneousPurchases/Budget/
Traceback (most recent call last):
  File "C:\Python372\mecheck\lib\site-packages\django\core\handlers\exception.py", line 34, in inner
    response = get_response(request)
  File "C:\Python372\mecheck\lib\site-packages\django\core\handlers\base.py", line 126, in _get_response
    response = self.process_exception_by_middleware(e, request)
  File "C:\Python372\mecheck\lib\site-packages\django\core\handlers\base.py", line 124, in _get_response
    response = wrapped_callback(request, *callback_args, **callback_kwargs)
  File "C:\Python372\mecheck\lib\site-packages\django\views\decorators\csrf.py", line 54, in wrapped_view
    return view_func(*args, **kwargs)
  File "C:\djangoproject\Reliability_Row_data\MiscellaneousPurchases\views.py", line 149, in Budget_view
    if Budget.objects.filter(**check_dic):
UnboundLocalError: local variable 'check_dic' referenced before assignment
[2025-03-04 13:21:06,826] [runserver.py:154] [runserver:log_action] [ERROR]- HTTP POST /MiscellaneousPurchases/Budget/ 500 [0.31, 127.0.0.1:63650]
[2025-03-04 14:44:02,758] [log.py:228] [log:log_response] [ERROR]- Internal Server Error: /favicon.ico
Traceback (most recent call last):
  File "C:\Python372\mecheck\lib\site-packages\django\core\handlers\exception.py", line 34, in inner
    response = get_response(request)
  File "C:\djangoproject\Reliability_Row_data\middleware\checkper.py", line 14, in __call__
    response = self.process_request(request)
  File "C:\djangoproject\Reliability_Row_data\middleware\checkper.py", line 80, in process_request
    info = '<br/>' + ('<br/>'.join(permission_url))
TypeError: sequence item 133: expected str instance, NoneType found
[2025-03-04 14:44:02,770] [runserver.py:154] [runserver:log_action] [ERROR]- HTTP GET /favicon.ico 500 [0.14, 127.0.0.1:54872]
[2025-03-04 14:45:49,907] [log.py:228] [log:log_response] [ERROR]- Internal Server Error: /favicon.ico
Traceback (most recent call last):
  File "C:\Python372\mecheck\lib\site-packages\django\core\handlers\exception.py", line 34, in inner
    response = get_response(request)
  File "C:\djangoproject\Reliability_Row_data\middleware\checkper.py", line 14, in __call__
    response = self.process_request(request)
  File "C:\djangoproject\Reliability_Row_data\middleware\checkper.py", line 80, in process_request
    info = '<br/>' + ('<br/>'.join(permission_url))
TypeError: sequence item 133: expected str instance, NoneType found
[2025-03-04 14:45:49,912] [runserver.py:154] [runserver:log_action] [ERROR]- HTTP GET /favicon.ico 500 [0.11, 127.0.0.1:55126]
[2025-03-04 14:46:37,511] [log.py:228] [log:log_response] [ERROR]- Internal Server Error: /favicon.ico
Traceback (most recent call last):
  File "C:\Python372\mecheck\lib\site-packages\django\core\handlers\exception.py", line 34, in inner
    response = get_response(request)
  File "C:\djangoproject\Reliability_Row_data\middleware\checkper.py", line 14, in __call__
    response = self.process_request(request)
  File "C:\djangoproject\Reliability_Row_data\middleware\checkper.py", line 80, in process_request
    info = '<br/>' + ('<br/>'.join(permission_url))
TypeError: sequence item 133: expected str instance, NoneType found
[2025-03-04 14:46:37,516] [runserver.py:154] [runserver:log_action] [ERROR]- HTTP GET /favicon.ico 500 [0.12, 127.0.0.1:55125]
[2025-03-04 16:04:11,311] [log.py:228] [log:log_response] [ERROR]- Internal Server Error: /favicon.ico
Traceback (most recent call last):
  File "C:\Python372\mecheck\lib\site-packages\django\core\handlers\exception.py", line 34, in inner
    response = get_response(request)
  File "C:\djangoproject\Reliability_Row_data\middleware\checkper.py", line 14, in __call__
    response = self.process_request(request)
  File "C:\djangoproject\Reliability_Row_data\middleware\checkper.py", line 80, in process_request
    info = '<br/>' + ('<br/>'.join(permission_url))
TypeError: sequence item 133: expected str instance, NoneType found
[2025-03-04 16:04:11,316] [runserver.py:154] [runserver:log_action] [ERROR]- HTTP GET /favicon.ico 500 [0.09, 127.0.0.1:61512]
[2025-03-04 16:04:14,138] [log.py:228] [log:log_response] [ERROR]- Internal Server Error: /favicon.ico
Traceback (most recent call last):
  File "C:\Python372\mecheck\lib\site-packages\django\core\handlers\exception.py", line 34, in inner
    response = get_response(request)
  File "C:\djangoproject\Reliability_Row_data\middleware\checkper.py", line 14, in __call__
    response = self.process_request(request)
  File "C:\djangoproject\Reliability_Row_data\middleware\checkper.py", line 80, in process_request
    info = '<br/>' + ('<br/>'.join(permission_url))
TypeError: sequence item 133: expected str instance, NoneType found
[2025-03-04 16:04:14,141] [runserver.py:154] [runserver:log_action] [ERROR]- HTTP GET /favicon.ico 500 [0.08, 127.0.0.1:61513]
[2025-03-04 16:04:16,188] [log.py:228] [log:log_response] [ERROR]- Internal Server Error: /favicon.ico
Traceback (most recent call last):
  File "C:\Python372\mecheck\lib\site-packages\django\core\handlers\exception.py", line 34, in inner
    response = get_response(request)
  File "C:\djangoproject\Reliability_Row_data\middleware\checkper.py", line 14, in __call__
    response = self.process_request(request)
  File "C:\djangoproject\Reliability_Row_data\middleware\checkper.py", line 80, in process_request
    info = '<br/>' + ('<br/>'.join(permission_url))
TypeError: sequence item 133: expected str instance, NoneType found
[2025-03-04 16:04:16,194] [runserver.py:154] [runserver:log_action] [ERROR]- HTTP GET /favicon.ico 500 [0.07, 127.0.0.1:61512]
[2025-03-04 16:04:23,102] [log.py:228] [log:log_response] [ERROR]- Internal Server Error: /favicon.ico
Traceback (most recent call last):
  File "C:\Python372\mecheck\lib\site-packages\django\core\handlers\exception.py", line 34, in inner
    response = get_response(request)
  File "C:\djangoproject\Reliability_Row_data\middleware\checkper.py", line 14, in __call__
    response = self.process_request(request)
  File "C:\djangoproject\Reliability_Row_data\middleware\checkper.py", line 80, in process_request
    info = '<br/>' + ('<br/>'.join(permission_url))
TypeError: sequence item 133: expected str instance, NoneType found
[2025-03-04 16:04:23,106] [runserver.py:154] [runserver:log_action] [ERROR]- HTTP GET /favicon.ico 500 [0.13, 127.0.0.1:61512]
[2025-03-04 16:06:08,918] [log.py:228] [log:log_response] [ERROR]- Internal Server Error: /favicon.ico
Traceback (most recent call last):
  File "C:\Python372\mecheck\lib\site-packages\django\core\handlers\exception.py", line 34, in inner
    response = get_response(request)
  File "C:\djangoproject\Reliability_Row_data\middleware\checkper.py", line 14, in __call__
    response = self.process_request(request)
  File "C:\djangoproject\Reliability_Row_data\middleware\checkper.py", line 80, in process_request
    info = '<br/>' + ('<br/>'.join(permission_url))
TypeError: sequence item 133: expected str instance, NoneType found
[2025-03-04 16:06:08,923] [runserver.py:154] [runserver:log_action] [ERROR]- HTTP GET /favicon.ico 500 [0.11, 127.0.0.1:61744]
[2025-03-04 16:06:48,922] [log.py:228] [log:log_response] [ERROR]- Internal Server Error: /favicon.ico
Traceback (most recent call last):
  File "C:\Python372\mecheck\lib\site-packages\django\core\handlers\exception.py", line 34, in inner
    response = get_response(request)
  File "C:\djangoproject\Reliability_Row_data\middleware\checkper.py", line 14, in __call__
    response = self.process_request(request)
  File "C:\djangoproject\Reliability_Row_data\middleware\checkper.py", line 80, in process_request
    info = '<br/>' + ('<br/>'.join(permission_url))
TypeError: sequence item 133: expected str instance, NoneType found
[2025-03-04 16:06:48,924] [runserver.py:154] [runserver:log_action] [ERROR]- HTTP GET /favicon.ico 500 [0.06, 127.0.0.1:61744]
[2025-03-04 16:11:40,211] [log.py:228] [log:log_response] [ERROR]- Internal Server Error: /favicon.ico
Traceback (most recent call last):
  File "C:\Python372\mecheck\lib\site-packages\django\core\handlers\exception.py", line 34, in inner
    response = get_response(request)
  File "C:\djangoproject\Reliability_Row_data\middleware\checkper.py", line 14, in __call__
    response = self.process_request(request)
  File "C:\djangoproject\Reliability_Row_data\middleware\checkper.py", line 80, in process_request
    info = '<br/>' + ('<br/>'.join(permission_url))
TypeError: sequence item 133: expected str instance, NoneType found
[2025-03-04 16:11:40,214] [runserver.py:154] [runserver:log_action] [ERROR]- HTTP GET /favicon.ico 500 [0.41, 127.0.0.1:62236]
[2025-03-04 16:14:48,947] [log.py:228] [log:log_response] [ERROR]- Internal Server Error: /favicon.ico
Traceback (most recent call last):
  File "C:\Python372\mecheck\lib\site-packages\django\core\handlers\exception.py", line 34, in inner
    response = get_response(request)
  File "C:\djangoproject\Reliability_Row_data\middleware\checkper.py", line 14, in __call__
    response = self.process_request(request)
  File "C:\djangoproject\Reliability_Row_data\middleware\checkper.py", line 80, in process_request
    info = '<br/>' + ('<br/>'.join(permission_url))
TypeError: sequence item 133: expected str instance, NoneType found
[2025-03-04 16:14:48,949] [runserver.py:154] [runserver:log_action] [ERROR]- HTTP GET /favicon.ico 500 [0.07, 127.0.0.1:62490]
[2025-03-04 16:16:18,773] [log.py:228] [log:log_response] [ERROR]- Internal Server Error: /favicon.ico
Traceback (most recent call last):
  File "C:\Python372\mecheck\lib\site-packages\django\core\handlers\exception.py", line 34, in inner
    response = get_response(request)
  File "C:\djangoproject\Reliability_Row_data\middleware\checkper.py", line 14, in __call__
    response = self.process_request(request)
  File "C:\djangoproject\Reliability_Row_data\middleware\checkper.py", line 81, in process_request
    info = '<br/>' + ('<br/>'.join(permission_url))
TypeError: sequence item 133: expected str instance, NoneType found
[2025-03-04 16:16:18,778] [runserver.py:154] [runserver:log_action] [ERROR]- HTTP GET /favicon.ico 500 [0.40, 127.0.0.1:62651]
[2025-03-04 16:17:39,657] [log.py:228] [log:log_response] [ERROR]- Internal Server Error: /favicon.ico
Traceback (most recent call last):
  File "C:\Python372\mecheck\lib\site-packages\django\core\handlers\exception.py", line 34, in inner
    response = get_response(request)
  File "C:\djangoproject\Reliability_Row_data\middleware\checkper.py", line 14, in __call__
    response = self.process_request(request)
  File "C:\djangoproject\Reliability_Row_data\middleware\checkper.py", line 81, in process_request
    info = '<br/>' + ('<br/>'.join(permission_url))
TypeError: sequence item 133: expected str instance, NoneType found
[2025-03-04 16:17:39,665] [runserver.py:154] [runserver:log_action] [ERROR]- HTTP GET /favicon.ico 500 [0.41, 127.0.0.1:62873]
[2025-03-04 16:17:40,164] [log.py:228] [log:log_response] [ERROR]- Internal Server Error: /favicon.ico
Traceback (most recent call last):
  File "C:\Python372\mecheck\lib\site-packages\django\core\handlers\exception.py", line 34, in inner
    response = get_response(request)
  File "C:\djangoproject\Reliability_Row_data\middleware\checkper.py", line 14, in __call__
    response = self.process_request(request)
  File "C:\djangoproject\Reliability_Row_data\middleware\checkper.py", line 81, in process_request
    info = '<br/>' + ('<br/>'.join(permission_url))
TypeError: sequence item 133: expected str instance, NoneType found
[2025-03-04 16:17:40,167] [runserver.py:154] [runserver:log_action] [ERROR]- HTTP GET /favicon.ico 500 [0.11, 127.0.0.1:62871]
[2025-03-04 16:17:43,349] [log.py:228] [log:log_response] [ERROR]- Internal Server Error: /favicon.ico
Traceback (most recent call last):
  File "C:\Python372\mecheck\lib\site-packages\django\core\handlers\exception.py", line 34, in inner
    response = get_response(request)
  File "C:\djangoproject\Reliability_Row_data\middleware\checkper.py", line 14, in __call__
    response = self.process_request(request)
  File "C:\djangoproject\Reliability_Row_data\middleware\checkper.py", line 81, in process_request
    info = '<br/>' + ('<br/>'.join(permission_url))
TypeError: sequence item 133: expected str instance, NoneType found
[2025-03-04 16:17:43,354] [runserver.py:154] [runserver:log_action] [ERROR]- HTTP GET /favicon.ico 500 [0.08, 127.0.0.1:62871]
[2025-03-04 16:17:47,127] [log.py:228] [log:log_response] [ERROR]- Internal Server Error: /favicon.ico
Traceback (most recent call last):
  File "C:\Python372\mecheck\lib\site-packages\django\core\handlers\exception.py", line 34, in inner
    response = get_response(request)
  File "C:\djangoproject\Reliability_Row_data\middleware\checkper.py", line 14, in __call__
    response = self.process_request(request)
  File "C:\djangoproject\Reliability_Row_data\middleware\checkper.py", line 81, in process_request
    info = '<br/>' + ('<br/>'.join(permission_url))
TypeError: sequence item 133: expected str instance, NoneType found
[2025-03-04 16:17:47,132] [runserver.py:154] [runserver:log_action] [ERROR]- HTTP GET /favicon.ico 500 [0.30, 127.0.0.1:62871]
[2025-03-04 16:17:52,394] [log.py:228] [log:log_response] [ERROR]- Internal Server Error: /favicon.ico
Traceback (most recent call last):
  File "C:\Python372\mecheck\lib\site-packages\django\core\handlers\exception.py", line 34, in inner
    response = get_response(request)
  File "C:\djangoproject\Reliability_Row_data\middleware\checkper.py", line 14, in __call__
    response = self.process_request(request)
  File "C:\djangoproject\Reliability_Row_data\middleware\checkper.py", line 81, in process_request
    info = '<br/>' + ('<br/>'.join(permission_url))
TypeError: sequence item 133: expected str instance, NoneType found
[2025-03-04 16:17:52,398] [runserver.py:154] [runserver:log_action] [ERROR]- HTTP GET /favicon.ico 500 [1.26, 127.0.0.1:62873]
[2025-03-04 16:18:08,033] [log.py:228] [log:log_response] [ERROR]- Internal Server Error: /favicon.ico
Traceback (most recent call last):
  File "C:\Python372\mecheck\lib\site-packages\django\core\handlers\exception.py", line 34, in inner
    response = get_response(request)
  File "C:\djangoproject\Reliability_Row_data\middleware\checkper.py", line 14, in __call__
    response = self.process_request(request)
  File "C:\djangoproject\Reliability_Row_data\middleware\checkper.py", line 81, in process_request
    info = '<br/>' + ('<br/>'.join(permission_url))
TypeError: sequence item 133: expected str instance, NoneType found
[2025-03-04 16:18:08,038] [runserver.py:154] [runserver:log_action] [ERROR]- HTTP GET /favicon.ico 500 [2.10, 127.0.0.1:62873]
[2025-03-04 16:18:10,094] [log.py:228] [log:log_response] [ERROR]- Internal Server Error: /favicon.ico
Traceback (most recent call last):
  File "C:\Python372\mecheck\lib\site-packages\django\core\handlers\exception.py", line 34, in inner
    response = get_response(request)
  File "C:\djangoproject\Reliability_Row_data\middleware\checkper.py", line 14, in __call__
    response = self.process_request(request)
  File "C:\djangoproject\Reliability_Row_data\middleware\checkper.py", line 81, in process_request
    info = '<br/>' + ('<br/>'.join(permission_url))
TypeError: sequence item 133: expected str instance, NoneType found
[2025-03-04 16:18:10,097] [runserver.py:154] [runserver:log_action] [ERROR]- HTTP GET /favicon.ico 500 [2.05, 127.0.0.1:62873]
[2025-03-04 16:18:24,239] [log.py:228] [log:log_response] [ERROR]- Internal Server Error: /favicon.ico
Traceback (most recent call last):
  File "C:\Python372\mecheck\lib\site-packages\django\core\handlers\exception.py", line 34, in inner
    response = get_response(request)
  File "C:\djangoproject\Reliability_Row_data\middleware\checkper.py", line 14, in __call__
    response = self.process_request(request)
  File "C:\djangoproject\Reliability_Row_data\middleware\checkper.py", line 81, in process_request
    info = '<br/>' + ('<br/>'.join(permission_url))
TypeError: sequence item 133: expected str instance, NoneType found
[2025-03-04 16:18:24,244] [runserver.py:154] [runserver:log_action] [ERROR]- HTTP GET /favicon.ico 500 [0.12, 127.0.0.1:62932]
[2025-03-04 16:18:25,674] [log.py:228] [log:log_response] [ERROR]- Internal Server Error: /favicon.ico
Traceback (most recent call last):
  File "C:\Python372\mecheck\lib\site-packages\django\core\handlers\exception.py", line 34, in inner
    response = get_response(request)
  File "C:\djangoproject\Reliability_Row_data\middleware\checkper.py", line 14, in __call__
    response = self.process_request(request)
  File "C:\djangoproject\Reliability_Row_data\middleware\checkper.py", line 81, in process_request
    info = '<br/>' + ('<br/>'.join(permission_url))
TypeError: sequence item 133: expected str instance, NoneType found
[2025-03-04 16:18:25,679] [runserver.py:154] [runserver:log_action] [ERROR]- HTTP GET /favicon.ico 500 [0.49, 127.0.0.1:62873]
[2025-03-04 16:31:13,317] [log.py:228] [log:log_response] [ERROR]- Internal Server Error: /
Traceback (most recent call last):
  File "C:\Python372\mecheck\lib\site-packages\django\core\handlers\exception.py", line 34, in inner
    response = get_response(request)
  File "C:\djangoproject\Reliability_Row_data\middleware\checkper.py", line 14, in __call__
    response = self.process_request(request)
  File "C:\djangoproject\Reliability_Row_data\middleware\checkper.py", line 81, in process_request
    info = '<br/>' + ('<br/>'.join(permission_url))
TypeError: sequence item 133: expected str instance, NoneType found
[2025-03-04 16:31:13,321] [runserver.py:154] [runserver:log_action] [ERROR]- HTTP GET / 500 [0.36, 127.0.0.1:63986]
[2025-03-04 16:31:13,474] [log.py:228] [log:log_response] [ERROR]- Internal Server Error: /favicon.ico
Traceback (most recent call last):
  File "C:\Python372\mecheck\lib\site-packages\django\core\handlers\exception.py", line 34, in inner
    response = get_response(request)
  File "C:\djangoproject\Reliability_Row_data\middleware\checkper.py", line 14, in __call__
    response = self.process_request(request)
  File "C:\djangoproject\Reliability_Row_data\middleware\checkper.py", line 81, in process_request
    info = '<br/>' + ('<br/>'.join(permission_url))
TypeError: sequence item 133: expected str instance, NoneType found
[2025-03-04 16:31:13,476] [runserver.py:154] [runserver:log_action] [ERROR]- HTTP GET /favicon.ico 500 [0.06, 127.0.0.1:63986]
[2025-03-04 16:34:10,825] [log.py:228] [log:log_response] [ERROR]- Internal Server Error: /
Traceback (most recent call last):
  File "C:\Python372\mecheck\lib\site-packages\django\core\handlers\exception.py", line 34, in inner
    response = get_response(request)
  File "C:\djangoproject\Reliability_Row_data\middleware\checkper.py", line 14, in __call__
    response = self.process_request(request)
  File "C:\djangoproject\Reliability_Row_data\middleware\checkper.py", line 81, in process_request
    info = '<br/>' + ('<br/>'.join(permission_url))
TypeError: sequence item 133: expected str instance, NoneType found
[2025-03-04 16:38:32,814] [log.py:228] [log:log_response] [ERROR]- Internal Server Error: /favicon.ico
Traceback (most recent call last):
  File "C:\Python372\mecheck\lib\site-packages\django\core\handlers\exception.py", line 34, in inner
    response = get_response(request)
  File "C:\djangoproject\Reliability_Row_data\middleware\checkper.py", line 14, in __call__
    response = self.process_request(request)
  File "C:\djangoproject\Reliability_Row_data\middleware\checkper.py", line 81, in process_request
    info = '<br/>' + ('<br/>'.join(permission_url))
TypeError: sequence item 133: expected str instance, NoneType found
[2025-03-04 16:38:32,817] [runserver.py:154] [runserver:log_action] [ERROR]- HTTP GET /favicon.ico 500 [0.35, 127.0.0.1:64559]
