[2025-05-15 10:43:42,392] [log.py:228] [log:log_response] [ERROR]- Internal Server Error: /MiscellaneousPurchases/SubscriptionStatus/
Traceback (most recent call last):
  File "C:\Python3129\mecheck\lib\site-packages\django\core\handlers\exception.py", line 34, in inner
    response = get_response(request)
  File "C:\Python3129\mecheck\lib\site-packages\django\core\handlers\base.py", line 126, in _get_response
    response = self.process_exception_by_middleware(e, request)
  File "C:\Python3129\mecheck\lib\site-packages\django\core\handlers\base.py", line 124, in _get_response
    response = wrapped_callback(request, *callback_args, **callback_kwargs)
  File "C:\Python3129\mecheck\lib\site-packages\django\views\decorators\csrf.py", line 54, in wrapped_view
    return view_func(*args, **kwargs)
  File "C:\djangoproject\Reliability_Row_data\MiscellaneousPurchases\views.py", line 138, in SubscriptionStatus_view
    SubscriptionStatus.objects.filter(id=editID).update(**update_dic)
  File "C:\Python3129\mecheck\lib\site-packages\django\db\models\query.py", line 693, in update
    rows = query.get_compiler(self.db).execute_sql(CURSOR)
  File "C:\Python3129\mecheck\lib\site-packages\django\db\models\sql\compiler.py", line 1383, in execute_sql
    cursor = super().execute_sql(result_type)
  File "C:\Python3129\mecheck\lib\site-packages\django\db\models\sql\compiler.py", line 1052, in execute_sql
    sql, params = self.as_sql()
  File "C:\Python3129\mecheck\lib\site-packages\django\db\models\sql\compiler.py", line 1349, in as_sql
    val = field.get_db_prep_save(val, connection=self.connection)
  File "C:\Python3129\mecheck\lib\site-packages\django\db\models\fields\__init__.py", line 790, in get_db_prep_save
    return self.get_db_prep_value(value, connection=connection, prepared=False)
  File "C:\Python3129\mecheck\lib\site-packages\django\db\models\fields\__init__.py", line 785, in get_db_prep_value
    value = self.get_prep_value(value)
  File "C:\Python3129\mecheck\lib\site-packages\django\db\models\fields\__init__.py", line 1737, in get_prep_value
    return float(value)
ValueError: could not convert string to float: '277xq'
[2025-05-15 10:43:42,410] [runserver.py:154] [runserver:log_action] [ERROR]- HTTP POST /MiscellaneousPurchases/SubscriptionStatus/ 500 [0.56, 127.0.0.1:56794]
[2025-05-15 10:43:50,348] [log.py:228] [log:log_response] [ERROR]- Internal Server Error: /MiscellaneousPurchases/SubscriptionStatus/
Traceback (most recent call last):
  File "C:\Python3129\mecheck\lib\site-packages\django\core\handlers\exception.py", line 34, in inner
    response = get_response(request)
  File "C:\Python3129\mecheck\lib\site-packages\django\core\handlers\base.py", line 126, in _get_response
    response = self.process_exception_by_middleware(e, request)
  File "C:\Python3129\mecheck\lib\site-packages\django\core\handlers\base.py", line 124, in _get_response
    response = wrapped_callback(request, *callback_args, **callback_kwargs)
  File "C:\Python3129\mecheck\lib\site-packages\django\views\decorators\csrf.py", line 54, in wrapped_view
    return view_func(*args, **kwargs)
  File "C:\djangoproject\Reliability_Row_data\MiscellaneousPurchases\views.py", line 138, in SubscriptionStatus_view
    SubscriptionStatus.objects.filter(id=editID).update(**update_dic)
  File "C:\Python3129\mecheck\lib\site-packages\django\db\models\query.py", line 693, in update
    rows = query.get_compiler(self.db).execute_sql(CURSOR)
  File "C:\Python3129\mecheck\lib\site-packages\django\db\models\sql\compiler.py", line 1383, in execute_sql
    cursor = super().execute_sql(result_type)
  File "C:\Python3129\mecheck\lib\site-packages\django\db\models\sql\compiler.py", line 1052, in execute_sql
    sql, params = self.as_sql()
  File "C:\Python3129\mecheck\lib\site-packages\django\db\models\sql\compiler.py", line 1349, in as_sql
    val = field.get_db_prep_save(val, connection=self.connection)
  File "C:\Python3129\mecheck\lib\site-packages\django\db\models\fields\__init__.py", line 790, in get_db_prep_save
    return self.get_db_prep_value(value, connection=connection, prepared=False)
  File "C:\Python3129\mecheck\lib\site-packages\django\db\models\fields\__init__.py", line 785, in get_db_prep_value
    value = self.get_prep_value(value)
  File "C:\Python3129\mecheck\lib\site-packages\django\db\models\fields\__init__.py", line 1737, in get_prep_value
    return float(value)
ValueError: could not convert string to float: '277xq'
[2025-05-15 10:43:50,354] [runserver.py:154] [runserver:log_action] [ERROR]- HTTP POST /MiscellaneousPurchases/SubscriptionStatus/ 500 [0.10, 127.0.0.1:56901]
