[2025-07-10 09:15:33,967] [log.py:228] [log:log_response] [ERROR]- Internal Server Error: /CommonFiles/CommonFiles_edit/
Traceback (most recent call last):
  File "C:\Python3129\mecheck\lib\site-packages\django\core\handlers\exception.py", line 34, in inner
    response = get_response(request)
  File "C:\Python3129\mecheck\lib\site-packages\django\core\handlers\base.py", line 126, in _get_response
    response = self.process_exception_by_middleware(e, request)
  File "C:\Python3129\mecheck\lib\site-packages\django\core\handlers\base.py", line 124, in _get_response
    response = wrapped_callback(request, *callback_args, **callback_kwargs)
  File "C:\Python3129\mecheck\lib\site-packages\django\views\decorators\csrf.py", line 54, in wrapped_view
    return view_func(*args, **kwargs)
  File "C:\djangoproject\Reliability_Row_data\CommonFiles\views.py", line 376, in CommonFiles_edit
    CommonFiles_object.Attachment.add(empt)
AttributeError: 'int' object has no attribute 'Attachment'
[2025-07-10 09:15:33,999] [runserver.py:154] [runserver:log_action] [ERROR]- HTTP POST /CommonFiles/CommonFiles_edit/ 500 [1.09, 127.0.0.1:58077]
