[2024-10-14 12:42:34,161] [log.py:228] [log:log_response] [ERROR]- Internal Server Error: /Navigations_Category/
Traceback (most recent call last):
  File "C:\Python372\mecheck\lib\site-packages\django\core\handlers\exception.py", line 34, in inner
    response = get_response(request)
  File "C:\Python372\mecheck\lib\site-packages\django\core\handlers\base.py", line 126, in _get_response
    response = self.process_exception_by_middleware(e, request)
  File "C:\Python372\mecheck\lib\site-packages\django\core\handlers\base.py", line 124, in _get_response
    response = wrapped_callback(request, *callback_args, **callback_kwargs)
  File "C:\Python372\mecheck\lib\site-packages\django\views\decorators\csrf.py", line 54, in wrapped_view
    return view_func(*args, **kwargs)
  File "C:\djangoproject\Reliability_Row_data\app01\views.py", line 1078, in Navigations_Category_axios
    gridData_Category = All_system_dic[request.POST.get("Categoryname")]
KeyError: '部門管理'
[2024-10-14 12:42:34,166] [runserver.py:154] [runserver:log_action] [ERROR]- HTTP POST /Navigations_Category/ 500 [0.32, 127.0.0.1:59122]
[2024-10-14 13:11:07,608] [log.py:228] [log:log_response] [ERROR]- Internal Server Error: /Navigations_system/
Traceback (most recent call last):
  File "C:\Python372\mecheck\lib\site-packages\django\core\handlers\exception.py", line 34, in inner
    response = get_response(request)
  File "C:\Python372\mecheck\lib\site-packages\django\core\handlers\base.py", line 126, in _get_response
    response = self.process_exception_by_middleware(e, request)
  File "C:\Python372\mecheck\lib\site-packages\django\core\handlers\base.py", line 124, in _get_response
    response = wrapped_callback(request, *callback_args, **callback_kwargs)
  File "C:\Python372\mecheck\lib\site-packages\django\views\decorators\csrf.py", line 54, in wrapped_view
    return view_func(*args, **kwargs)
  File "C:\djangoproject\Reliability_Row_data\app01\views.py", line 2639, in Navigations_system_axios
    gridData = All_system_dic[Sysname]
KeyError: 'CapitalExpenditure'
[2024-10-14 13:11:07,620] [runserver.py:154] [runserver:log_action] [ERROR]- HTTP POST /Navigations_system/ 500 [1.09, 127.0.0.1:56547]
[2024-10-14 13:11:13,110] [log.py:228] [log:log_response] [ERROR]- Internal Server Error: /Navigations_system/
Traceback (most recent call last):
  File "C:\Python372\mecheck\lib\site-packages\django\core\handlers\exception.py", line 34, in inner
    response = get_response(request)
  File "C:\Python372\mecheck\lib\site-packages\django\core\handlers\base.py", line 126, in _get_response
    response = self.process_exception_by_middleware(e, request)
  File "C:\Python372\mecheck\lib\site-packages\django\core\handlers\base.py", line 124, in _get_response
    response = wrapped_callback(request, *callback_args, **callback_kwargs)
  File "C:\Python372\mecheck\lib\site-packages\django\views\decorators\csrf.py", line 54, in wrapped_view
    return view_func(*args, **kwargs)
  File "C:\djangoproject\Reliability_Row_data\app01\views.py", line 2639, in Navigations_system_axios
    gridData = All_system_dic[Sysname]
KeyError: 'PublicArea'
[2024-10-14 13:11:13,147] [runserver.py:154] [runserver:log_action] [ERROR]- HTTP POST /Navigations_system/ 500 [0.18, 127.0.0.1:56547]
