[2024-09-12 15:01:30,385] [log.py:228] [log:log_response] [ERROR]- Internal Server Error: /ProjectInfoSearch/
Traceback (most recent call last):
  File "C:\Python372\mecheck\lib\site-packages\django\core\handlers\exception.py", line 34, in inner
    response = get_response(request)
  File "C:\Python372\mecheck\lib\site-packages\django\core\handlers\base.py", line 126, in _get_response
    response = self.process_exception_by_middleware(e, request)
  File "C:\Python372\mecheck\lib\site-packages\django\core\handlers\base.py", line 124, in _get_response
    response = wrapped_callback(request, *callback_args, **callback_kwargs)
  File "C:\Python372\mecheck\lib\site-packages\django\views\decorators\csrf.py", line 54, in wrapped_view
    return view_func(*args, **kwargs)
  File "C:\djangoproject\Reliability_Row_data\app01\views.py", line 363, in ProjectInfoSearch
    DataTypeSearch = responseData['DataType']
KeyError: 'DataType'
[2024-09-12 15:01:30,406] [runserver.py:154] [runserver:log_action] [ERROR]- HTTP POST /ProjectInfoSearch/ 500 [1.16, 127.0.0.1:61440]
