[2025-02-20 09:09:37,166] [log.py:228] [log:log_response] [ERROR]- Internal Server Error: /SpecDownload/ManagementSop-summary/
Traceback (most recent call last):
  File "C:\Python372\mecheck\lib\site-packages\django\core\handlers\exception.py", line 34, in inner
    response = get_response(request)
  File "C:\Python372\mecheck\lib\site-packages\django\core\handlers\base.py", line 126, in _get_response
    response = self.process_exception_by_middleware(e, request)
  File "C:\Python372\mecheck\lib\site-packages\django\core\handlers\base.py", line 124, in _get_response
    response = wrapped_callback(request, *callback_args, **callback_kwargs)
  File "C:\Python372\mecheck\lib\site-packages\django\views\decorators\csrf.py", line 54, in wrapped_view
    return view_func(*args, **kwargs)
  File "C:\djangoproject\Reliability_Row_data\SpecDownload\views.py", line 356, in ManagementSop_summary
    addPermission, deletePermission = 1
TypeError: cannot unpack non-iterable int object
[2025-02-20 09:09:37,174] [runserver.py:154] [runserver:log_action] [ERROR]- HTTP GET /SpecDownload/ManagementSop-summary/ 500 [0.22, 127.0.0.1:57473]
[2025-02-20 09:23:18,046] [log.py:228] [log:log_response] [ERROR]- Internal Server Error: /SpecDownload/ManagementSop-summary/
Traceback (most recent call last):
  File "C:\Python372\mecheck\lib\site-packages\django\core\handlers\exception.py", line 34, in inner
    response = get_response(request)
  File "C:\Python372\mecheck\lib\site-packages\django\core\handlers\base.py", line 126, in _get_response
    response = self.process_exception_by_middleware(e, request)
  File "C:\Python372\mecheck\lib\site-packages\django\core\handlers\base.py", line 124, in _get_response
    response = wrapped_callback(request, *callback_args, **callback_kwargs)
  File "C:\Python372\mecheck\lib\site-packages\django\views\decorators\csrf.py", line 54, in wrapped_view
    return view_func(*args, **kwargs)
  File "C:\djangoproject\Reliability_Row_data\SpecDownload\views.py", line 375, in ManagementSop_summary
    if SpecDownload.objects.filter(Num=Num):
  File "C:\Python372\mecheck\lib\site-packages\django\db\models\manager.py", line 82, in manager_method
    return getattr(self.get_queryset(), name)(*args, **kwargs)
  File "C:\Python372\mecheck\lib\site-packages\django\db\models\query.py", line 844, in filter
    return self._filter_or_exclude(False, *args, **kwargs)
  File "C:\Python372\mecheck\lib\site-packages\django\db\models\query.py", line 862, in _filter_or_exclude
    clone.query.add_q(Q(*args, **kwargs))
  File "C:\Python372\mecheck\lib\site-packages\django\db\models\sql\query.py", line 1263, in add_q
    clause, _ = self._add_q(q_object, self.used_aliases)
  File "C:\Python372\mecheck\lib\site-packages\django\db\models\sql\query.py", line 1287, in _add_q
    split_subq=split_subq,
  File "C:\Python372\mecheck\lib\site-packages\django\db\models\sql\query.py", line 1164, in build_filter
    lookups, parts, reffed_expression = self.solve_lookup_type(arg)
  File "C:\Python372\mecheck\lib\site-packages\django\db\models\sql\query.py", line 1028, in solve_lookup_type
    _, field, _, lookup_parts = self.names_to_path(lookup_splitted, self.get_meta())
  File "C:\Python372\mecheck\lib\site-packages\django\db\models\sql\query.py", line 1389, in names_to_path
    "Choices are: %s" % (name, ", ".join(available)))
django.core.exceptions.FieldError: Cannot resolve keyword 'Num' into field. Choices are: Case_name, Category, Customer, Functionn, Project, Version, edit_time, editor, files_Spec, id
[2025-02-20 09:23:18,060] [runserver.py:154] [runserver:log_action] [ERROR]- HTTP POST /SpecDownload/ManagementSop-summary/ 500 [0.28, 127.0.0.1:60389]
[2025-02-20 10:12:10,560] [log.py:228] [log:log_response] [ERROR]- Internal Server Error: /SpecDownload/ManagementSop-summary/
Traceback (most recent call last):
  File "C:\Python372\mecheck\lib\site-packages\django\core\handlers\exception.py", line 34, in inner
    response = get_response(request)
  File "C:\Python372\mecheck\lib\site-packages\django\core\handlers\base.py", line 126, in _get_response
    response = self.process_exception_by_middleware(e, request)
  File "C:\Python372\mecheck\lib\site-packages\django\core\handlers\base.py", line 124, in _get_response
    response = wrapped_callback(request, *callback_args, **callback_kwargs)
  File "C:\Python372\mecheck\lib\site-packages\django\views\decorators\csrf.py", line 54, in wrapped_view
    return view_func(*args, **kwargs)
  File "C:\djangoproject\Reliability_Row_data\SpecDownload\views.py", line 412, in ManagementSop_summary
    instance = ManagementSopRoom.objects.get(id=1)
  File "C:\Python372\mecheck\lib\site-packages\django\db\models\manager.py", line 82, in manager_method
    return getattr(self.get_queryset(), name)(*args, **kwargs)
  File "C:\Python372\mecheck\lib\site-packages\django\db\models\query.py", line 399, in get
    self.model._meta.object_name
SpecDownload.models.ManagementSopRoom.DoesNotExist: ManagementSopRoom matching query does not exist.
[2025-02-20 10:12:10,564] [runserver.py:154] [runserver:log_action] [ERROR]- HTTP POST /SpecDownload/ManagementSop-summary/ 500 [0.15, 127.0.0.1:51068]
[2025-02-20 10:12:40,451] [log.py:228] [log:log_response] [ERROR]- Internal Server Error: /SpecDownload/ManagementSop-summary/
Traceback (most recent call last):
  File "C:\Python372\mecheck\lib\site-packages\django\core\handlers\exception.py", line 34, in inner
    response = get_response(request)
  File "C:\Python372\mecheck\lib\site-packages\django\core\handlers\base.py", line 126, in _get_response
    response = self.process_exception_by_middleware(e, request)
  File "C:\Python372\mecheck\lib\site-packages\django\core\handlers\base.py", line 124, in _get_response
    response = wrapped_callback(request, *callback_args, **callback_kwargs)
  File "C:\Python372\mecheck\lib\site-packages\django\views\decorators\csrf.py", line 54, in wrapped_view
    return view_func(*args, **kwargs)
  File "C:\djangoproject\Reliability_Row_data\SpecDownload\views.py", line 409, in ManagementSop_summary
    ManagementSopRoom.objects.get(id=i).files_Spec.all().delete()
  File "C:\Python372\mecheck\lib\site-packages\django\db\models\manager.py", line 82, in manager_method
    return getattr(self.get_queryset(), name)(*args, **kwargs)
  File "C:\Python372\mecheck\lib\site-packages\django\db\models\query.py", line 399, in get
    self.model._meta.object_name
SpecDownload.models.ManagementSopRoom.DoesNotExist: ManagementSopRoom matching query does not exist.
[2025-02-20 10:12:40,461] [runserver.py:154] [runserver:log_action] [ERROR]- HTTP POST /SpecDownload/ManagementSop-summary/ 500 [0.14, 127.0.0.1:50839]
[2025-02-20 10:14:38,042] [log.py:228] [log:log_response] [ERROR]- Internal Server Error: /SpecDownload/ManagementSop-summary/
Traceback (most recent call last):
  File "C:\Python372\mecheck\lib\site-packages\django\core\handlers\exception.py", line 34, in inner
    response = get_response(request)
  File "C:\Python372\mecheck\lib\site-packages\django\core\handlers\base.py", line 126, in _get_response
    response = self.process_exception_by_middleware(e, request)
  File "C:\Python372\mecheck\lib\site-packages\django\core\handlers\base.py", line 124, in _get_response
    response = wrapped_callback(request, *callback_args, **callback_kwargs)
  File "C:\Python372\mecheck\lib\site-packages\django\views\decorators\csrf.py", line 54, in wrapped_view
    return view_func(*args, **kwargs)
  File "C:\djangoproject\Reliability_Row_data\SpecDownload\views.py", line 409, in ManagementSop_summary
    ManagementSopRoom.objects.get(id=i).files_Spec.all().delete()
  File "C:\Python372\mecheck\lib\site-packages\django\db\models\manager.py", line 82, in manager_method
    return getattr(self.get_queryset(), name)(*args, **kwargs)
  File "C:\Python372\mecheck\lib\site-packages\django\db\models\query.py", line 399, in get
    self.model._meta.object_name
SpecDownload.models.ManagementSopRoom.DoesNotExist: ManagementSopRoom matching query does not exist.
[2025-02-20 10:14:38,044] [runserver.py:154] [runserver:log_action] [ERROR]- HTTP POST /SpecDownload/ManagementSop-summary/ 500 [0.06, 127.0.0.1:51057]
[2025-02-20 10:15:20,171] [log.py:228] [log:log_response] [ERROR]- Internal Server Error: /SpecDownload/ManagementSop-summary/
Traceback (most recent call last):
  File "C:\Python372\mecheck\lib\site-packages\django\core\handlers\exception.py", line 34, in inner
    response = get_response(request)
  File "C:\Python372\mecheck\lib\site-packages\django\core\handlers\base.py", line 126, in _get_response
    response = self.process_exception_by_middleware(e, request)
  File "C:\Python372\mecheck\lib\site-packages\django\core\handlers\base.py", line 124, in _get_response
    response = wrapped_callback(request, *callback_args, **callback_kwargs)
  File "C:\Python372\mecheck\lib\site-packages\django\views\decorators\csrf.py", line 54, in wrapped_view
    return view_func(*args, **kwargs)
  File "C:\djangoproject\Reliability_Row_data\SpecDownload\views.py", line 412, in ManagementSop_summary
    instance = ManagementSopRoom.objects.get(id=i)
  File "C:\Python372\mecheck\lib\site-packages\django\db\models\manager.py", line 82, in manager_method
    return getattr(self.get_queryset(), name)(*args, **kwargs)
  File "C:\Python372\mecheck\lib\site-packages\django\db\models\query.py", line 399, in get
    self.model._meta.object_name
SpecDownload.models.ManagementSopRoom.DoesNotExist: ManagementSopRoom matching query does not exist.
[2025-02-20 10:15:20,174] [runserver.py:154] [runserver:log_action] [ERROR]- HTTP POST /SpecDownload/ManagementSop-summary/ 500 [0.11, 127.0.0.1:50819]
[2025-02-20 10:16:42,671] [log.py:228] [log:log_response] [ERROR]- Internal Server Error: /SpecDownload/ManagementSop-summary/
Traceback (most recent call last):
  File "C:\Python372\mecheck\lib\site-packages\django\core\handlers\exception.py", line 34, in inner
    response = get_response(request)
  File "C:\Python372\mecheck\lib\site-packages\django\core\handlers\base.py", line 126, in _get_response
    response = self.process_exception_by_middleware(e, request)
  File "C:\Python372\mecheck\lib\site-packages\django\core\handlers\base.py", line 124, in _get_response
    response = wrapped_callback(request, *callback_args, **callback_kwargs)
  File "C:\Python372\mecheck\lib\site-packages\django\views\decorators\csrf.py", line 54, in wrapped_view
    return view_func(*args, **kwargs)
  File "C:\djangoproject\Reliability_Row_data\SpecDownload\views.py", line 413, in ManagementSop_summary
    files_SopRom_delete(instance)
TypeError: files_SopRom_delete() missing 1 required positional argument: 'instance'
[2025-02-20 10:16:42,675] [runserver.py:154] [runserver:log_action] [ERROR]- HTTP POST /SpecDownload/ManagementSop-summary/ 500 [0.24, 127.0.0.1:50879]
[2025-02-20 10:18:23,449] [log.py:228] [log:log_response] [ERROR]- Internal Server Error: /SpecDownload/ManagementSop-summary/
Traceback (most recent call last):
  File "C:\Python372\mecheck\lib\site-packages\django\core\handlers\exception.py", line 34, in inner
    response = get_response(request)
  File "C:\Python372\mecheck\lib\site-packages\django\core\handlers\base.py", line 126, in _get_response
    response = self.process_exception_by_middleware(e, request)
  File "C:\Python372\mecheck\lib\site-packages\django\core\handlers\base.py", line 124, in _get_response
    response = wrapped_callback(request, *callback_args, **callback_kwargs)
  File "C:\Python372\mecheck\lib\site-packages\django\views\decorators\csrf.py", line 54, in wrapped_view
    return view_func(*args, **kwargs)
  File "C:\djangoproject\Reliability_Row_data\SpecDownload\views.py", line 413, in ManagementSop_summary
    files_SopRom_delete(instance)
TypeError: files_SopRom_delete() missing 1 required positional argument: 'instance'
[2025-02-20 10:18:23,453] [runserver.py:154] [runserver:log_action] [ERROR]- HTTP POST /SpecDownload/ManagementSop-summary/ 500 [0.14, 127.0.0.1:51025]
[2025-02-20 10:24:48,479] [log.py:228] [log:log_response] [ERROR]- Internal Server Error: /SpecDownload/ManagementSop-summary/
Traceback (most recent call last):
  File "C:\Python372\mecheck\lib\site-packages\django\core\handlers\exception.py", line 34, in inner
    response = get_response(request)
  File "C:\Python372\mecheck\lib\site-packages\django\core\handlers\base.py", line 126, in _get_response
    response = self.process_exception_by_middleware(e, request)
  File "C:\Python372\mecheck\lib\site-packages\django\core\handlers\base.py", line 124, in _get_response
    response = wrapped_callback(request, *callback_args, **callback_kwargs)
  File "C:\Python372\mecheck\lib\site-packages\django\views\decorators\csrf.py", line 54, in wrapped_view
    return view_func(*args, **kwargs)
  File "C:\djangoproject\Reliability_Row_data\SpecDownload\views.py", line 414, in ManagementSop_summary
    files_SopRom_delete(sender, instance)
  File "C:\djangoproject\Reliability_Row_data\SpecDownload\models.py", line 38, in files_SopRom_delete
    instance.files.delete(False)
AttributeError: 'ManagementSopRoom' object has no attribute 'files'
[2025-02-20 10:24:48,482] [runserver.py:154] [runserver:log_action] [ERROR]- HTTP POST /SpecDownload/ManagementSop-summary/ 500 [0.21, 127.0.0.1:50811]
[2025-02-21 10:17:49,651] [log.py:228] [log:log_response] [ERROR]- Internal Server Error: /favicon.ico
Traceback (most recent call last):
  File "C:\Python372\mecheck\lib\site-packages\django\contrib\sessions\backends\base.py", line 190, in _get_session
    return self._session_cache
AttributeError: 'SessionStore' object has no attribute '_session_cache'

During handling of the above exception, another exception occurred:

Traceback (most recent call last):
  File "C:\Python372\mecheck\lib\site-packages\pymysql\connections.py", line 583, in connect
    **kwargs)
  File "C:\Python372\lib\socket.py", line 727, in create_connection
    raise err
  File "C:\Python372\lib\socket.py", line 716, in create_connection
    sock.connect(sa)
socket.timeout: timed out

During handling of the above exception, another exception occurred:

Traceback (most recent call last):
  File "C:\Python372\mecheck\lib\site-packages\django\db\backends\base\base.py", line 216, in ensure_connection
    self.connect()
  File "C:\Python372\mecheck\lib\site-packages\django\db\backends\base\base.py", line 194, in connect
    self.connection = self.get_new_connection(conn_params)
  File "C:\Python372\mecheck\lib\site-packages\django\db\backends\mysql\base.py", line 227, in get_new_connection
    return Database.connect(**conn_params)
  File "C:\Python372\mecheck\lib\site-packages\pymysql\__init__.py", line 94, in Connect
    return Connection(*args, **kwargs)
  File "C:\Python372\mecheck\lib\site-packages\pymysql\connections.py", line 325, in __init__
    self.connect()
  File "C:\Python372\mecheck\lib\site-packages\pymysql\connections.py", line 630, in connect
    raise exc
pymysql.err.OperationalError: (2003, "Can't connect to MySQL server on '127.0.0.1' (timed out)")

The above exception was the direct cause of the following exception:

Traceback (most recent call last):
  File "C:\Python372\mecheck\lib\site-packages\django\core\handlers\exception.py", line 34, in inner
    response = get_response(request)
  File "C:\djangoproject\Reliability_Row_data\middleware\checkper.py", line 14, in __call__
    response = self.process_request(request)
  File "C:\djangoproject\Reliability_Row_data\middleware\checkper.py", line 32, in process_request
    permission_url = request.session.get(settings.SESSION_PERMISSION_URL_KEY)
  File "C:\Python372\mecheck\lib\site-packages\django\contrib\sessions\backends\base.py", line 66, in get
    return self._session.get(key, default)
  File "C:\Python372\mecheck\lib\site-packages\django\contrib\sessions\backends\base.py", line 195, in _get_session
    self._session_cache = self.load()
  File "C:\Python372\mecheck\lib\site-packages\django\contrib\sessions\backends\db.py", line 43, in load
    s = self._get_session_from_db()
  File "C:\Python372\mecheck\lib\site-packages\django\contrib\sessions\backends\db.py", line 34, in _get_session_from_db
    expire_date__gt=timezone.now()
  File "C:\Python372\mecheck\lib\site-packages\django\db\models\manager.py", line 82, in manager_method
    return getattr(self.get_queryset(), name)(*args, **kwargs)
  File "C:\Python372\mecheck\lib\site-packages\django\db\models\query.py", line 393, in get
    num = len(clone)
  File "C:\Python372\mecheck\lib\site-packages\django\db\models\query.py", line 250, in __len__
    self._fetch_all()
  File "C:\Python372\mecheck\lib\site-packages\django\db\models\query.py", line 1186, in _fetch_all
    self._result_cache = list(self._iterable_class(self))
  File "C:\Python372\mecheck\lib\site-packages\django\db\models\query.py", line 54, in __iter__
    results = compiler.execute_sql(chunked_fetch=self.chunked_fetch, chunk_size=self.chunk_size)
  File "C:\Python372\mecheck\lib\site-packages\django\db\models\sql\compiler.py", line 1063, in execute_sql
    cursor = self.connection.cursor()
  File "C:\Python372\mecheck\lib\site-packages\django\db\backends\base\base.py", line 255, in cursor
    return self._cursor()
  File "C:\Python372\mecheck\lib\site-packages\django\db\backends\base\base.py", line 232, in _cursor
    self.ensure_connection()
  File "C:\Python372\mecheck\lib\site-packages\django\db\backends\base\base.py", line 216, in ensure_connection
    self.connect()
  File "C:\Python372\mecheck\lib\site-packages\django\db\utils.py", line 89, in __exit__
    raise dj_exc_value.with_traceback(traceback) from exc_value
  File "C:\Python372\mecheck\lib\site-packages\django\db\backends\base\base.py", line 216, in ensure_connection
    self.connect()
  File "C:\Python372\mecheck\lib\site-packages\django\db\backends\base\base.py", line 194, in connect
    self.connection = self.get_new_connection(conn_params)
  File "C:\Python372\mecheck\lib\site-packages\django\db\backends\mysql\base.py", line 227, in get_new_connection
    return Database.connect(**conn_params)
  File "C:\Python372\mecheck\lib\site-packages\pymysql\__init__.py", line 94, in Connect
    return Connection(*args, **kwargs)
  File "C:\Python372\mecheck\lib\site-packages\pymysql\connections.py", line 325, in __init__
    self.connect()
  File "C:\Python372\mecheck\lib\site-packages\pymysql\connections.py", line 630, in connect
    raise exc
django.db.utils.OperationalError: (2003, "Can't connect to MySQL server on '127.0.0.1' (timed out)")
[2025-02-21 10:17:49,661] [runserver.py:154] [runserver:log_action] [ERROR]- HTTP GET /favicon.ico 500 [10.20, 127.0.0.1:52431]
[2025-02-21 10:17:53,675] [log.py:228] [log:log_response] [ERROR]- Internal Server Error: /admin/jsi18n/
Traceback (most recent call last):
  File "C:\Python372\mecheck\lib\site-packages\django\contrib\sessions\backends\base.py", line 190, in _get_session
    return self._session_cache
AttributeError: 'SessionStore' object has no attribute '_session_cache'

During handling of the above exception, another exception occurred:

Traceback (most recent call last):
  File "C:\Python372\mecheck\lib\site-packages\pymysql\connections.py", line 583, in connect
    **kwargs)
  File "C:\Python372\lib\socket.py", line 727, in create_connection
    raise err
  File "C:\Python372\lib\socket.py", line 716, in create_connection
    sock.connect(sa)
OSError: [WinError 10048] 通常每个套接字地址(协议/网络地址/端口)只允许使用一次。

During handling of the above exception, another exception occurred:

Traceback (most recent call last):
  File "C:\Python372\mecheck\lib\site-packages\django\db\backends\base\base.py", line 216, in ensure_connection
    self.connect()
  File "C:\Python372\mecheck\lib\site-packages\django\db\backends\base\base.py", line 194, in connect
    self.connection = self.get_new_connection(conn_params)
  File "C:\Python372\mecheck\lib\site-packages\django\db\backends\mysql\base.py", line 227, in get_new_connection
    return Database.connect(**conn_params)
  File "C:\Python372\mecheck\lib\site-packages\pymysql\__init__.py", line 94, in Connect
    return Connection(*args, **kwargs)
  File "C:\Python372\mecheck\lib\site-packages\pymysql\connections.py", line 325, in __init__
    self.connect()
  File "C:\Python372\mecheck\lib\site-packages\pymysql\connections.py", line 630, in connect
    raise exc
pymysql.err.OperationalError: (2003, "Can't connect to MySQL server on '127.0.0.1' ([WinError 10048] 通常每个套接字地址(协议/网络地址/端口)只允许使用一次。)")

The above exception was the direct cause of the following exception:

Traceback (most recent call last):
  File "C:\Python372\mecheck\lib\site-packages\django\core\handlers\exception.py", line 34, in inner
    response = get_response(request)
  File "C:\Python372\mecheck\lib\site-packages\django\core\handlers\base.py", line 126, in _get_response
    response = self.process_exception_by_middleware(e, request)
  File "C:\Python372\mecheck\lib\site-packages\django\core\handlers\base.py", line 124, in _get_response
    response = wrapped_callback(request, *callback_args, **callback_kwargs)
  File "C:\Python372\mecheck\lib\site-packages\django\contrib\admin\sites.py", line 241, in wrapper
    return self.admin_view(view, cacheable)(*args, **kwargs)
  File "C:\Python372\mecheck\lib\site-packages\django\utils\decorators.py", line 142, in _wrapped_view
    response = view_func(request, *args, **kwargs)
  File "C:\Python372\mecheck\lib\site-packages\django\contrib\admin\sites.py", line 212, in inner
    if not self.has_permission(request):
  File "C:\Python372\mecheck\lib\site-packages\django\contrib\admin\sites.py", line 186, in has_permission
    return request.user.is_active and request.user.is_staff
  File "C:\Python372\mecheck\lib\site-packages\django\utils\functional.py", line 213, in inner
    self._setup()
  File "C:\Python372\mecheck\lib\site-packages\django\utils\functional.py", line 347, in _setup
    self._wrapped = self._setupfunc()
  File "C:\Python372\mecheck\lib\site-packages\django\contrib\auth\middleware.py", line 24, in <lambda>
    request.user = SimpleLazyObject(lambda: get_user(request))
  File "C:\Python372\mecheck\lib\site-packages\django\contrib\auth\middleware.py", line 12, in get_user
    request._cached_user = auth.get_user(request)
  File "C:\Python372\mecheck\lib\site-packages\django\contrib\auth\__init__.py", line 182, in get_user
    user_id = _get_user_session_key(request)
  File "C:\Python372\mecheck\lib\site-packages\django\contrib\auth\__init__.py", line 59, in _get_user_session_key
    return get_user_model()._meta.pk.to_python(request.session[SESSION_KEY])
  File "C:\Python372\mecheck\lib\site-packages\django\contrib\sessions\backends\base.py", line 55, in __getitem__
    return self._session[key]
  File "C:\Python372\mecheck\lib\site-packages\django\contrib\sessions\backends\base.py", line 195, in _get_session
    self._session_cache = self.load()
  File "C:\Python372\mecheck\lib\site-packages\django\contrib\sessions\backends\db.py", line 43, in load
    s = self._get_session_from_db()
  File "C:\Python372\mecheck\lib\site-packages\django\contrib\sessions\backends\db.py", line 34, in _get_session_from_db
    expire_date__gt=timezone.now()
  File "C:\Python372\mecheck\lib\site-packages\django\db\models\manager.py", line 82, in manager_method
    return getattr(self.get_queryset(), name)(*args, **kwargs)
  File "C:\Python372\mecheck\lib\site-packages\django\db\models\query.py", line 393, in get
    num = len(clone)
  File "C:\Python372\mecheck\lib\site-packages\django\db\models\query.py", line 250, in __len__
    self._fetch_all()
  File "C:\Python372\mecheck\lib\site-packages\django\db\models\query.py", line 1186, in _fetch_all
    self._result_cache = list(self._iterable_class(self))
  File "C:\Python372\mecheck\lib\site-packages\django\db\models\query.py", line 54, in __iter__
    results = compiler.execute_sql(chunked_fetch=self.chunked_fetch, chunk_size=self.chunk_size)
  File "C:\Python372\mecheck\lib\site-packages\django\db\models\sql\compiler.py", line 1063, in execute_sql
    cursor = self.connection.cursor()
  File "C:\Python372\mecheck\lib\site-packages\django\db\backends\base\base.py", line 255, in cursor
    return self._cursor()
  File "C:\Python372\mecheck\lib\site-packages\django\db\backends\base\base.py", line 232, in _cursor
    self.ensure_connection()
  File "C:\Python372\mecheck\lib\site-packages\django\db\backends\base\base.py", line 216, in ensure_connection
    self.connect()
  File "C:\Python372\mecheck\lib\site-packages\django\db\utils.py", line 89, in __exit__
    raise dj_exc_value.with_traceback(traceback) from exc_value
  File "C:\Python372\mecheck\lib\site-packages\django\db\backends\base\base.py", line 216, in ensure_connection
    self.connect()
  File "C:\Python372\mecheck\lib\site-packages\django\db\backends\base\base.py", line 194, in connect
    self.connection = self.get_new_connection(conn_params)
  File "C:\Python372\mecheck\lib\site-packages\django\db\backends\mysql\base.py", line 227, in get_new_connection
    return Database.connect(**conn_params)
  File "C:\Python372\mecheck\lib\site-packages\pymysql\__init__.py", line 94, in Connect
    return Connection(*args, **kwargs)
  File "C:\Python372\mecheck\lib\site-packages\pymysql\connections.py", line 325, in __init__
    self.connect()
  File "C:\Python372\mecheck\lib\site-packages\pymysql\connections.py", line 630, in connect
    raise exc
django.db.utils.OperationalError: (2003, "Can't connect to MySQL server on '127.0.0.1' ([WinError 10048] 通常每个套接字地址(协议/网络地址/端口)只允许使用一次。)")
[2025-02-21 10:17:53,883] [log.py:228] [log:log_response] [ERROR]- Internal Server Error: /admin/jsi18n/
Traceback (most recent call last):
  File "C:\Python372\mecheck\lib\site-packages\django\contrib\sessions\backends\base.py", line 190, in _get_session
    return self._session_cache
AttributeError: 'SessionStore' object has no attribute '_session_cache'

During handling of the above exception, another exception occurred:

Traceback (most recent call last):
  File "C:\Python372\mecheck\lib\site-packages\pymysql\connections.py", line 583, in connect
    **kwargs)
  File "C:\Python372\lib\socket.py", line 727, in create_connection
    raise err
  File "C:\Python372\lib\socket.py", line 716, in create_connection
    sock.connect(sa)
OSError: [WinError 10048] 通常每个套接字地址(协议/网络地址/端口)只允许使用一次。

During handling of the above exception, another exception occurred:

Traceback (most recent call last):
  File "C:\Python372\mecheck\lib\site-packages\django\db\backends\base\base.py", line 216, in ensure_connection
    self.connect()
  File "C:\Python372\mecheck\lib\site-packages\django\db\backends\base\base.py", line 194, in connect
    self.connection = self.get_new_connection(conn_params)
  File "C:\Python372\mecheck\lib\site-packages\django\db\backends\mysql\base.py", line 227, in get_new_connection
    return Database.connect(**conn_params)
  File "C:\Python372\mecheck\lib\site-packages\pymysql\__init__.py", line 94, in Connect
    return Connection(*args, **kwargs)
  File "C:\Python372\mecheck\lib\site-packages\pymysql\connections.py", line 325, in __init__
    self.connect()
  File "C:\Python372\mecheck\lib\site-packages\pymysql\connections.py", line 630, in connect
    raise exc
pymysql.err.OperationalError: (2003, "Can't connect to MySQL server on '127.0.0.1' ([WinError 10048] 通常每个套接字地址(协议/网络地址/端口)只允许使用一次。)")

The above exception was the direct cause of the following exception:

Traceback (most recent call last):
  File "C:\Python372\mecheck\lib\site-packages\django\core\handlers\exception.py", line 34, in inner
    response = get_response(request)
  File "C:\djangoproject\Reliability_Row_data\middleware\checkper.py", line 14, in __call__
    response = self.process_request(request)
  File "C:\djangoproject\Reliability_Row_data\middleware\checkper.py", line 32, in process_request
    permission_url = request.session.get(settings.SESSION_PERMISSION_URL_KEY)
  File "C:\Python372\mecheck\lib\site-packages\django\contrib\sessions\backends\base.py", line 66, in get
    return self._session.get(key, default)
  File "C:\Python372\mecheck\lib\site-packages\django\contrib\sessions\backends\base.py", line 195, in _get_session
    self._session_cache = self.load()
  File "C:\Python372\mecheck\lib\site-packages\django\contrib\sessions\backends\db.py", line 43, in load
    s = self._get_session_from_db()
  File "C:\Python372\mecheck\lib\site-packages\django\contrib\sessions\backends\db.py", line 34, in _get_session_from_db
    expire_date__gt=timezone.now()
  File "C:\Python372\mecheck\lib\site-packages\django\db\models\manager.py", line 82, in manager_method
    return getattr(self.get_queryset(), name)(*args, **kwargs)
  File "C:\Python372\mecheck\lib\site-packages\django\db\models\query.py", line 393, in get
    num = len(clone)
  File "C:\Python372\mecheck\lib\site-packages\django\db\models\query.py", line 250, in __len__
    self._fetch_all()
  File "C:\Python372\mecheck\lib\site-packages\django\db\models\query.py", line 1186, in _fetch_all
    self._result_cache = list(self._iterable_class(self))
  File "C:\Python372\mecheck\lib\site-packages\django\db\models\query.py", line 54, in __iter__
    results = compiler.execute_sql(chunked_fetch=self.chunked_fetch, chunk_size=self.chunk_size)
  File "C:\Python372\mecheck\lib\site-packages\django\db\models\sql\compiler.py", line 1063, in execute_sql
    cursor = self.connection.cursor()
  File "C:\Python372\mecheck\lib\site-packages\django\db\backends\base\base.py", line 255, in cursor
    return self._cursor()
  File "C:\Python372\mecheck\lib\site-packages\django\db\backends\base\base.py", line 232, in _cursor
    self.ensure_connection()
  File "C:\Python372\mecheck\lib\site-packages\django\db\backends\base\base.py", line 216, in ensure_connection
    self.connect()
  File "C:\Python372\mecheck\lib\site-packages\django\db\utils.py", line 89, in __exit__
    raise dj_exc_value.with_traceback(traceback) from exc_value
  File "C:\Python372\mecheck\lib\site-packages\django\db\backends\base\base.py", line 216, in ensure_connection
    self.connect()
  File "C:\Python372\mecheck\lib\site-packages\django\db\backends\base\base.py", line 194, in connect
    self.connection = self.get_new_connection(conn_params)
  File "C:\Python372\mecheck\lib\site-packages\django\db\backends\mysql\base.py", line 227, in get_new_connection
    return Database.connect(**conn_params)
  File "C:\Python372\mecheck\lib\site-packages\pymysql\__init__.py", line 94, in Connect
    return Connection(*args, **kwargs)
  File "C:\Python372\mecheck\lib\site-packages\pymysql\connections.py", line 325, in __init__
    self.connect()
  File "C:\Python372\mecheck\lib\site-packages\pymysql\connections.py", line 630, in connect
    raise exc
django.db.utils.OperationalError: (2003, "Can't connect to MySQL server on '127.0.0.1' ([WinError 10048] 通常每个套接字地址(协议/网络地址/端口)只允许使用一次。)")
[2025-02-21 10:17:54,051] [log.py:228] [log:log_response] [ERROR]- Internal Server Error: /admin/jsi18n/
Traceback (most recent call last):
  File "C:\Python372\mecheck\lib\site-packages\django\contrib\sessions\backends\base.py", line 190, in _get_session
    return self._session_cache
AttributeError: 'SessionStore' object has no attribute '_session_cache'

During handling of the above exception, another exception occurred:

Traceback (most recent call last):
  File "C:\Python372\mecheck\lib\site-packages\pymysql\connections.py", line 583, in connect
    **kwargs)
  File "C:\Python372\lib\socket.py", line 727, in create_connection
    raise err
  File "C:\Python372\lib\socket.py", line 716, in create_connection
    sock.connect(sa)
OSError: [WinError 10048] 通常每个套接字地址(协议/网络地址/端口)只允许使用一次。

During handling of the above exception, another exception occurred:

Traceback (most recent call last):
  File "C:\Python372\mecheck\lib\site-packages\django\db\backends\base\base.py", line 216, in ensure_connection
    self.connect()
  File "C:\Python372\mecheck\lib\site-packages\django\db\backends\base\base.py", line 194, in connect
    self.connection = self.get_new_connection(conn_params)
  File "C:\Python372\mecheck\lib\site-packages\django\db\backends\mysql\base.py", line 227, in get_new_connection
    return Database.connect(**conn_params)
  File "C:\Python372\mecheck\lib\site-packages\pymysql\__init__.py", line 94, in Connect
    return Connection(*args, **kwargs)
  File "C:\Python372\mecheck\lib\site-packages\pymysql\connections.py", line 325, in __init__
    self.connect()
  File "C:\Python372\mecheck\lib\site-packages\pymysql\connections.py", line 630, in connect
    raise exc
pymysql.err.OperationalError: (2003, "Can't connect to MySQL server on '127.0.0.1' ([WinError 10048] 通常每个套接字地址(协议/网络地址/端口)只允许使用一次。)")

The above exception was the direct cause of the following exception:

Traceback (most recent call last):
  File "C:\Python372\mecheck\lib\site-packages\django\core\handlers\exception.py", line 34, in inner
    response = get_response(request)
  File "C:\Python372\mecheck\lib\site-packages\django\utils\deprecation.py", line 93, in __call__
    response = self.process_response(request, response)
  File "C:\Python372\mecheck\lib\site-packages\django\contrib\sessions\middleware.py", line 47, in process_response
    if request.session.get_expire_at_browser_close():
  File "C:\Python372\mecheck\lib\site-packages\django\contrib\sessions\backends\base.py", line 279, in get_expire_at_browser_close
    if self.get('_session_expiry') is None:
  File "C:\Python372\mecheck\lib\site-packages\django\contrib\sessions\backends\base.py", line 66, in get
    return self._session.get(key, default)
  File "C:\Python372\mecheck\lib\site-packages\django\contrib\sessions\backends\base.py", line 195, in _get_session
    self._session_cache = self.load()
  File "C:\Python372\mecheck\lib\site-packages\django\contrib\sessions\backends\db.py", line 43, in load
    s = self._get_session_from_db()
  File "C:\Python372\mecheck\lib\site-packages\django\contrib\sessions\backends\db.py", line 34, in _get_session_from_db
    expire_date__gt=timezone.now()
  File "C:\Python372\mecheck\lib\site-packages\django\db\models\manager.py", line 82, in manager_method
    return getattr(self.get_queryset(), name)(*args, **kwargs)
  File "C:\Python372\mecheck\lib\site-packages\django\db\models\query.py", line 393, in get
    num = len(clone)
  File "C:\Python372\mecheck\lib\site-packages\django\db\models\query.py", line 250, in __len__
    self._fetch_all()
  File "C:\Python372\mecheck\lib\site-packages\django\db\models\query.py", line 1186, in _fetch_all
    self._result_cache = list(self._iterable_class(self))
  File "C:\Python372\mecheck\lib\site-packages\django\db\models\query.py", line 54, in __iter__
    results = compiler.execute_sql(chunked_fetch=self.chunked_fetch, chunk_size=self.chunk_size)
  File "C:\Python372\mecheck\lib\site-packages\django\db\models\sql\compiler.py", line 1063, in execute_sql
    cursor = self.connection.cursor()
  File "C:\Python372\mecheck\lib\site-packages\django\db\backends\base\base.py", line 255, in cursor
    return self._cursor()
  File "C:\Python372\mecheck\lib\site-packages\django\db\backends\base\base.py", line 232, in _cursor
    self.ensure_connection()
  File "C:\Python372\mecheck\lib\site-packages\django\db\backends\base\base.py", line 216, in ensure_connection
    self.connect()
  File "C:\Python372\mecheck\lib\site-packages\django\db\utils.py", line 89, in __exit__
    raise dj_exc_value.with_traceback(traceback) from exc_value
  File "C:\Python372\mecheck\lib\site-packages\django\db\backends\base\base.py", line 216, in ensure_connection
    self.connect()
  File "C:\Python372\mecheck\lib\site-packages\django\db\backends\base\base.py", line 194, in connect
    self.connection = self.get_new_connection(conn_params)
  File "C:\Python372\mecheck\lib\site-packages\django\db\backends\mysql\base.py", line 227, in get_new_connection
    return Database.connect(**conn_params)
  File "C:\Python372\mecheck\lib\site-packages\pymysql\__init__.py", line 94, in Connect
    return Connection(*args, **kwargs)
  File "C:\Python372\mecheck\lib\site-packages\pymysql\connections.py", line 325, in __init__
    self.connect()
  File "C:\Python372\mecheck\lib\site-packages\pymysql\connections.py", line 630, in connect
    raise exc
django.db.utils.OperationalError: (2003, "Can't connect to MySQL server on '127.0.0.1' ([WinError 10048] 通常每个套接字地址(协议/网络地址/端口)只允许使用一次。)")
[2025-02-21 10:17:54,058] [runserver.py:154] [runserver:log_action] [ERROR]- HTTP GET /admin/jsi18n/ 500 [0.68, 127.0.0.1:52431]
