[2025-10-14 08:32:08,107] [log.py:228] [log:log_response] [ERROR]- Internal Server Error: /MiscellaneousPurchases/ReceiptAmount/
Traceback (most recent call last):
  File "C:\Python3129\mecheck\lib\site-packages\django\core\handlers\exception.py", line 34, in inner
    response = get_response(request)
  File "C:\Python3129\mecheck\lib\site-packages\django\core\handlers\base.py", line 126, in _get_response
    response = self.process_exception_by_middleware(e, request)
  File "C:\Python3129\mecheck\lib\site-packages\django\core\handlers\base.py", line 124, in _get_response
    response = wrapped_callback(request, *callback_args, **callback_kwargs)
  File "C:\Python3129\mecheck\lib\site-packages\django\views\decorators\csrf.py", line 54, in wrapped_view
    return view_func(*args, **kwargs)
  File "C:\djangoproject\Reliability_Row_data\MiscellaneousPurchases\views.py", line 465, in ReceiptAmount_view
    ReceiptAmount.objects.filter(id=ID).update(**update_dic)
  File "C:\Python3129\mecheck\lib\site-packages\django\db\models\query.py", line 693, in update
    rows = query.get_compiler(self.db).execute_sql(CURSOR)
  File "C:\Python3129\mecheck\lib\site-packages\django\db\models\sql\compiler.py", line 1383, in execute_sql
    cursor = super().execute_sql(result_type)
  File "C:\Python3129\mecheck\lib\site-packages\django\db\models\sql\compiler.py", line 1052, in execute_sql
    sql, params = self.as_sql()
  File "C:\Python3129\mecheck\lib\site-packages\django\db\models\sql\compiler.py", line 1349, in as_sql
    val = field.get_db_prep_save(val, connection=self.connection)
  File "C:\Python3129\mecheck\lib\site-packages\django\db\models\fields\__init__.py", line 790, in get_db_prep_save
    return self.get_db_prep_value(value, connection=connection, prepared=False)
  File "C:\Python3129\mecheck\lib\site-packages\django\db\models\fields\__init__.py", line 785, in get_db_prep_value
    value = self.get_prep_value(value)
  File "C:\Python3129\mecheck\lib\site-packages\django\db\models\fields\__init__.py", line 1737, in get_prep_value
    return float(value)
ValueError: could not convert string to float: 'null'
[2025-10-14 08:32:08,188] [runserver.py:154] [runserver:log_action] [ERROR]- HTTP POST /MiscellaneousPurchases/ReceiptAmount/ 500 [2.19, 127.0.0.1:54766]
[2025-10-14 09:31:24,892] [log.py:228] [log:log_response] [ERROR]- Internal Server Error: /AutoResult/AutoItem_edit/
Traceback (most recent call last):
  File "C:\Python3129\mecheck\lib\site-packages\django\core\handlers\exception.py", line 34, in inner
    response = get_response(request)
  File "C:\Python3129\mecheck\lib\site-packages\django\core\handlers\base.py", line 126, in _get_response
    response = self.process_exception_by_middleware(e, request)
  File "C:\Python3129\mecheck\lib\site-packages\django\core\handlers\base.py", line 124, in _get_response
    response = wrapped_callback(request, *callback_args, **callback_kwargs)
  File "C:\Python3129\mecheck\lib\site-packages\django\views\decorators\csrf.py", line 54, in wrapped_view
    return view_func(*args, **kwargs)
  File "C:\djangoproject\Reliability_Row_data\AutoResult\views.py", line 421, in AutoItem_edit
    return HttpResponse(json.dumps(data), content_type="application/json")
  File "C:\Python372\lib\json\__init__.py", line 231, in dumps
    return _default_encoder.encode(obj)
  File "C:\Python372\lib\json\encoder.py", line 199, in encode
    chunks = self.iterencode(o, _one_shot=True)
  File "C:\Python372\lib\json\encoder.py", line 257, in iterencode
    return _iterencode(o, 0)
  File "C:\Python372\lib\json\encoder.py", line 179, in default
    raise TypeError(f'Object of type {o.__class__.__name__} '
TypeError: Object of type date is not JSON serializable
[2025-10-14 09:31:24,998] [runserver.py:154] [runserver:log_action] [ERROR]- HTTP POST /AutoResult/AutoItem_edit/ 500 [4.57, 127.0.0.1:65063]
