[2025-07-11 12:39:50,945] [log.py:228] [log:log_response] [ERROR]- Internal Server Error: /CommonFiles/CommonFiles_edit/
Traceback (most recent call last):
  File "C:\Python3129\mecheck\lib\site-packages\django\core\handlers\exception.py", line 34, in inner
    response = get_response(request)
  File "C:\Python3129\mecheck\lib\site-packages\django\core\handlers\base.py", line 126, in _get_response
    response = self.process_exception_by_middleware(e, request)
  File "C:\Python3129\mecheck\lib\site-packages\django\core\handlers\base.py", line 124, in _get_response
    response = wrapped_callback(request, *callback_args, **callback_kwargs)
  File "C:\Python3129\mecheck\lib\site-packages\django\views\decorators\csrf.py", line 54, in wrapped_view
    return view_func(*args, **kwargs)
  File "C:\djangoproject\Reliability_Row_data\CommonFiles\views.py", line 505, in CommonFiles_edit
    return HttpResponse(json.dumps(data), content_type="application/json")
  File "C:\Python372\lib\json\__init__.py", line 231, in dumps
    return _default_encoder.encode(obj)
  File "C:\Python372\lib\json\encoder.py", line 199, in encode
    chunks = self.iterencode(o, _one_shot=True)
  File "C:\Python372\lib\json\encoder.py", line 257, in iterencode
    return _iterencode(o, 0)
  File "C:\Python372\lib\json\encoder.py", line 179, in default
    raise TypeError(f'Object of type {o.__class__.__name__} '
TypeError: Object of type ManyRelatedManager is not JSON serializable
[2025-07-11 12:39:50,950] [runserver.py:154] [runserver:log_action] [ERROR]- HTTP POST /CommonFiles/CommonFiles_edit/ 500 [0.35, 127.0.0.1:50010]
[2025-07-11 15:39:36,820] [log.py:228] [log:log_response] [ERROR]- Internal Server Error: /CommonFiles/CommonFiles_edit/
Traceback (most recent call last):
  File "C:\Python3129\mecheck\lib\site-packages\django\core\handlers\exception.py", line 34, in inner
    response = get_response(request)
  File "C:\Python3129\mecheck\lib\site-packages\django\core\handlers\base.py", line 126, in _get_response
    response = self.process_exception_by_middleware(e, request)
  File "C:\Python3129\mecheck\lib\site-packages\django\core\handlers\base.py", line 124, in _get_response
    response = wrapped_callback(request, *callback_args, **callback_kwargs)
  File "C:\Python3129\mecheck\lib\site-packages\django\views\decorators\csrf.py", line 54, in wrapped_view
    return view_func(*args, **kwargs)
  File "C:\djangoproject\Reliability_Row_data\CommonFiles\views.py", line 401, in CommonFiles_edit
    CommonFiles_object.Category_L2 = SubCategory.objects.get(id=request.POST.get('Category_L2'))
  File "C:\Python3129\mecheck\lib\site-packages\django\db\models\manager.py", line 82, in manager_method
    return getattr(self.get_queryset(), name)(*args, **kwargs)
  File "C:\Python3129\mecheck\lib\site-packages\django\db\models\query.py", line 390, in get
    clone = self.filter(*args, **kwargs)
  File "C:\Python3129\mecheck\lib\site-packages\django\db\models\query.py", line 844, in filter
    return self._filter_or_exclude(False, *args, **kwargs)
  File "C:\Python3129\mecheck\lib\site-packages\django\db\models\query.py", line 862, in _filter_or_exclude
    clone.query.add_q(Q(*args, **kwargs))
  File "C:\Python3129\mecheck\lib\site-packages\django\db\models\sql\query.py", line 1263, in add_q
    clause, _ = self._add_q(q_object, self.used_aliases)
  File "C:\Python3129\mecheck\lib\site-packages\django\db\models\sql\query.py", line 1287, in _add_q
    split_subq=split_subq,
  File "C:\Python3129\mecheck\lib\site-packages\django\db\models\sql\query.py", line 1225, in build_filter
    condition = self.build_lookup(lookups, col, value)
  File "C:\Python3129\mecheck\lib\site-packages\django\db\models\sql\query.py", line 1096, in build_lookup
    lookup = lookup_class(lhs, rhs)
  File "C:\Python3129\mecheck\lib\site-packages\django\db\models\lookups.py", line 20, in __init__
    self.rhs = self.get_prep_lookup()
  File "C:\Python3129\mecheck\lib\site-packages\django\db\models\lookups.py", line 70, in get_prep_lookup
    return self.lhs.output_field.get_prep_value(self.rhs)
  File "C:\Python3129\mecheck\lib\site-packages\django\db\models\fields\__init__.py", line 965, in get_prep_value
    return int(value)
ValueError: invalid literal for int() with base 10: ''
[2025-07-11 15:39:36,873] [runserver.py:154] [runserver:log_action] [ERROR]- HTTP POST /CommonFiles/CommonFiles_edit/ 500 [0.71, 127.0.0.1:62551]
[2025-07-11 16:07:26,222] [log.py:228] [log:log_response] [ERROR]- Internal Server Error: /CommonFiles/CommonFiles_edit/
Traceback (most recent call last):
  File "C:\Python3129\mecheck\lib\site-packages\django\core\handlers\exception.py", line 34, in inner
    response = get_response(request)
  File "C:\Python3129\mecheck\lib\site-packages\django\core\handlers\base.py", line 126, in _get_response
    response = self.process_exception_by_middleware(e, request)
  File "C:\Python3129\mecheck\lib\site-packages\django\core\handlers\base.py", line 124, in _get_response
    response = wrapped_callback(request, *callback_args, **callback_kwargs)
  File "C:\Python3129\mecheck\lib\site-packages\django\views\decorators\csrf.py", line 54, in wrapped_view
    return view_func(*args, **kwargs)
  File "C:\djangoproject\Reliability_Row_data\CommonFiles\views.py", line 401, in CommonFiles_edit
    CommonFiles_object.Category_L2 = SubCategory.objects.get(id=request.POST.get('Category_L2'))
  File "C:\Python3129\mecheck\lib\site-packages\django\db\models\manager.py", line 82, in manager_method
    return getattr(self.get_queryset(), name)(*args, **kwargs)
  File "C:\Python3129\mecheck\lib\site-packages\django\db\models\query.py", line 390, in get
    clone = self.filter(*args, **kwargs)
  File "C:\Python3129\mecheck\lib\site-packages\django\db\models\query.py", line 844, in filter
    return self._filter_or_exclude(False, *args, **kwargs)
  File "C:\Python3129\mecheck\lib\site-packages\django\db\models\query.py", line 862, in _filter_or_exclude
    clone.query.add_q(Q(*args, **kwargs))
  File "C:\Python3129\mecheck\lib\site-packages\django\db\models\sql\query.py", line 1263, in add_q
    clause, _ = self._add_q(q_object, self.used_aliases)
  File "C:\Python3129\mecheck\lib\site-packages\django\db\models\sql\query.py", line 1287, in _add_q
    split_subq=split_subq,
  File "C:\Python3129\mecheck\lib\site-packages\django\db\models\sql\query.py", line 1225, in build_filter
    condition = self.build_lookup(lookups, col, value)
  File "C:\Python3129\mecheck\lib\site-packages\django\db\models\sql\query.py", line 1096, in build_lookup
    lookup = lookup_class(lhs, rhs)
  File "C:\Python3129\mecheck\lib\site-packages\django\db\models\lookups.py", line 20, in __init__
    self.rhs = self.get_prep_lookup()
  File "C:\Python3129\mecheck\lib\site-packages\django\db\models\lookups.py", line 70, in get_prep_lookup
    return self.lhs.output_field.get_prep_value(self.rhs)
  File "C:\Python3129\mecheck\lib\site-packages\django\db\models\fields\__init__.py", line 965, in get_prep_value
    return int(value)
ValueError: invalid literal for int() with base 10: ''
[2025-07-11 16:07:26,235] [runserver.py:154] [runserver:log_action] [ERROR]- HTTP POST /CommonFiles/CommonFiles_edit/ 500 [0.63, 127.0.0.1:64423]
[2025-07-11 16:07:44,167] [log.py:228] [log:log_response] [ERROR]- Internal Server Error: /CommonFiles/CommonFiles_edit/
Traceback (most recent call last):
  File "C:\Python3129\mecheck\lib\site-packages\django\core\handlers\exception.py", line 34, in inner
    response = get_response(request)
  File "C:\Python3129\mecheck\lib\site-packages\django\core\handlers\base.py", line 126, in _get_response
    response = self.process_exception_by_middleware(e, request)
  File "C:\Python3129\mecheck\lib\site-packages\django\core\handlers\base.py", line 124, in _get_response
    response = wrapped_callback(request, *callback_args, **callback_kwargs)
  File "C:\Python3129\mecheck\lib\site-packages\django\views\decorators\csrf.py", line 54, in wrapped_view
    return view_func(*args, **kwargs)
  File "C:\djangoproject\Reliability_Row_data\CommonFiles\views.py", line 401, in CommonFiles_edit
    CommonFiles_object.Category_L2 = SubCategory.objects.get(id=request.POST.get('Category_L2'))
  File "C:\Python3129\mecheck\lib\site-packages\django\db\models\manager.py", line 82, in manager_method
    return getattr(self.get_queryset(), name)(*args, **kwargs)
  File "C:\Python3129\mecheck\lib\site-packages\django\db\models\query.py", line 390, in get
    clone = self.filter(*args, **kwargs)
  File "C:\Python3129\mecheck\lib\site-packages\django\db\models\query.py", line 844, in filter
    return self._filter_or_exclude(False, *args, **kwargs)
  File "C:\Python3129\mecheck\lib\site-packages\django\db\models\query.py", line 862, in _filter_or_exclude
    clone.query.add_q(Q(*args, **kwargs))
  File "C:\Python3129\mecheck\lib\site-packages\django\db\models\sql\query.py", line 1263, in add_q
    clause, _ = self._add_q(q_object, self.used_aliases)
  File "C:\Python3129\mecheck\lib\site-packages\django\db\models\sql\query.py", line 1287, in _add_q
    split_subq=split_subq,
  File "C:\Python3129\mecheck\lib\site-packages\django\db\models\sql\query.py", line 1225, in build_filter
    condition = self.build_lookup(lookups, col, value)
  File "C:\Python3129\mecheck\lib\site-packages\django\db\models\sql\query.py", line 1096, in build_lookup
    lookup = lookup_class(lhs, rhs)
  File "C:\Python3129\mecheck\lib\site-packages\django\db\models\lookups.py", line 20, in __init__
    self.rhs = self.get_prep_lookup()
  File "C:\Python3129\mecheck\lib\site-packages\django\db\models\lookups.py", line 70, in get_prep_lookup
    return self.lhs.output_field.get_prep_value(self.rhs)
  File "C:\Python3129\mecheck\lib\site-packages\django\db\models\fields\__init__.py", line 965, in get_prep_value
    return int(value)
ValueError: invalid literal for int() with base 10: ''
[2025-07-11 16:07:44,173] [runserver.py:154] [runserver:log_action] [ERROR]- HTTP POST /CommonFiles/CommonFiles_edit/ 500 [0.26, 127.0.0.1:64436]
[2025-07-11 16:11:26,313] [log.py:228] [log:log_response] [ERROR]- Internal Server Error: /CommonFiles/CommonFiles_edit/
Traceback (most recent call last):
  File "C:\Python3129\mecheck\lib\site-packages\django\core\handlers\exception.py", line 34, in inner
    response = get_response(request)
  File "C:\Python3129\mecheck\lib\site-packages\django\core\handlers\base.py", line 126, in _get_response
    response = self.process_exception_by_middleware(e, request)
  File "C:\Python3129\mecheck\lib\site-packages\django\core\handlers\base.py", line 124, in _get_response
    response = wrapped_callback(request, *callback_args, **callback_kwargs)
  File "C:\Python3129\mecheck\lib\site-packages\django\views\decorators\csrf.py", line 54, in wrapped_view
    return view_func(*args, **kwargs)
  File "C:\djangoproject\Reliability_Row_data\CommonFiles\views.py", line 490, in CommonFiles_edit
    "Category_L2": SubCategory.objects.filter(name=i.Category_L2).first().id,
AttributeError: 'NoneType' object has no attribute 'id'
[2025-07-11 16:11:26,321] [runserver.py:154] [runserver:log_action] [ERROR]- HTTP POST /CommonFiles/CommonFiles_edit/ 500 [0.64, 127.0.0.1:64794]
[2025-07-11 16:12:55,254] [log.py:228] [log:log_response] [ERROR]- Internal Server Error: /CommonFiles/CommonFiles_edit/
Traceback (most recent call last):
  File "C:\Python3129\mecheck\lib\site-packages\django\core\handlers\exception.py", line 34, in inner
    response = get_response(request)
  File "C:\Python3129\mecheck\lib\site-packages\django\core\handlers\base.py", line 126, in _get_response
    response = self.process_exception_by_middleware(e, request)
  File "C:\Python3129\mecheck\lib\site-packages\django\core\handlers\base.py", line 124, in _get_response
    response = wrapped_callback(request, *callback_args, **callback_kwargs)
  File "C:\Python3129\mecheck\lib\site-packages\django\views\decorators\csrf.py", line 54, in wrapped_view
    return view_func(*args, **kwargs)
  File "C:\djangoproject\Reliability_Row_data\CommonFiles\views.py", line 491, in CommonFiles_edit
    "Category_L2": SubCategory.objects.filter(name=i.Category_L2).first().id,
AttributeError: 'NoneType' object has no attribute 'id'
[2025-07-11 16:12:55,258] [runserver.py:154] [runserver:log_action] [ERROR]- HTTP POST /CommonFiles/CommonFiles_edit/ 500 [0.16, 127.0.0.1:64892]
[2025-07-11 16:12:59,968] [log.py:228] [log:log_response] [ERROR]- Internal Server Error: /CommonFiles/CommonFiles_edit/
Traceback (most recent call last):
  File "C:\Python3129\mecheck\lib\site-packages\django\core\handlers\exception.py", line 34, in inner
    response = get_response(request)
  File "C:\Python3129\mecheck\lib\site-packages\django\core\handlers\base.py", line 126, in _get_response
    response = self.process_exception_by_middleware(e, request)
  File "C:\Python3129\mecheck\lib\site-packages\django\core\handlers\base.py", line 124, in _get_response
    response = wrapped_callback(request, *callback_args, **callback_kwargs)
  File "C:\Python3129\mecheck\lib\site-packages\django\views\decorators\csrf.py", line 54, in wrapped_view
    return view_func(*args, **kwargs)
  File "C:\djangoproject\Reliability_Row_data\CommonFiles\views.py", line 491, in CommonFiles_edit
    "Category_L2": SubCategory.objects.filter(name=i.Category_L2).first().id,
AttributeError: 'NoneType' object has no attribute 'id'
[2025-07-11 16:12:59,974] [runserver.py:154] [runserver:log_action] [ERROR]- HTTP POST /CommonFiles/CommonFiles_edit/ 500 [0.23, 127.0.0.1:64892]
[2025-07-11 16:13:30,974] [log.py:228] [log:log_response] [ERROR]- Internal Server Error: /CommonFiles/CommonFiles_edit/
Traceback (most recent call last):
  File "C:\Python3129\mecheck\lib\site-packages\django\core\handlers\exception.py", line 34, in inner
    response = get_response(request)
  File "C:\Python3129\mecheck\lib\site-packages\django\core\handlers\base.py", line 126, in _get_response
    response = self.process_exception_by_middleware(e, request)
  File "C:\Python3129\mecheck\lib\site-packages\django\core\handlers\base.py", line 124, in _get_response
    response = wrapped_callback(request, *callback_args, **callback_kwargs)
  File "C:\Python3129\mecheck\lib\site-packages\django\views\decorators\csrf.py", line 54, in wrapped_view
    return view_func(*args, **kwargs)
  File "C:\djangoproject\Reliability_Row_data\CommonFiles\views.py", line 491, in CommonFiles_edit
    "Category_L2": SubCategory.objects.filter(name=i.Category_L2).first().id,
AttributeError: 'NoneType' object has no attribute 'id'
[2025-07-11 16:13:30,977] [runserver.py:154] [runserver:log_action] [ERROR]- HTTP POST /CommonFiles/CommonFiles_edit/ 500 [0.17, 127.0.0.1:64962]
