[2024-10-09 09:24:17,319] [runserver.py:154] [runserver:log_action] [ERROR]- HTTP POST /Navigations_Category/ 500 [0.59, 127.0.0.1:55693]
[2024-10-09 09:24:24,388] [runserver.py:154] [runserver:log_action] [ERROR]- HTTP POST /Navigations_Category/ 500 [0.14, 127.0.0.1:55693]
[2024-10-09 10:29:44,627] [runserver.py:154] [runserver:log_action] [ERROR]- HTTP POST /Navigations_Category/ 500 [0.64, 127.0.0.1:63534]
[2024-10-09 10:29:51,686] [runserver.py:154] [runserver:log_action] [ERROR]- HTTP POST /Navigations_Category/ 500 [0.56, 127.0.0.1:63534]
[2024-10-09 10:29:54,714] [runserver.py:154] [runserver:log_action] [ERROR]- HTTP POST /Navigations_Category/ 500 [0.28, 127.0.0.1:63534]
[2024-10-09 11:16:41,652] [runserver.py:154] [runserver:log_action] [ERROR]- HTTP POST /Navigations_Category/ 500 [0.48, 127.0.0.1:58202]
[2024-10-09 11:16:43,151] [log.py:228] [log:log_response] [ERROR]- Internal Server Error: /Navigations_system/
Traceback (most recent call last):
  File "C:\Python372\mecheck\lib\site-packages\django\core\handlers\exception.py", line 34, in inner
    response = get_response(request)
  File "C:\Python372\mecheck\lib\site-packages\django\core\handlers\base.py", line 126, in _get_response
    response = self.process_exception_by_middleware(e, request)
  File "C:\Python372\mecheck\lib\site-packages\django\core\handlers\base.py", line 124, in _get_response
    response = wrapped_callback(request, *callback_args, **callback_kwargs)
  File "C:\Python372\mecheck\lib\site-packages\django\views\decorators\csrf.py", line 54, in wrapped_view
    return view_func(*args, **kwargs)
  File "C:\djangoproject\Reliability_Row_data\app01\views.py", line 2535, in Navigations_system_axios
    gridData = All_system_dic[Sysname]
KeyError: 'ProjectComparison'
[2024-10-09 11:16:43,163] [runserver.py:154] [runserver:log_action] [ERROR]- HTTP POST /Navigations_system/ 500 [0.86, 127.0.0.1:58202]
[2024-10-09 11:16:46,704] [runserver.py:154] [runserver:log_action] [ERROR]- HTTP POST /Navigations_Category/ 500 [0.35, 127.0.0.1:58203]
[2024-10-09 11:16:49,729] [runserver.py:154] [runserver:log_action] [ERROR]- HTTP POST /Navigations_Category/ 500 [1.04, 127.0.0.1:58203]
[2024-10-09 11:16:52,020] [log.py:228] [log:log_response] [ERROR]- Internal Server Error: /Navigations_system/
Traceback (most recent call last):
  File "C:\Python372\mecheck\lib\site-packages\django\core\handlers\exception.py", line 34, in inner
    response = get_response(request)
  File "C:\Python372\mecheck\lib\site-packages\django\core\handlers\base.py", line 126, in _get_response
    response = self.process_exception_by_middleware(e, request)
  File "C:\Python372\mecheck\lib\site-packages\django\core\handlers\base.py", line 124, in _get_response
    response = wrapped_callback(request, *callback_args, **callback_kwargs)
  File "C:\Python372\mecheck\lib\site-packages\django\views\decorators\csrf.py", line 54, in wrapped_view
    return view_func(*args, **kwargs)
  File "C:\djangoproject\Reliability_Row_data\app01\views.py", line 2535, in Navigations_system_axios
    gridData = All_system_dic[Sysname]
KeyError: 'CapitalExpenditure'
[2024-10-09 11:16:52,028] [runserver.py:154] [runserver:log_action] [ERROR]- HTTP POST /Navigations_system/ 500 [0.11, 127.0.0.1:58203]
[2024-10-09 11:16:55,870] [log.py:228] [log:log_response] [ERROR]- Internal Server Error: /Navigations_system/
Traceback (most recent call last):
  File "C:\Python372\mecheck\lib\site-packages\django\core\handlers\exception.py", line 34, in inner
    response = get_response(request)
  File "C:\Python372\mecheck\lib\site-packages\django\core\handlers\base.py", line 126, in _get_response
    response = self.process_exception_by_middleware(e, request)
  File "C:\Python372\mecheck\lib\site-packages\django\core\handlers\base.py", line 124, in _get_response
    response = wrapped_callback(request, *callback_args, **callback_kwargs)
  File "C:\Python372\mecheck\lib\site-packages\django\views\decorators\csrf.py", line 54, in wrapped_view
    return view_func(*args, **kwargs)
  File "C:\djangoproject\Reliability_Row_data\app01\views.py", line 2535, in Navigations_system_axios
    gridData = All_system_dic[Sysname]
KeyError: 'Public Area'
[2024-10-09 11:16:55,879] [runserver.py:154] [runserver:log_action] [ERROR]- HTTP POST /Navigations_system/ 500 [0.11, 127.0.0.1:58203]
[2024-10-09 11:16:57,798] [runserver.py:154] [runserver:log_action] [ERROR]- HTTP POST /Navigations_Category/ 500 [0.26, 127.0.0.1:58260]
[2024-10-09 11:17:02,827] [runserver.py:154] [runserver:log_action] [ERROR]- HTTP POST /Navigations_Category/ 500 [0.77, 127.0.0.1:58260]
[2024-10-09 11:17:06,858] [runserver.py:154] [runserver:log_action] [ERROR]- HTTP POST /Navigations_Category/ 500 [0.68, 127.0.0.1:58260]
[2024-10-09 11:17:08,879] [runserver.py:154] [runserver:log_action] [ERROR]- HTTP POST /Navigations_Category/ 500 [0.16, 127.0.0.1:58260]
[2024-10-09 11:17:10,905] [runserver.py:154] [runserver:log_action] [ERROR]- HTTP POST /Navigations_Category/ 500 [0.12, 127.0.0.1:58260]
[2024-10-09 11:17:13,936] [runserver.py:154] [runserver:log_action] [ERROR]- HTTP POST /Navigations_Category/ 500 [0.49, 127.0.0.1:58260]
[2024-10-09 11:17:28,078] [runserver.py:154] [runserver:log_action] [ERROR]- HTTP POST /Navigations_Category/ 500 [0.49, 127.0.0.1:58260]
[2024-10-09 11:17:30,101] [runserver.py:154] [runserver:log_action] [ERROR]- HTTP POST /Navigations_Category/ 500 [0.59, 127.0.0.1:58260]
[2024-10-09 11:17:48,313] [runserver.py:154] [runserver:log_action] [ERROR]- HTTP POST /Navigations_Category/ 500 [0.95, 127.0.0.1:58260]
[2024-10-09 11:18:00,422] [runserver.py:154] [runserver:log_action] [ERROR]- HTTP POST /Navigations_Category/ 500 [0.65, 127.0.0.1:58389]
[2024-10-09 16:02:49,639] [log.py:228] [log:log_response] [ERROR]- Internal Server Error: /Navigations_Category/
Traceback (most recent call last):
  File "C:\Python372\mecheck\lib\site-packages\django\core\handlers\exception.py", line 34, in inner
    response = get_response(request)
  File "C:\Python372\mecheck\lib\site-packages\django\core\handlers\base.py", line 126, in _get_response
    response = self.process_exception_by_middleware(e, request)
  File "C:\Python372\mecheck\lib\site-packages\django\core\handlers\base.py", line 124, in _get_response
    response = wrapped_callback(request, *callback_args, **callback_kwargs)
  File "C:\Python372\mecheck\lib\site-packages\django\views\decorators\csrf.py", line 54, in wrapped_view
    return view_func(*args, **kwargs)
  File "C:\djangoproject\Reliability_Row_data\app01\views.py", line 1073, in Navigations_Category_axios
    gridData_Category = All_system_dic[Navigations_Category_name]
KeyError: 'å°\x88æ¡\x88ç®¡ç\x90\x86'
[2024-10-09 16:02:49,653] [runserver.py:154] [runserver:log_action] [ERROR]- HTTP POST /Navigations_Category/ 500 [0.82, 127.0.0.1:62773]
[2024-10-09 16:02:54,375] [log.py:228] [log:log_response] [ERROR]- Internal Server Error: /Navigations_system/
Traceback (most recent call last):
  File "C:\Python372\mecheck\lib\site-packages\django\core\handlers\exception.py", line 34, in inner
    response = get_response(request)
  File "C:\Python372\mecheck\lib\site-packages\django\core\handlers\base.py", line 126, in _get_response
    response = self.process_exception_by_middleware(e, request)
  File "C:\Python372\mecheck\lib\site-packages\django\core\handlers\base.py", line 124, in _get_response
    response = wrapped_callback(request, *callback_args, **callback_kwargs)
  File "C:\Python372\mecheck\lib\site-packages\django\views\decorators\csrf.py", line 54, in wrapped_view
    return view_func(*args, **kwargs)
  File "C:\djangoproject\Reliability_Row_data\app01\views.py", line 2535, in Navigations_system_axios
    gridData = All_system_dic[Sysname]
KeyError: 'CapitalExpenditure'
[2024-10-09 16:02:54,381] [runserver.py:154] [runserver:log_action] [ERROR]- HTTP POST /Navigations_system/ 500 [0.11, 127.0.0.1:62772]
[2024-10-09 16:02:59,776] [log.py:228] [log:log_response] [ERROR]- Internal Server Error: /Navigations_Category/
Traceback (most recent call last):
  File "C:\Python372\mecheck\lib\site-packages\django\core\handlers\exception.py", line 34, in inner
    response = get_response(request)
  File "C:\Python372\mecheck\lib\site-packages\django\core\handlers\base.py", line 126, in _get_response
    response = self.process_exception_by_middleware(e, request)
  File "C:\Python372\mecheck\lib\site-packages\django\core\handlers\base.py", line 124, in _get_response
    response = wrapped_callback(request, *callback_args, **callback_kwargs)
  File "C:\Python372\mecheck\lib\site-packages\django\views\decorators\csrf.py", line 54, in wrapped_view
    return view_func(*args, **kwargs)
  File "C:\djangoproject\Reliability_Row_data\app01\views.py", line 1073, in Navigations_Category_axios
    gridData_Category = All_system_dic[Navigations_Category_name]
KeyError: 'å°\x88æ¡\x88ç®¡ç\x90\x86'
[2024-10-09 16:02:59,784] [runserver.py:154] [runserver:log_action] [ERROR]- HTTP POST /Navigations_Category/ 500 [0.08, 127.0.0.1:62773]
[2024-10-09 16:03:00,995] [log.py:228] [log:log_response] [ERROR]- Internal Server Error: /Navigations_system/
Traceback (most recent call last):
  File "C:\Python372\mecheck\lib\site-packages\django\core\handlers\exception.py", line 34, in inner
    response = get_response(request)
  File "C:\Python372\mecheck\lib\site-packages\django\core\handlers\base.py", line 126, in _get_response
    response = self.process_exception_by_middleware(e, request)
  File "C:\Python372\mecheck\lib\site-packages\django\core\handlers\base.py", line 124, in _get_response
    response = wrapped_callback(request, *callback_args, **callback_kwargs)
  File "C:\Python372\mecheck\lib\site-packages\django\views\decorators\csrf.py", line 54, in wrapped_view
    return view_func(*args, **kwargs)
  File "C:\djangoproject\Reliability_Row_data\app01\views.py", line 2535, in Navigations_system_axios
    gridData = All_system_dic[Sysname]
KeyError: 'ProjectComparison'
[2024-10-09 16:03:01,001] [runserver.py:154] [runserver:log_action] [ERROR]- HTTP POST /Navigations_system/ 500 [0.11, 127.0.0.1:62772]
[2024-10-09 16:05:13,052] [log.py:228] [log:log_response] [ERROR]- Internal Server Error: /Navigations_Category/
Traceback (most recent call last):
  File "C:\Python372\mecheck\lib\site-packages\django\core\handlers\exception.py", line 34, in inner
    response = get_response(request)
  File "C:\Python372\mecheck\lib\site-packages\django\core\handlers\base.py", line 126, in _get_response
    response = self.process_exception_by_middleware(e, request)
  File "C:\Python372\mecheck\lib\site-packages\django\core\handlers\base.py", line 124, in _get_response
    response = wrapped_callback(request, *callback_args, **callback_kwargs)
  File "C:\Python372\mecheck\lib\site-packages\django\views\decorators\csrf.py", line 54, in wrapped_view
    return view_func(*args, **kwargs)
  File "C:\djangoproject\Reliability_Row_data\app01\views.py", line 1073, in Navigations_Category_axios
    gridData_Category = All_system_dic[Navigations_Category_name]
KeyError: 'å°\x88æ¡\x88ç®¡ç\x90\x86'
[2024-10-09 16:05:13,059] [runserver.py:154] [runserver:log_action] [ERROR]- HTTP POST /Navigations_Category/ 500 [0.09, 127.0.0.1:60628]
[2024-10-09 16:05:34,653] [log.py:228] [log:log_response] [ERROR]- Internal Server Error: /Navigations_Category/
Traceback (most recent call last):
  File "C:\Python372\mecheck\lib\site-packages\django\core\handlers\exception.py", line 34, in inner
    response = get_response(request)
  File "C:\Python372\mecheck\lib\site-packages\django\core\handlers\base.py", line 126, in _get_response
    response = self.process_exception_by_middleware(e, request)
  File "C:\Python372\mecheck\lib\site-packages\django\core\handlers\base.py", line 124, in _get_response
    response = wrapped_callback(request, *callback_args, **callback_kwargs)
  File "C:\Python372\mecheck\lib\site-packages\django\views\decorators\csrf.py", line 54, in wrapped_view
    return view_func(*args, **kwargs)
  File "C:\djangoproject\Reliability_Row_data\app01\views.py", line 1073, in Navigations_Category_axios
    gridData_Category = All_system_dic[Navigations_Category_name]
KeyError: 'å°\x88æ¡\x88ç®¡ç\x90\x86'
[2024-10-09 16:05:34,659] [runserver.py:154] [runserver:log_action] [ERROR]- HTTP POST /Navigations_Category/ 500 [0.09, 127.0.0.1:60628]
[2024-10-09 16:07:41,451] [log.py:228] [log:log_response] [ERROR]- Internal Server Error: /Navigations_Category/
Traceback (most recent call last):
  File "C:\Python372\mecheck\lib\site-packages\django\core\handlers\exception.py", line 34, in inner
    response = get_response(request)
  File "C:\Python372\mecheck\lib\site-packages\django\core\handlers\base.py", line 126, in _get_response
    response = self.process_exception_by_middleware(e, request)
  File "C:\Python372\mecheck\lib\site-packages\django\core\handlers\base.py", line 124, in _get_response
    response = wrapped_callback(request, *callback_args, **callback_kwargs)
  File "C:\Python372\mecheck\lib\site-packages\django\views\decorators\csrf.py", line 54, in wrapped_view
    return view_func(*args, **kwargs)
  File "C:\djangoproject\Reliability_Row_data\app01\views.py", line 1073, in Navigations_Category_axios
    gridData_Category = All_system_dic[Navigations_Category_name]
KeyError: 'å°\x88æ¡\x88ç®¡ç\x90\x86'
[2024-10-09 16:07:41,458] [runserver.py:154] [runserver:log_action] [ERROR]- HTTP POST /Navigations_Category/ 500 [0.06, 127.0.0.1:53620]
[2024-10-09 16:08:11,196] [log.py:228] [log:log_response] [ERROR]- Internal Server Error: /Navigations_Category/
Traceback (most recent call last):
  File "C:\Python372\mecheck\lib\site-packages\django\core\handlers\exception.py", line 34, in inner
    response = get_response(request)
  File "C:\Python372\mecheck\lib\site-packages\django\core\handlers\base.py", line 126, in _get_response
    response = self.process_exception_by_middleware(e, request)
  File "C:\Python372\mecheck\lib\site-packages\django\core\handlers\base.py", line 124, in _get_response
    response = wrapped_callback(request, *callback_args, **callback_kwargs)
  File "C:\Python372\mecheck\lib\site-packages\django\views\decorators\csrf.py", line 54, in wrapped_view
    return view_func(*args, **kwargs)
  File "C:\djangoproject\Reliability_Row_data\app01\views.py", line 1073, in Navigations_Category_axios
    gridData_Category = All_system_dic[Navigations_Category_name]
KeyError: 'å°\x88æ¡\x88ç®¡ç\x90\x86'
[2024-10-09 16:08:11,200] [runserver.py:154] [runserver:log_action] [ERROR]- HTTP POST /Navigations_Category/ 500 [0.07, 127.0.0.1:53621]
[2024-10-09 16:08:58,705] [log.py:228] [log:log_response] [ERROR]- Internal Server Error: /Navigations_system/
Traceback (most recent call last):
  File "C:\Python372\mecheck\lib\site-packages\django\core\handlers\exception.py", line 34, in inner
    response = get_response(request)
  File "C:\Python372\mecheck\lib\site-packages\django\core\handlers\base.py", line 126, in _get_response
    response = self.process_exception_by_middleware(e, request)
  File "C:\Python372\mecheck\lib\site-packages\django\core\handlers\base.py", line 124, in _get_response
    response = wrapped_callback(request, *callback_args, **callback_kwargs)
  File "C:\Python372\mecheck\lib\site-packages\django\views\decorators\csrf.py", line 54, in wrapped_view
    return view_func(*args, **kwargs)
  File "C:\djangoproject\Reliability_Row_data\app01\views.py", line 2535, in Navigations_system_axios
    gridData = All_system_dic[Sysname]
KeyError: 'ProjectInfo'
[2024-10-09 16:08:58,712] [runserver.py:154] [runserver:log_action] [ERROR]- HTTP POST /Navigations_system/ 500 [0.06, 127.0.0.1:53621]
[2024-10-09 16:09:02,756] [log.py:228] [log:log_response] [ERROR]- Internal Server Error: /Navigations_Category/
Traceback (most recent call last):
  File "C:\Python372\mecheck\lib\site-packages\django\core\handlers\exception.py", line 34, in inner
    response = get_response(request)
  File "C:\Python372\mecheck\lib\site-packages\django\core\handlers\base.py", line 126, in _get_response
    response = self.process_exception_by_middleware(e, request)
  File "C:\Python372\mecheck\lib\site-packages\django\core\handlers\base.py", line 124, in _get_response
    response = wrapped_callback(request, *callback_args, **callback_kwargs)
  File "C:\Python372\mecheck\lib\site-packages\django\views\decorators\csrf.py", line 54, in wrapped_view
    return view_func(*args, **kwargs)
  File "C:\djangoproject\Reliability_Row_data\app01\views.py", line 1073, in Navigations_Category_axios
    gridData_Category = All_system_dic[Navigations_Category_name]
KeyError: 'å°\x88æ¡\x88ç®¡ç\x90\x86'
[2024-10-09 16:09:02,763] [runserver.py:154] [runserver:log_action] [ERROR]- HTTP POST /Navigations_Category/ 500 [0.06, 127.0.0.1:53621]
[2024-10-09 16:09:08,680] [log.py:228] [log:log_response] [ERROR]- Internal Server Error: /Navigations_Category/
Traceback (most recent call last):
  File "C:\Python372\mecheck\lib\site-packages\django\core\handlers\exception.py", line 34, in inner
    response = get_response(request)
  File "C:\Python372\mecheck\lib\site-packages\django\core\handlers\base.py", line 126, in _get_response
    response = self.process_exception_by_middleware(e, request)
  File "C:\Python372\mecheck\lib\site-packages\django\core\handlers\base.py", line 124, in _get_response
    response = wrapped_callback(request, *callback_args, **callback_kwargs)
  File "C:\Python372\mecheck\lib\site-packages\django\views\decorators\csrf.py", line 54, in wrapped_view
    return view_func(*args, **kwargs)
  File "C:\djangoproject\Reliability_Row_data\app01\views.py", line 1073, in Navigations_Category_axios
    gridData_Category = All_system_dic[Navigations_Category_name]
KeyError: 'å°\x88æ¡\x88ç®¡ç\x90\x86'
[2024-10-09 16:09:08,688] [runserver.py:154] [runserver:log_action] [ERROR]- HTTP POST /Navigations_Category/ 500 [0.08, 127.0.0.1:53620]
[2024-10-09 16:11:50,810] [log.py:228] [log:log_response] [ERROR]- Internal Server Error: /Navigations_Category/
Traceback (most recent call last):
  File "C:\Python372\mecheck\lib\site-packages\django\core\handlers\exception.py", line 34, in inner
    response = get_response(request)
  File "C:\Python372\mecheck\lib\site-packages\django\core\handlers\base.py", line 126, in _get_response
    response = self.process_exception_by_middleware(e, request)
  File "C:\Python372\mecheck\lib\site-packages\django\core\handlers\base.py", line 124, in _get_response
    response = wrapped_callback(request, *callback_args, **callback_kwargs)
  File "C:\Python372\mecheck\lib\site-packages\django\views\decorators\csrf.py", line 54, in wrapped_view
    return view_func(*args, **kwargs)
  File "C:\djangoproject\Reliability_Row_data\app01\views.py", line 1073, in Navigations_Category_axios
    gridData_Category = All_system_dic[Navigations_Category_name]
KeyError: 'å°\x88æ¡\x88ç®¡ç\x90\x86'
[2024-10-09 16:11:50,813] [runserver.py:154] [runserver:log_action] [ERROR]- HTTP POST /Navigations_Category/ 500 [0.06, 127.0.0.1:53909]
[2024-10-09 16:12:46,386] [log.py:228] [log:log_response] [ERROR]- Internal Server Error: /Navigations_Category/
Traceback (most recent call last):
  File "C:\Python372\mecheck\lib\site-packages\django\core\handlers\exception.py", line 34, in inner
    response = get_response(request)
  File "C:\Python372\mecheck\lib\site-packages\django\core\handlers\base.py", line 126, in _get_response
    response = self.process_exception_by_middleware(e, request)
  File "C:\Python372\mecheck\lib\site-packages\django\core\handlers\base.py", line 124, in _get_response
    response = wrapped_callback(request, *callback_args, **callback_kwargs)
  File "C:\Python372\mecheck\lib\site-packages\django\views\decorators\csrf.py", line 54, in wrapped_view
    return view_func(*args, **kwargs)
  File "C:\djangoproject\Reliability_Row_data\app01\views.py", line 1073, in Navigations_Category_axios
    gridData_Category = All_system_dic[Navigations_Category_name]
KeyError: 'å°\x88æ¡\x88ç®¡ç\x90\x86'
[2024-10-09 16:12:46,394] [runserver.py:154] [runserver:log_action] [ERROR]- HTTP POST /Navigations_Category/ 500 [0.06, 127.0.0.1:53909]
[2024-10-09 16:16:02,296] [log.py:228] [log:log_response] [ERROR]- Internal Server Error: /Navigations_Category/
Traceback (most recent call last):
  File "C:\Python372\mecheck\lib\site-packages\django\core\handlers\exception.py", line 34, in inner
    response = get_response(request)
  File "C:\Python372\mecheck\lib\site-packages\django\core\handlers\base.py", line 126, in _get_response
    response = self.process_exception_by_middleware(e, request)
  File "C:\Python372\mecheck\lib\site-packages\django\core\handlers\base.py", line 124, in _get_response
    response = wrapped_callback(request, *callback_args, **callback_kwargs)
  File "C:\Python372\mecheck\lib\site-packages\django\views\decorators\csrf.py", line 54, in wrapped_view
    return view_func(*args, **kwargs)
  File "C:\djangoproject\Reliability_Row_data\app01\views.py", line 1073, in Navigations_Category_axios
    gridData_Category = All_system_dic[Navigations_Category_name]
KeyError: 'å°\x88æ¡\x88ç®¡ç\x90\x86'
[2024-10-09 16:16:02,306] [runserver.py:154] [runserver:log_action] [ERROR]- HTTP POST /Navigations_Category/ 500 [0.88, 127.0.0.1:51372]
[2024-10-09 16:18:00,050] [log.py:228] [log:log_response] [ERROR]- Internal Server Error: /Navigations_Category/
Traceback (most recent call last):
  File "C:\Python372\mecheck\lib\site-packages\django\core\handlers\exception.py", line 34, in inner
    response = get_response(request)
  File "C:\Python372\mecheck\lib\site-packages\django\core\handlers\base.py", line 126, in _get_response
    response = self.process_exception_by_middleware(e, request)
  File "C:\Python372\mecheck\lib\site-packages\django\core\handlers\base.py", line 124, in _get_response
    response = wrapped_callback(request, *callback_args, **callback_kwargs)
  File "C:\Python372\mecheck\lib\site-packages\django\views\decorators\csrf.py", line 54, in wrapped_view
    return view_func(*args, **kwargs)
  File "C:\djangoproject\Reliability_Row_data\app01\views.py", line 1071, in Navigations_Category_axios
    Navigations_Category_name = json.loads(request.COOKIES.get('Navigations_Category_name'))
  File "C:\Python372\lib\json\__init__.py", line 348, in loads
    return _default_decoder.decode(s)
  File "C:\Python372\lib\json\decoder.py", line 337, in decode
    obj, end = self.raw_decode(s, idx=_w(s, 0).end())
  File "C:\Python372\lib\json\decoder.py", line 355, in raw_decode
    raise JSONDecodeError("Expecting value", s, err.value) from None
json.decoder.JSONDecodeError: Expecting value: line 1 column 1 (char 0)
[2024-10-09 16:18:00,060] [runserver.py:154] [runserver:log_action] [ERROR]- HTTP POST /Navigations_Category/ 500 [0.47, 127.0.0.1:55411]
[2024-10-09 16:18:14,370] [log.py:228] [log:log_response] [ERROR]- Internal Server Error: /Navigations_Category/
Traceback (most recent call last):
  File "C:\Python372\mecheck\lib\site-packages\django\core\handlers\exception.py", line 34, in inner
    response = get_response(request)
  File "C:\Python372\mecheck\lib\site-packages\django\core\handlers\base.py", line 126, in _get_response
    response = self.process_exception_by_middleware(e, request)
  File "C:\Python372\mecheck\lib\site-packages\django\core\handlers\base.py", line 124, in _get_response
    response = wrapped_callback(request, *callback_args, **callback_kwargs)
  File "C:\Python372\mecheck\lib\site-packages\django\views\decorators\csrf.py", line 54, in wrapped_view
    return view_func(*args, **kwargs)
  File "C:\djangoproject\Reliability_Row_data\app01\views.py", line 1073, in Navigations_Category_axios
    gridData_Category = All_system_dic[Navigations_Category_name]
KeyError: 'å°\x88æ¡\x88ç®¡ç\x90\x86'
[2024-10-09 16:18:14,374] [runserver.py:154] [runserver:log_action] [ERROR]- HTTP POST /Navigations_Category/ 500 [0.04, 127.0.0.1:55411]
[2024-10-09 16:27:16,310] [log.py:228] [log:log_response] [ERROR]- Internal Server Error: /Navigations_Category/
Traceback (most recent call last):
  File "C:\Python372\mecheck\lib\site-packages\django\core\handlers\exception.py", line 34, in inner
    response = get_response(request)
  File "C:\Python372\mecheck\lib\site-packages\django\core\handlers\base.py", line 126, in _get_response
    response = self.process_exception_by_middleware(e, request)
  File "C:\Python372\mecheck\lib\site-packages\django\core\handlers\base.py", line 124, in _get_response
    response = wrapped_callback(request, *callback_args, **callback_kwargs)
  File "C:\Python372\mecheck\lib\site-packages\django\views\decorators\csrf.py", line 54, in wrapped_view
    return view_func(*args, **kwargs)
  File "C:\djangoproject\Reliability_Row_data\app01\views.py", line 1073, in Navigations_Category_axios
    gridData_Category = All_system_dic[Navigations_Category_name]
KeyError: 'å°\x88æ¡\x88ç®¡ç\x90\x86'
[2024-10-09 16:27:16,323] [runserver.py:154] [runserver:log_action] [ERROR]- HTTP POST /Navigations_Category/ 500 [0.77, 127.0.0.1:63674]
[2024-10-09 16:31:13,366] [log.py:228] [log:log_response] [ERROR]- Internal Server Error: /Navigations_Category/
Traceback (most recent call last):
  File "C:\Python372\mecheck\lib\site-packages\django\core\handlers\exception.py", line 34, in inner
    response = get_response(request)
  File "C:\Python372\mecheck\lib\site-packages\django\core\handlers\base.py", line 126, in _get_response
    response = self.process_exception_by_middleware(e, request)
  File "C:\Python372\mecheck\lib\site-packages\django\core\handlers\base.py", line 124, in _get_response
    response = wrapped_callback(request, *callback_args, **callback_kwargs)
  File "C:\Python372\mecheck\lib\site-packages\django\views\decorators\csrf.py", line 54, in wrapped_view
    return view_func(*args, **kwargs)
  File "C:\djangoproject\Reliability_Row_data\app01\views.py", line 1073, in Navigations_Category_axios
    gridData_Category = All_system_dic[Navigations_Category_name]
KeyError: 'å°\x88æ¡\x88ç®¡ç\x90\x86'
[2024-10-09 16:31:13,371] [runserver.py:154] [runserver:log_action] [ERROR]- HTTP POST /Navigations_Category/ 500 [0.25, 127.0.0.1:63785]
