[2025-07-21 08:57:09,931] [log.py:228] [log:log_response] [ERROR]- Internal Server Error: /CommonFiles/CommonFiles_edit/
Traceback (most recent call last):
  File "C:\Python3129\mecheck\lib\site-packages\django\core\handlers\exception.py", line 34, in inner
    response = get_response(request)
  File "C:\Python3129\mecheck\lib\site-packages\django\core\handlers\base.py", line 126, in _get_response
    response = self.process_exception_by_middleware(e, request)
  File "C:\Python3129\mecheck\lib\site-packages\django\core\handlers\base.py", line 124, in _get_response
    response = wrapped_callback(request, *callback_args, **callback_kwargs)
  File "C:\Python3129\mecheck\lib\site-packages\django\views\decorators\csrf.py", line 54, in wrapped_view
    return view_func(*args, **kwargs)
  File "C:\djangoproject\Reliability_Row_data\CommonFiles\views.py", line 351, in CommonFiles_edit
    mock_obj = CommonFiles.objects.filter(**check_dic).order_by('-created_at')
  File "C:\Python3129\mecheck\lib\site-packages\django\db\models\manager.py", line 82, in manager_method
    return getattr(self.get_queryset(), name)(*args, **kwargs)
  File "C:\Python3129\mecheck\lib\site-packages\django\db\models\query.py", line 844, in filter
    return self._filter_or_exclude(False, *args, **kwargs)
  File "C:\Python3129\mecheck\lib\site-packages\django\db\models\query.py", line 862, in _filter_or_exclude
    clone.query.add_q(Q(*args, **kwargs))
  File "C:\Python3129\mecheck\lib\site-packages\django\db\models\sql\query.py", line 1263, in add_q
    clause, _ = self._add_q(q_object, self.used_aliases)
  File "C:\Python3129\mecheck\lib\site-packages\django\db\models\sql\query.py", line 1287, in _add_q
    split_subq=split_subq,
  File "C:\Python3129\mecheck\lib\site-packages\django\db\models\sql\query.py", line 1164, in build_filter
    lookups, parts, reffed_expression = self.solve_lookup_type(arg)
  File "C:\Python3129\mecheck\lib\site-packages\django\db\models\sql\query.py", line 1028, in solve_lookup_type
    _, field, _, lookup_parts = self.names_to_path(lookup_splitted, self.get_meta())
  File "C:\Python3129\mecheck\lib\site-packages\django\db\models\sql\query.py", line 1389, in names_to_path
    "Choices are: %s" % (name, ", ".join(available)))
django.core.exceptions.FieldError: Cannot resolve keyword 'searchCG' into field. Choices are: Attachment, CG, Category_L1, Category_L1_id, Category_L2, Category_L2_id, Creator, Description, Item, Owner, SWHW, Version, created_at, id, updated_at
[2025-07-21 08:57:09,941] [runserver.py:154] [runserver:log_action] [ERROR]- HTTP POST /CommonFiles/CommonFiles_edit/ 500 [0.67, 127.0.0.1:52930]
[2025-07-21 09:07:50,302] [log.py:228] [log:log_response] [ERROR]- Internal Server Error: /CommonFiles/CommonFiles_edit/
Traceback (most recent call last):
  File "C:\Python3129\mecheck\lib\site-packages\django\core\handlers\exception.py", line 34, in inner
    response = get_response(request)
  File "C:\Python3129\mecheck\lib\site-packages\django\core\handlers\base.py", line 126, in _get_response
    response = self.process_exception_by_middleware(e, request)
  File "C:\Python3129\mecheck\lib\site-packages\django\core\handlers\base.py", line 124, in _get_response
    response = wrapped_callback(request, *callback_args, **callback_kwargs)
  File "C:\Python3129\mecheck\lib\site-packages\django\views\decorators\csrf.py", line 54, in wrapped_view
    return view_func(*args, **kwargs)
  File "C:\djangoproject\Reliability_Row_data\CommonFiles\views.py", line 435, in CommonFiles_edit
    files_to_delete = i.Attachment.all
AttributeError: 'int' object has no attribute 'Attachment'
[2025-07-21 09:07:50,310] [runserver.py:154] [runserver:log_action] [ERROR]- HTTP POST /CommonFiles/CommonFiles_edit/ 500 [0.21, 127.0.0.1:53828]
[2025-07-21 09:10:51,084] [log.py:228] [log:log_response] [ERROR]- Internal Server Error: /CommonFiles/CommonFiles_edit/
Traceback (most recent call last):
  File "C:\Python3129\mecheck\lib\site-packages\django\core\handlers\exception.py", line 34, in inner
    response = get_response(request)
  File "C:\Python3129\mecheck\lib\site-packages\django\core\handlers\base.py", line 126, in _get_response
    response = self.process_exception_by_middleware(e, request)
  File "C:\Python3129\mecheck\lib\site-packages\django\core\handlers\base.py", line 124, in _get_response
    response = wrapped_callback(request, *callback_args, **callback_kwargs)
  File "C:\Python3129\mecheck\lib\site-packages\django\views\decorators\csrf.py", line 54, in wrapped_view
    return view_func(*args, **kwargs)
  File "C:\djangoproject\Reliability_Row_data\CommonFiles\views.py", line 437, in CommonFiles_edit
    for j in CommonFiles.objects.get(id=i).Attachment.all:
TypeError: 'method' object is not iterable
[2025-07-21 09:10:51,109] [runserver.py:154] [runserver:log_action] [ERROR]- HTTP POST /CommonFiles/CommonFiles_edit/ 500 [0.60, 127.0.0.1:54042]
