[2025-02-18 14:08:29,220] [log.py:228] [log:log_response] [ERROR]- Internal Server Error: /Navigations_Category/Property/
Traceback (most recent call last):
  File "C:\Python372\mecheck\lib\site-packages\django\core\handlers\exception.py", line 34, in inner
    response = get_response(request)
  File "C:\Python372\mecheck\lib\site-packages\django\core\handlers\base.py", line 126, in _get_response
    response = self.process_exception_by_middleware(e, request)
  File "C:\Python372\mecheck\lib\site-packages\django\core\handlers\base.py", line 124, in _get_response
    response = wrapped_callback(request, *callback_args, **callback_kwargs)
  File "C:\Python372\mecheck\lib\site-packages\django\views\decorators\csrf.py", line 54, in wrapped_view
    return view_func(*args, **kwargs)
  File "C:\djangoproject\Reliability_Row_data\app01\views.py", line 697, in Navigations_Category
    print(Category)
OSError: [Errno 22] Invalid argument
[2025-02-18 14:08:29,229] [runserver.py:154] [runserver:log_action] [ERROR]- HTTP GET /Navigations_Category/Property/ 500 [0.63, 127.0.0.1:62003]
[2025-02-18 14:08:31,899] [log.py:228] [log:log_response] [ERROR]- Internal Server Error: /Navigations_Category/Property/
Traceback (most recent call last):
  File "C:\Python372\mecheck\lib\site-packages\django\core\handlers\exception.py", line 34, in inner
    response = get_response(request)
  File "C:\Python372\mecheck\lib\site-packages\django\core\handlers\base.py", line 126, in _get_response
    response = self.process_exception_by_middleware(e, request)
  File "C:\Python372\mecheck\lib\site-packages\django\core\handlers\base.py", line 124, in _get_response
    response = wrapped_callback(request, *callback_args, **callback_kwargs)
  File "C:\Python372\mecheck\lib\site-packages\django\views\decorators\csrf.py", line 54, in wrapped_view
    return view_func(*args, **kwargs)
  File "C:\djangoproject\Reliability_Row_data\app01\views.py", line 697, in Navigations_Category
    print(Category)
OSError: [Errno 22] Invalid argument
[2025-02-18 14:08:31,903] [runserver.py:154] [runserver:log_action] [ERROR]- HTTP GET /Navigations_Category/Property/ 500 [0.10, 127.0.0.1:62003]
[2025-02-18 14:08:37,478] [log.py:228] [log:log_response] [ERROR]- Internal Server Error: /Navigations_Category/Property/
Traceback (most recent call last):
  File "C:\Python372\mecheck\lib\site-packages\django\core\handlers\exception.py", line 34, in inner
    response = get_response(request)
  File "C:\Python372\mecheck\lib\site-packages\django\core\handlers\base.py", line 126, in _get_response
    response = self.process_exception_by_middleware(e, request)
  File "C:\Python372\mecheck\lib\site-packages\django\core\handlers\base.py", line 124, in _get_response
    response = wrapped_callback(request, *callback_args, **callback_kwargs)
  File "C:\Python372\mecheck\lib\site-packages\django\views\decorators\csrf.py", line 54, in wrapped_view
    return view_func(*args, **kwargs)
  File "C:\djangoproject\Reliability_Row_data\app01\views.py", line 697, in Navigations_Category
    print(Category)
OSError: [Errno 22] Invalid argument
[2025-02-18 14:08:37,485] [runserver.py:154] [runserver:log_action] [ERROR]- HTTP GET /Navigations_Category/Property/ 500 [0.09, 127.0.0.1:62004]
[2025-02-18 14:08:41,178] [log.py:228] [log:log_response] [ERROR]- Internal Server Error: /Navigations_Category/Budget/
Traceback (most recent call last):
  File "C:\Python372\mecheck\lib\site-packages\django\core\handlers\exception.py", line 34, in inner
    response = get_response(request)
  File "C:\Python372\mecheck\lib\site-packages\django\core\handlers\base.py", line 126, in _get_response
    response = self.process_exception_by_middleware(e, request)
  File "C:\Python372\mecheck\lib\site-packages\django\core\handlers\base.py", line 124, in _get_response
    response = wrapped_callback(request, *callback_args, **callback_kwargs)
  File "C:\Python372\mecheck\lib\site-packages\django\views\decorators\csrf.py", line 54, in wrapped_view
    return view_func(*args, **kwargs)
  File "C:\djangoproject\Reliability_Row_data\app01\views.py", line 697, in Navigations_Category
    print(Category)
OSError: [Errno 22] Invalid argument
[2025-02-18 14:08:41,183] [runserver.py:154] [runserver:log_action] [ERROR]- HTTP GET /Navigations_Category/Budget/ 500 [0.11, 127.0.0.1:62004]
[2025-02-18 14:08:54,001] [log.py:228] [log:log_response] [ERROR]- Internal Server Error: /Navigations_Category/Property/
Traceback (most recent call last):
  File "C:\Python372\mecheck\lib\site-packages\django\core\handlers\exception.py", line 34, in inner
    response = get_response(request)
  File "C:\Python372\mecheck\lib\site-packages\django\core\handlers\base.py", line 126, in _get_response
    response = self.process_exception_by_middleware(e, request)
  File "C:\Python372\mecheck\lib\site-packages\django\core\handlers\base.py", line 124, in _get_response
    response = wrapped_callback(request, *callback_args, **callback_kwargs)
  File "C:\Python372\mecheck\lib\site-packages\django\views\decorators\csrf.py", line 54, in wrapped_view
    return view_func(*args, **kwargs)
  File "C:\djangoproject\Reliability_Row_data\app01\views.py", line 697, in Navigations_Category
    print(Category)
OSError: [Errno 22] Invalid argument
[2025-02-18 14:08:54,006] [runserver.py:154] [runserver:log_action] [ERROR]- HTTP GET /Navigations_Category/Property/ 500 [0.09, 127.0.0.1:62004]
[2025-02-18 14:08:56,782] [log.py:228] [log:log_response] [ERROR]- Internal Server Error: /Navigations_Category/Property/
Traceback (most recent call last):
  File "C:\Python372\mecheck\lib\site-packages\django\core\handlers\exception.py", line 34, in inner
    response = get_response(request)
  File "C:\Python372\mecheck\lib\site-packages\django\core\handlers\base.py", line 126, in _get_response
    response = self.process_exception_by_middleware(e, request)
  File "C:\Python372\mecheck\lib\site-packages\django\core\handlers\base.py", line 124, in _get_response
    response = wrapped_callback(request, *callback_args, **callback_kwargs)
  File "C:\Python372\mecheck\lib\site-packages\django\views\decorators\csrf.py", line 54, in wrapped_view
    return view_func(*args, **kwargs)
  File "C:\djangoproject\Reliability_Row_data\app01\views.py", line 697, in Navigations_Category
    print(Category)
OSError: [Errno 22] Invalid argument
[2025-02-18 14:08:56,786] [runserver.py:154] [runserver:log_action] [ERROR]- HTTP GET /Navigations_Category/Property/ 500 [0.09, 127.0.0.1:62004]
[2025-02-18 14:08:57,499] [log.py:228] [log:log_response] [ERROR]- Internal Server Error: /Navigations_Category/DepartMent/
Traceback (most recent call last):
  File "C:\Python372\mecheck\lib\site-packages\django\core\handlers\exception.py", line 34, in inner
    response = get_response(request)
  File "C:\Python372\mecheck\lib\site-packages\django\core\handlers\base.py", line 126, in _get_response
    response = self.process_exception_by_middleware(e, request)
  File "C:\Python372\mecheck\lib\site-packages\django\core\handlers\base.py", line 124, in _get_response
    response = wrapped_callback(request, *callback_args, **callback_kwargs)
  File "C:\Python372\mecheck\lib\site-packages\django\views\decorators\csrf.py", line 54, in wrapped_view
    return view_func(*args, **kwargs)
  File "C:\djangoproject\Reliability_Row_data\app01\views.py", line 697, in Navigations_Category
    print(Category)
OSError: [Errno 22] Invalid argument
[2025-02-18 14:08:57,504] [runserver.py:154] [runserver:log_action] [ERROR]- HTTP GET /Navigations_Category/DepartMent/ 500 [0.10, 127.0.0.1:62004]
[2025-02-18 14:08:58,084] [log.py:228] [log:log_response] [ERROR]- Internal Server Error: /Navigations_Category/Property/
Traceback (most recent call last):
  File "C:\Python372\mecheck\lib\site-packages\django\core\handlers\exception.py", line 34, in inner
    response = get_response(request)
  File "C:\Python372\mecheck\lib\site-packages\django\core\handlers\base.py", line 126, in _get_response
    response = self.process_exception_by_middleware(e, request)
  File "C:\Python372\mecheck\lib\site-packages\django\core\handlers\base.py", line 124, in _get_response
    response = wrapped_callback(request, *callback_args, **callback_kwargs)
  File "C:\Python372\mecheck\lib\site-packages\django\views\decorators\csrf.py", line 54, in wrapped_view
    return view_func(*args, **kwargs)
  File "C:\djangoproject\Reliability_Row_data\app01\views.py", line 697, in Navigations_Category
    print(Category)
OSError: [Errno 22] Invalid argument
[2025-02-18 14:08:58,088] [runserver.py:154] [runserver:log_action] [ERROR]- HTTP GET /Navigations_Category/Property/ 500 [0.10, 127.0.0.1:62004]
[2025-02-18 14:09:23,192] [log.py:228] [log:log_response] [ERROR]- Internal Server Error: /Navigations_Category/DepartMent/
Traceback (most recent call last):
  File "C:\Python372\mecheck\lib\site-packages\django\core\handlers\exception.py", line 34, in inner
    response = get_response(request)
  File "C:\Python372\mecheck\lib\site-packages\django\core\handlers\base.py", line 126, in _get_response
    response = self.process_exception_by_middleware(e, request)
  File "C:\Python372\mecheck\lib\site-packages\django\core\handlers\base.py", line 124, in _get_response
    response = wrapped_callback(request, *callback_args, **callback_kwargs)
  File "C:\Python372\mecheck\lib\site-packages\django\views\decorators\csrf.py", line 54, in wrapped_view
    return view_func(*args, **kwargs)
  File "C:\djangoproject\Reliability_Row_data\app01\views.py", line 697, in Navigations_Category
    print(Category)
OSError: [Errno 22] Invalid argument
[2025-02-18 14:09:23,196] [runserver.py:154] [runserver:log_action] [ERROR]- HTTP GET /Navigations_Category/DepartMent/ 500 [0.08, 127.0.0.1:62004]
[2025-02-18 14:09:24,288] [log.py:228] [log:log_response] [ERROR]- Internal Server Error: /Navigations_Category/DepartMent/
Traceback (most recent call last):
  File "C:\Python372\mecheck\lib\site-packages\django\core\handlers\exception.py", line 34, in inner
    response = get_response(request)
  File "C:\Python372\mecheck\lib\site-packages\django\core\handlers\base.py", line 126, in _get_response
    response = self.process_exception_by_middleware(e, request)
  File "C:\Python372\mecheck\lib\site-packages\django\core\handlers\base.py", line 124, in _get_response
    response = wrapped_callback(request, *callback_args, **callback_kwargs)
  File "C:\Python372\mecheck\lib\site-packages\django\views\decorators\csrf.py", line 54, in wrapped_view
    return view_func(*args, **kwargs)
  File "C:\djangoproject\Reliability_Row_data\app01\views.py", line 697, in Navigations_Category
    print(Category)
OSError: [Errno 22] Invalid argument
[2025-02-18 14:09:24,290] [runserver.py:154] [runserver:log_action] [ERROR]- HTTP GET /Navigations_Category/DepartMent/ 500 [0.07, 127.0.0.1:62004]
[2025-02-18 14:09:24,965] [log.py:228] [log:log_response] [ERROR]- Internal Server Error: /Navigations_Category/DepartMent/
Traceback (most recent call last):
  File "C:\Python372\mecheck\lib\site-packages\django\core\handlers\exception.py", line 34, in inner
    response = get_response(request)
  File "C:\Python372\mecheck\lib\site-packages\django\core\handlers\base.py", line 126, in _get_response
    response = self.process_exception_by_middleware(e, request)
  File "C:\Python372\mecheck\lib\site-packages\django\core\handlers\base.py", line 124, in _get_response
    response = wrapped_callback(request, *callback_args, **callback_kwargs)
  File "C:\Python372\mecheck\lib\site-packages\django\views\decorators\csrf.py", line 54, in wrapped_view
    return view_func(*args, **kwargs)
  File "C:\djangoproject\Reliability_Row_data\app01\views.py", line 697, in Navigations_Category
    print(Category)
OSError: [Errno 22] Invalid argument
[2025-02-18 14:09:24,970] [runserver.py:154] [runserver:log_action] [ERROR]- HTTP GET /Navigations_Category/DepartMent/ 500 [0.09, 127.0.0.1:62004]
[2025-02-18 14:11:27,161] [log.py:228] [log:log_response] [ERROR]- Internal Server Error: /Navigations_Category/DepartMent/
Traceback (most recent call last):
  File "C:\Python372\mecheck\lib\site-packages\django\core\handlers\exception.py", line 34, in inner
    response = get_response(request)
  File "C:\Python372\mecheck\lib\site-packages\django\core\handlers\base.py", line 126, in _get_response
    response = self.process_exception_by_middleware(e, request)
  File "C:\Python372\mecheck\lib\site-packages\django\core\handlers\base.py", line 124, in _get_response
    response = wrapped_callback(request, *callback_args, **callback_kwargs)
  File "C:\Python372\mecheck\lib\site-packages\django\views\decorators\csrf.py", line 54, in wrapped_view
    return view_func(*args, **kwargs)
  File "C:\djangoproject\Reliability_Row_data\app01\views.py", line 697, in Navigations_Category
    print(Category)
OSError: [Errno 22] Invalid argument
[2025-02-18 14:11:27,165] [runserver.py:154] [runserver:log_action] [ERROR]- HTTP GET /Navigations_Category/DepartMent/ 500 [0.08, 127.0.0.1:63281]
[2025-02-18 14:11:27,848] [log.py:228] [log:log_response] [ERROR]- Internal Server Error: /Navigations_Category/DepartMent/
Traceback (most recent call last):
  File "C:\Python372\mecheck\lib\site-packages\django\core\handlers\exception.py", line 34, in inner
    response = get_response(request)
  File "C:\Python372\mecheck\lib\site-packages\django\core\handlers\base.py", line 126, in _get_response
    response = self.process_exception_by_middleware(e, request)
  File "C:\Python372\mecheck\lib\site-packages\django\core\handlers\base.py", line 124, in _get_response
    response = wrapped_callback(request, *callback_args, **callback_kwargs)
  File "C:\Python372\mecheck\lib\site-packages\django\views\decorators\csrf.py", line 54, in wrapped_view
    return view_func(*args, **kwargs)
  File "C:\djangoproject\Reliability_Row_data\app01\views.py", line 697, in Navigations_Category
    print(Category)
OSError: [Errno 22] Invalid argument
[2025-02-18 14:11:27,851] [runserver.py:154] [runserver:log_action] [ERROR]- HTTP GET /Navigations_Category/DepartMent/ 500 [0.09, 127.0.0.1:63281]
[2025-02-18 14:11:28,064] [log.py:228] [log:log_response] [ERROR]- Internal Server Error: /Navigations_Category/DepartMent/
Traceback (most recent call last):
  File "C:\Python372\mecheck\lib\site-packages\django\core\handlers\exception.py", line 34, in inner
    response = get_response(request)
  File "C:\Python372\mecheck\lib\site-packages\django\core\handlers\base.py", line 126, in _get_response
    response = self.process_exception_by_middleware(e, request)
  File "C:\Python372\mecheck\lib\site-packages\django\core\handlers\base.py", line 124, in _get_response
    response = wrapped_callback(request, *callback_args, **callback_kwargs)
  File "C:\Python372\mecheck\lib\site-packages\django\views\decorators\csrf.py", line 54, in wrapped_view
    return view_func(*args, **kwargs)
  File "C:\djangoproject\Reliability_Row_data\app01\views.py", line 697, in Navigations_Category
    print(Category)
OSError: [Errno 22] Invalid argument
[2025-02-18 14:11:28,069] [runserver.py:154] [runserver:log_action] [ERROR]- HTTP GET /Navigations_Category/DepartMent/ 500 [0.08, 127.0.0.1:63281]
[2025-02-18 14:11:28,297] [log.py:228] [log:log_response] [ERROR]- Internal Server Error: /Navigations_Category/DepartMent/
Traceback (most recent call last):
  File "C:\Python372\mecheck\lib\site-packages\django\core\handlers\exception.py", line 34, in inner
    response = get_response(request)
  File "C:\Python372\mecheck\lib\site-packages\django\core\handlers\base.py", line 126, in _get_response
    response = self.process_exception_by_middleware(e, request)
  File "C:\Python372\mecheck\lib\site-packages\django\core\handlers\base.py", line 124, in _get_response
    response = wrapped_callback(request, *callback_args, **callback_kwargs)
  File "C:\Python372\mecheck\lib\site-packages\django\views\decorators\csrf.py", line 54, in wrapped_view
    return view_func(*args, **kwargs)
  File "C:\djangoproject\Reliability_Row_data\app01\views.py", line 697, in Navigations_Category
    print(Category)
OSError: [Errno 22] Invalid argument
[2025-02-18 14:11:28,302] [runserver.py:154] [runserver:log_action] [ERROR]- HTTP GET /Navigations_Category/DepartMent/ 500 [0.07, 127.0.0.1:63281]
