[2025-05-06 13:41:03,352] [log.py:228] [log:log_response] [ERROR]- Internal Server Error: /admin/app01/menu/
Traceback (most recent call last):
  File "C:\Python3129\mecheck\lib\site-packages\django\core\handlers\exception.py", line 34, in inner
    response = get_response(request)
  File "C:\Python3129\mecheck\lib\site-packages\django\core\handlers\base.py", line 126, in _get_response
    response = self.process_exception_by_middleware(e, request)
  File "C:\Python3129\mecheck\lib\site-packages\django\core\handlers\base.py", line 124, in _get_response
    response = wrapped_callback(request, *callback_args, **callback_kwargs)
  File "C:\Python3129\mecheck\lib\site-packages\django\contrib\admin\options.py", line 604, in wrapper
    return self.admin_site.admin_view(view)(*args, **kwargs)
  File "C:\Python3129\mecheck\lib\site-packages\django\utils\decorators.py", line 142, in _wrapped_view
    response = view_func(request, *args, **kwargs)
  File "C:\Python3129\mecheck\lib\site-packages\django\views\decorators\cache.py", line 44, in _wrapped_view_func
    response = view_func(request, *args, **kwargs)
  File "C:\Python3129\mecheck\lib\site-packages\django\contrib\admin\sites.py", line 223, in inner
    return view(request, *args, **kwargs)
  File "C:\Python3129\mecheck\lib\site-packages\django\utils\decorators.py", line 45, in _wrapper
    return bound_method(*args, **kwargs)
  File "C:\Python3129\mecheck\lib\site-packages\django\utils\decorators.py", line 142, in _wrapped_view
    response = view_func(request, *args, **kwargs)
  File "C:\Python3129\mecheck\lib\site-packages\django\contrib\admin\options.py", line 1717, in changelist_view
    response = self.response_action(request, queryset=cl.get_queryset(request))
  File "C:\Python3129\mecheck\lib\site-packages\django\contrib\admin\options.py", line 1400, in response_action
    response = func(self, request, queryset)
  File "C:\Python3129\mecheck\lib\site-packages\django\contrib\admin\actions.py", line 28, in delete_selected
    deletable_objects, model_count, perms_needed, protected = modeladmin.get_deleted_objects(queryset, request)
  File "C:\Python3129\mecheck\lib\site-packages\django\contrib\admin\options.py", line 1823, in get_deleted_objects
    return get_deleted_objects(objs, request, self.admin_site)
  File "C:\Python3129\mecheck\lib\site-packages\django\contrib\admin\utils.py", line 134, in get_deleted_objects
    collector.collect(objs)
  File "C:\Python3129\mecheck\lib\site-packages\django\contrib\admin\utils.py", line 197, in collect
    return super().collect(objs, source_attr=source_attr, **kwargs)
  File "C:\Python3129\mecheck\lib\site-packages\django\db\models\deletion.py", line 221, in collect
    field.remote_field.on_delete(self, field, sub_objs, self.using)
TypeError: 'bool' object is not callable
[2025-05-06 13:41:03,363] [runserver.py:154] [runserver:log_action] [ERROR]- HTTP POST /admin/app01/menu/ 500 [0.13, 127.0.0.1:52961]
