[2025-05-19 10:18:14,399] [log.py:228] [log:log_response] [ERROR]- Internal Server Error: /CommonDevice/CommonDevice_edit/
Traceback (most recent call last):
  File "C:\Python3129\mecheck\lib\site-packages\django\core\handlers\exception.py", line 34, in inner
    response = get_response(request)
  File "C:\Python3129\mecheck\lib\site-packages\django\core\handlers\base.py", line 126, in _get_response
    response = self.process_exception_by_middleware(e, request)
  File "C:\Python3129\mecheck\lib\site-packages\django\core\handlers\base.py", line 124, in _get_response
    response = wrapped_callback(request, *callback_args, **callback_kwargs)
  File "C:\Python3129\mecheck\lib\site-packages\django\views\decorators\csrf.py", line 54, in wrapped_view
    return view_func(*args, **kwargs)
  File "C:\djangoproject\Reliability_Row_data\CommonDevice\views.py", line 95, in CommonDevice_edit
    if j.Purchasing_Date:
UnboundLocalError: local variable 'j' referenced before assignment
[2025-05-19 10:18:14,404] [runserver.py:154] [runserver:log_action] [ERROR]- HTTP POST /CommonDevice/CommonDevice_edit/ 500 [0.46, 127.0.0.1:50113]
[2025-05-19 10:19:05,745] [log.py:228] [log:log_response] [ERROR]- Internal Server Error: /CommonDevice/CommonDevice_edit/
Traceback (most recent call last):
  File "C:\Python3129\mecheck\lib\site-packages\django\core\handlers\exception.py", line 34, in inner
    response = get_response(request)
  File "C:\Python3129\mecheck\lib\site-packages\django\core\handlers\base.py", line 126, in _get_response
    response = self.process_exception_by_middleware(e, request)
  File "C:\Python3129\mecheck\lib\site-packages\django\core\handlers\base.py", line 124, in _get_response
    response = wrapped_callback(request, *callback_args, **callback_kwargs)
  File "C:\Python3129\mecheck\lib\site-packages\django\views\decorators\csrf.py", line 54, in wrapped_view
    return view_func(*args, **kwargs)
  File "C:\djangoproject\Reliability_Row_data\CommonDevice\views.py", line 103, in CommonDevice_edit
    for j in i.owner.all():
AttributeError: 'CommonDevice' object has no attribute 'owner'
[2025-05-19 10:19:05,756] [runserver.py:154] [runserver:log_action] [ERROR]- HTTP POST /CommonDevice/CommonDevice_edit/ 500 [0.59, 127.0.0.1:50182]
[2025-05-19 10:21:12,422] [log.py:228] [log:log_response] [ERROR]- Internal Server Error: /CommonDevice/CommonDevice_edit/
Traceback (most recent call last):
  File "C:\Python3129\mecheck\lib\site-packages\django\core\handlers\exception.py", line 34, in inner
    response = get_response(request)
  File "C:\Python3129\mecheck\lib\site-packages\django\core\handlers\base.py", line 126, in _get_response
    response = self.process_exception_by_middleware(e, request)
  File "C:\Python3129\mecheck\lib\site-packages\django\core\handlers\base.py", line 124, in _get_response
    response = wrapped_callback(request, *callback_args, **callback_kwargs)
  File "C:\Python3129\mecheck\lib\site-packages\django\views\decorators\csrf.py", line 54, in wrapped_view
    return view_func(*args, **kwargs)
  File "C:\djangoproject\Reliability_Row_data\CommonDevice\views.py", line 138, in CommonDevice_edit
    return HttpResponse(json.dumps(data), content_type="application/json")
  File "C:\Python372\lib\json\__init__.py", line 231, in dumps
    return _default_encoder.encode(obj)
  File "C:\Python372\lib\json\encoder.py", line 199, in encode
    chunks = self.iterencode(o, _one_shot=True)
  File "C:\Python372\lib\json\encoder.py", line 257, in iterencode
    return _iterencode(o, 0)
  File "C:\Python372\lib\json\encoder.py", line 179, in default
    raise TypeError(f'Object of type {o.__class__.__name__} '
TypeError: Object of type UserInfo is not JSON serializable
[2025-05-19 10:21:12,431] [runserver.py:154] [runserver:log_action] [ERROR]- HTTP POST /CommonDevice/CommonDevice_edit/ 500 [0.56, 127.0.0.1:50381]
[2025-05-19 10:47:21,456] [log.py:228] [log:log_response] [ERROR]- Internal Server Error: /CommonDevice/CommonDevice_edit/
Traceback (most recent call last):
  File "C:\Python3129\mecheck\lib\site-packages\django\core\handlers\exception.py", line 34, in inner
    response = get_response(request)
  File "C:\Python3129\mecheck\lib\site-packages\django\core\handlers\base.py", line 126, in _get_response
    response = self.process_exception_by_middleware(e, request)
  File "C:\Python3129\mecheck\lib\site-packages\django\core\handlers\base.py", line 124, in _get_response
    response = wrapped_callback(request, *callback_args, **callback_kwargs)
  File "C:\Python3129\mecheck\lib\site-packages\django\views\decorators\csrf.py", line 54, in wrapped_view
    return view_func(*args, **kwargs)
  File "C:\djangoproject\Reliability_Row_data\CommonDevice\views.py", line 29, in CommonDevice_edit
    i.Category
AttributeError: 'dict' object has no attribute 'Category'
[2025-05-19 10:47:21,490] [runserver.py:154] [runserver:log_action] [ERROR]- HTTP GET /CommonDevice/CommonDevice_edit/ 500 [0.63, 127.0.0.1:52517]
